Workbook
Name MasterList: Списки!$A$2:$A$5
Name ShiftList: Списки!$B$2:$B$5
Name Мастер: [1]инфо!$A$34:$A$37
Name Продукт: [1]инфо!$A$15:$A$29

Sheet Выработка
A1: Дата | B1: Месяц | C1: Тип смены | D1: Линия | E1: Мастер | F1: Смена | G1: План | H1: Факт | I1: 1-сорт | J1: Брак
A2: 02.06.2026 | B2: =IF(ТаблицаВыработки[[#This Row],[Дата]]="","",DATE(VALUE(RIGHT(ТаблицаВыработки[[#This Row],[Дата]],4)),VALUE(MID(ТаблицаВыработки[[#This Row],[Дата]],4,2)),1)) | C2: Ночь | D2: Линия 2 | E2: Султанулы С. | F2: 3 | G2: 3300 | H2: 990 | I2: =SUMIFS(рапорт!$K:$K,рапорт!$A:$A,DATE(VALUE(RIGHT(ТаблицаВыработки[[#This Row],[Дата]],4)),VALUE(MID(ТаблицаВыработки[[#This Row],[Дата]],4,2)),VALUE(LEFT(ТаблицаВыработки[[#This Row],[Дата]],2))),рапорт!$D:$D,LOWER(ТаблицаВыработки[[#This Row],[Тип смены]])&"*",рапорт!$E:$E,LEFT(ТаблицаВыработки[[#This Row],[Мастер]],SEARCH(" ",ТаблицаВыработки[[#This Row],[Мастер]]&" ")-1)&"*") | J2: =SUMIFS(рапорт!$L:$L,рапорт!$A:$A,DATE(VALUE(RIGHT(ТаблицаВыработки[[#This Row],[Дата]],4)),VALUE(MID(ТаблицаВыработки[[#This Row],[Дата]],4,2)),VALUE(LEFT(ТаблицаВыработки[[#This Row],[Дата]],2))),рапорт!$D:$D,LOWER(ТаблицаВыработки[[#This Row],[Тип смены]])&"*",рапорт!$E:$E,LEFT(ТаблицаВыработки[[#This Row],[Мастер]],SEARCH(" ",ТаблицаВыработки[[#This Row],[Мастер]]&" ")-1)&"*")
A3: 02.06.2026 | B3: =IF(ТаблицаВыработки[[#This Row],[Дата]]="","",DATE(VALUE(RIGHT(ТаблицаВыработки[[#This Row],[Дата]],4)),VALUE(MID(ТаблицаВыработки[[#This Row],[Дата]],4,2)),1)) | C3: День | D3: Линия 2 | E3: Дауылбай М. | F3: 4 | G3: 2700 | H3: 140 | I3: =SUMIFS(рапорт!$K:$K,рапорт!$A:$A,DATE(VALUE(RIGHT(ТаблицаВыработки[[#This Row],[Дата]],4)),VALUE(MID(ТаблицаВыработки[[#This Row],[Дата]],4,2)),VALUE(LEFT(ТаблицаВыработки[[#This Row],[Дата]],2))),рапорт!$D:$D,LOWER(ТаблицаВыработки[[#This Row],[Тип смены]])&"*",рапорт!$E:$E,LEFT(ТаблицаВыработки[[#This Row],[Мастер]],SEARCH(" ",ТаблицаВыработки[[#This Row],[Мастер]]&" ")-1)&"*") | J3: =SUMIFS(рапорт!$L:$L,рапорт!$A:$A,DATE(VALUE(RIGHT(ТаблицаВыработки[[#This Row],[Дата]],4)),VALUE(MID(ТаблицаВыработки[[#This Row],[Дата]],4,2)),VALUE(LEFT(ТаблицаВыработки[[#This Row],[Дата]],2))),рапорт!$D:$D,LOWER(ТаблицаВыработки[[#This Row],[Тип смены]])&"*",рапорт!$E:$E,LEFT(ТаблицаВыработки[[#This Row],[Мастер]],SEARCH(" ",ТаблицаВыработки[[#This Row],[Мастер]]&" ")-1)&"*")
A4: 03.06.2026 | B4: =IF(ТаблицаВыработки[[#This Row],[Дата]]="","",DATE(VALUE(RIGHT(ТаблицаВыработки[[#This Row],[Дата]],4)),VALUE(MID(ТаблицаВыработки[[#This Row],[Дата]],4,2)),1)) | C4: День | D4: Линия 2 | E4: Монаев С. | F4: 2 | G4: 2700 | H4: 800 | I4: =SUMIFS(рапорт!$K:$K,рапорт!$A:$A,DATE(VALUE(RIGHT(ТаблицаВыработки[[#This Row],[Дата]],4)),VALUE(MID(ТаблицаВыработки[[#This Row],[Дата]],4,2)),VALUE(LEFT(ТаблицаВыработки[[#This Row],[Дата]],2))),рапорт!$D:$D,LOWER(ТаблицаВыработки[[#This Row],[Тип смены]])&"*",рапорт!$E:$E,LEFT(ТаблицаВыработки[[#This Row],[Мастер]],SEARCH(" ",ТаблицаВыработки[[#This Row],[Мастер]]&" ")-1)&"*") | J4: =SUMIFS(рапорт!$L:$L,рапорт!$A:$A,DATE(VALUE(RIGHT(ТаблицаВыработки[[#This Row],[Дата]],4)),VALUE(MID(ТаблицаВыработки[[#This Row],[Дата]],4,2)),VALUE(LEFT(ТаблицаВыработки[[#This Row],[Дата]],2))),рапорт!$D:$D,LOWER(ТаблицаВыработки[[#This Row],[Тип смены]])&"*",рапорт!$E:$E,LEFT(ТаблицаВыработки[[#This Row],[Мастер]],SEARCH(" ",ТаблицаВыработки[[#This Row],[Мастер]]&" ")-1)&"*")
A5: 03.06.2026 | B5: =IF(ТаблицаВыработки[[#This Row],[Дата]]="","",DATE(VALUE(RIGHT(ТаблицаВыработки[[#This Row],[Дата]],4)),VALUE(MID(ТаблицаВыработки[[#This Row],[Дата]],4,2)),1)) | C5: Ночь | D5: Линия 2 | E5: Дауылбай М. | F5: 4 | G5: 3300 | H5: 1420 | I5: =SUMIFS(рапорт!$K:$K,рапорт!$A:$A,DATE(VALUE(RIGHT(ТаблицаВыработки[[#This Row],[Дата]],4)),VALUE(MID(ТаблицаВыработки[[#This Row],[Дата]],4,2)),VALUE(LEFT(ТаблицаВыработки[[#This Row],[Дата]],2))),рапорт!$D:$D,LOWER(ТаблицаВыработки[[#This Row],[Тип смены]])&"*",рапорт!$E:$E,LEFT(ТаблицаВыработки[[#This Row],[Мастер]],SEARCH(" ",ТаблицаВыработки[[#This Row],[Мастер]]&" ")-1)&"*") | J5: =SUMIFS(рапорт!$L:$L,рапорт!$A:$A,DATE(VALUE(RIGHT(ТаблицаВыработки[[#This Row],[Дата]],4)),VALUE(MID(ТаблицаВыработки[[#This Row],[Дата]],4,2)),VALUE(LEFT(ТаблицаВыработки[[#This Row],[Дата]],2))),рапорт!$D:$D,LOWER(ТаблицаВыработки[[#This Row],[Тип смены]])&"*",рапорт!$E:$E,LEFT(ТаблицаВыработки[[#This Row],[Мастер]],SEARCH(" ",ТаблицаВыработки[[#This Row],[Мастер]]&" ")-1)&"*")
A6: 04.06.2026 | B6: =IF(ТаблицаВыработки[[#This Row],[Дата]]="","",DATE(VALUE(RIGHT(ТаблицаВыработки[[#This Row],[Дата]],4)),VALUE(MID(ТаблицаВыработки[[#This Row],[Дата]],4,2)),1)) | C6: День | D6: Линия 2 | E6: Бекбосынов Р. | F6: 1 | G6: 2700 | H6: 390 | I6: =SUMIFS(рапорт!$K:$K,рапорт!$A:$A,DATE(VALUE(RIGHT(ТаблицаВыработки[[#This Row],[Дата]],4)),VALUE(MID(ТаблицаВыработки[[#This Row],[Дата]],4,2)),VALUE(LEFT(ТаблицаВыработки[[#This Row],[Дата]],2))),рапорт!$D:$D,LOWER(ТаблицаВыработки[[#This Row],[Тип смены]])&"*",рапорт!$E:$E,LEFT(ТаблицаВыработки[[#This Row],[Мастер]],SEARCH(" ",ТаблицаВыработки[[#This Row],[Мастер]]&" ")-1)&"*") | J6: =SUMIFS(рапорт!$L:$L,рапорт!$A:$A,DATE(VALUE(RIGHT(ТаблицаВыработки[[#This Row],[Дата]],4)),VALUE(MID(ТаблицаВыработки[[#This Row],[Дата]],4,2)),VALUE(LEFT(ТаблицаВыработки[[#This Row],[Дата]],2))),рапорт!$D:$D,LOWER(ТаблицаВыработки[[#This Row],[Тип смены]])&"*",рапорт!$E:$E,LEFT(ТаблицаВыработки[[#This Row],[Мастер]],SEARCH(" ",ТаблицаВыработки[[#This Row],[Мастер]]&" ")-1)&"*")
A7: 04.06.2026 | B7: =IF(ТаблицаВыработки[[#This Row],[Дата]]="","",DATE(VALUE(RIGHT(ТаблицаВыработки[[#This Row],[Дата]],4)),VALUE(MID(ТаблицаВыработки[[#This Row],[Дата]],4,2)),1)) | C7: Ночь | D7: Линия 2 | E7: Монаев С. | F7: 2 | G7: 3300 | H7: 2280 | I7: =SUMIFS(рапорт!$K:$K,рапорт!$A:$A,DATE(VALUE(RIGHT(ТаблицаВыработки[[#This Row],[Дата]],4)),VALUE(MID(ТаблицаВыработки[[#This Row],[Дата]],4,2)),VALUE(LEFT(ТаблицаВыработки[[#This Row],[Дата]],2))),рапорт!$D:$D,LOWER(ТаблицаВыработки[[#This Row],[Тип смены]])&"*",рапорт!$E:$E,LEFT(ТаблицаВыработки[[#This Row],[Мастер]],SEARCH(" ",ТаблицаВыработки[[#This Row],[Мастер]]&" ")-1)&"*") | J7: =SUMIFS(рапорт!$L:$L,рапорт!$A:$A,DATE(VALUE(RIGHT(ТаблицаВыработки[[#This Row],[Дата]],4)),VALUE(MID(ТаблицаВыработки[[#This Row],[Дата]],4,2)),VALUE(LEFT(ТаблицаВыработки[[#This Row],[Дата]],2))),рапорт!$D:$D,LOWER(ТаблицаВыработки[[#This Row],[Тип смены]])&"*",рапорт!$E:$E,LEFT(ТаблицаВыработки[[#This Row],[Мастер]],SEARCH(" ",ТаблицаВыработки[[#This Row],[Мастер]]&" ")-1)&"*")
A8: 05.06.2026 | B8: =IF(ТаблицаВыработки[[#This Row],[Дата]]="","",DATE(VALUE(RIGHT(ТаблицаВыработки[[#This Row],[Дата]],4)),VALUE(MID(ТаблицаВыработки[[#This Row],[Дата]],4,2)),1)) | C8: Ночь | D8: Линия 2 | E8: Бекбосынов Р. | F8: 1 | G8: 3300 | H8: 3200 | I8: =SUMIFS(рапорт!$K:$K,рапорт!$A:$A,DATE(VALUE(RIGHT(ТаблицаВыработки[[#This Row],[Дата]],4)),VALUE(MID(ТаблицаВыработки[[#This Row],[Дата]],4,2)),VALUE(LEFT(ТаблицаВыработки[[#This Row],[Дата]],2))),рапорт!$D:$D,LOWER(ТаблицаВыработки[[#This Row],[Тип смены]])&"*",рапорт!$E:$E,LEFT(ТаблицаВыработки[[#This Row],[Мастер]],SEARCH(" ",ТаблицаВыработки[[#This Row],[Мастер]]&" ")-1)&"*") | J8: =SUMIFS(рапорт!$L:$L,рапорт!$A:$A,DATE(VALUE(RIGHT(ТаблицаВыработки[[#This Row],[Дата]],4)),VALUE(MID(ТаблицаВыработки[[#This Row],[Дата]],4,2)),VALUE(LEFT(ТаблицаВыработки[[#This Row],[Дата]],2))),рапорт!$D:$D,LOWER(ТаблицаВыработки[[#This Row],[Тип смены]])&"*",рапорт!$E:$E,LEFT(ТаблицаВыработки[[#This Row],[Мастер]],SEARCH(" ",ТаблицаВыработки[[#This Row],[Мастер]]&" ")-1)&"*")
A9: 05.06.2026 | B9: =IF(ТаблицаВыработки[[#This Row],[Дата]]="","",DATE(VALUE(RIGHT(ТаблицаВыработки[[#This Row],[Дата]],4)),VALUE(MID(ТаблицаВыработки[[#This Row],[Дата]],4,2)),1)) | C9: День | D9: Линия 2 | E9: Султанулы С. | F9: 3 | G9: 2700 | H9: 2488 | I9: =SUMIFS(рапорт!$K:$K,рапорт!$A:$A,DATE(VALUE(RIGHT(ТаблицаВыработки[[#This Row],[Дата]],4)),VALUE(MID(ТаблицаВыработки[[#This Row],[Дата]],4,2)),VALUE(LEFT(ТаблицаВыработки[[#This Row],[Дата]],2))),рапорт!$D:$D,LOWER(ТаблицаВыработки[[#This Row],[Тип смены]])&"*",рапорт!$E:$E,LEFT(ТаблицаВыработки[[#This Row],[Мастер]],SEARCH(" ",ТаблицаВыработки[[#This Row],[Мастер]]&" ")-1)&"*") | J9: =SUMIFS(рапорт!$L:$L,рапорт!$A:$A,DATE(VALUE(RIGHT(ТаблицаВыработки[[#This Row],[Дата]],4)),VALUE(MID(ТаблицаВыработки[[#This Row],[Дата]],4,2)),VALUE(LEFT(ТаблицаВыработки[[#This Row],[Дата]],2))),рапорт!$D:$D,LOWER(ТаблицаВыработки[[#This Row],[Тип смены]])&"*",рапорт!$E:$E,LEFT(ТаблицаВыработки[[#This Row],[Мастер]],SEARCH(" ",ТаблицаВыработки[[#This Row],[Мастер]]&" ")-1)&"*")
A10: 06.06.2026 | B10: =IF(ТаблицаВыработки[[#This Row],[Дата]]="","",DATE(VALUE(RIGHT(ТаблицаВыработки[[#This Row],[Дата]],4)),VALUE(MID(ТаблицаВыработки[[#This Row],[Дата]],4,2)),1)) | C10: Ночь | D10: Линия 2 | E10: Султанулы С. | F10: 3 | G10: 3300 | H10: 2856 | I10: =SUMIFS(рапорт!$K:$K,рапорт!$A:$A,DATE(VALUE(RIGHT(ТаблицаВыработки[[#This Row],[Дата]],4)),VALUE(MID(ТаблицаВыработки[[#This Row],[Дата]],4,2)),VALUE(LEFT(ТаблицаВыработки[[#This Row],[Дата]],2))),рапорт!$D:$D,LOWER(ТаблицаВыработки[[#This Row],[Тип смены]])&"*",рапорт!$E:$E,LEFT(ТаблицаВыработки[[#This Row],[Мастер]],SEARCH(" ",ТаблицаВыработки[[#This Row],[Мастер]]&" ")-1)&"*") | J10: =SUMIFS(рапорт!$L:$L,рапорт!$A:$A,DATE(VALUE(RIGHT(ТаблицаВыработки[[#This Row],[Дата]],4)),VALUE(MID(ТаблицаВыработки[[#This Row],[Дата]],4,2)),VALUE(LEFT(ТаблицаВыработки[[#This Row],[Дата]],2))),рапорт!$D:$D,LOWER(ТаблицаВыработки[[#This Row],[Тип смены]])&"*",рапорт!$E:$E,LEFT(ТаблицаВыработки[[#This Row],[Мастер]],SEARCH(" ",ТаблицаВыработки[[#This Row],[Мастер]]&" ")-1)&"*")
A11: 06.06.2026 | B11: =IF(ТаблицаВыработки[[#This Row],[Дата]]="","",DATE(VALUE(RIGHT(ТаблицаВыработки[[#This Row],[Дата]],4)),VALUE(MID(ТаблицаВыработки[[#This Row],[Дата]],4,2)),1)) | C11: День | D11: Линия 2 | E11: Дауылбай М. | F11: 4 | G11: 2700 | H11: 2800 | I11: =SUMIFS(рапорт!$K:$K,рапорт!$A:$A,DATE(VALUE(RIGHT(ТаблицаВыработки[[#This Row],[Дата]],4)),VALUE(MID(ТаблицаВыработки[[#This Row],[Дата]],4,2)),VALUE(LEFT(ТаблицаВыработки[[#This Row],[Дата]],2))),рапорт!$D:$D,LOWER(ТаблицаВыработки[[#This Row],[Тип смены]])&"*",рапорт!$E:$E,LEFT(ТаблицаВыработки[[#This Row],[Мастер]],SEARCH(" ",ТаблицаВыработки[[#This Row],[Мастер]]&" ")-1)&"*") | J11: =SUMIFS(рапорт!$L:$L,рапорт!$A:$A,DATE(VALUE(RIGHT(ТаблицаВыработки[[#This Row],[Дата]],4)),VALUE(MID(ТаблицаВыработки[[#This Row],[Дата]],4,2)),VALUE(LEFT(ТаблицаВыработки[[#This Row],[Дата]],2))),рапорт!$D:$D,LOWER(ТаблицаВыработки[[#This Row],[Тип смены]])&"*",рапорт!$E:$E,LEFT(ТаблицаВыработки[[#This Row],[Мастер]],SEARCH(" ",ТаблицаВыработки[[#This Row],[Мастер]]&" ")-1)&"*")
A12: 07.06.2026 | B12: =IF(ТаблицаВыработки[[#This Row],[Дата]]="","",DATE(VALUE(RIGHT(ТаблицаВыработки[[#This Row],[Дата]],4)),VALUE(MID(ТаблицаВыработки[[#This Row],[Дата]],4,2)),1)) | C12: День | D12: Линия 2 | E12: Монаев С. | F12: 2 | G12: 2700 | H12: 1890 | I12: =SUMIFS(рапорт!$K:$K,рапорт!$A:$A,DATE(VALUE(RIGHT(ТаблицаВыработки[[#This Row],[Дата]],4)),VALUE(MID(ТаблицаВыработки[[#This Row],[Дата]],4,2)),VALUE(LEFT(ТаблицаВыработки[[#This Row],[Дата]],2))),рапорт!$D:$D,LOWER(ТаблицаВыработки[[#This Row],[Тип смены]])&"*",рапорт!$E:$E,LEFT(ТаблицаВыработки[[#This Row],[Мастер]],SEARCH(" ",ТаблицаВыработки[[#This Row],[Мастер]]&" ")-1)&"*") | J12: =SUMIFS(рапорт!$L:$L,рапорт!$A:$A,DATE(VALUE(RIGHT(ТаблицаВыработки[[#This Row],[Дата]],4)),VALUE(MID(ТаблицаВыработки[[#This Row],[Дата]],4,2)),VALUE(LEFT(ТаблицаВыработки[[#This Row],[Дата]],2))),рапорт!$D:$D,LOWER(ТаблицаВыработки[[#This Row],[Тип смены]])&"*",рапорт!$E:$E,LEFT(ТаблицаВыработки[[#This Row],[Мастер]],SEARCH(" ",ТаблицаВыработки[[#This Row],[Мастер]]&" ")-1)&"*")
A13: 07.06.2026 | B13: =IF(ТаблицаВыработки[[#This Row],[Дата]]="","",DATE(VALUE(RIGHT(ТаблицаВыработки[[#This Row],[Дата]],4)),VALUE(MID(ТаблицаВыработки[[#This Row],[Дата]],4,2)),1)) | C13: Ночь | D13: Линия 2 | E13: Дауылбай М. | F13: 4 | G13: 3300 | H13: 3070 | I13: =SUMIFS(рапорт!$K:$K,рапорт!$A:$A,DATE(VALUE(RIGHT(ТаблицаВыработки[[#This Row],[Дата]],4)),VALUE(MID(ТаблицаВыработки[[#This Row],[Дата]],4,2)),VALUE(LEFT(ТаблицаВыработки[[#This Row],[Дата]],2))),рапорт!$D:$D,LOWER(ТаблицаВыработки[[#This Row],[Тип смены]])&"*",рапорт!$E:$E,LEFT(ТаблицаВыработки[[#This Row],[Мастер]],SEARCH(" ",ТаблицаВыработки[[#This Row],[Мастер]]&" ")-1)&"*") | J13: =SUMIFS(рапорт!$L:$L,рапорт!$A:$A,DATE(VALUE(RIGHT(ТаблицаВыработки[[#This Row],[Дата]],4)),VALUE(MID(ТаблицаВыработки[[#This Row],[Дата]],4,2)),VALUE(LEFT(ТаблицаВыработки[[#This Row],[Дата]],2))),рапорт!$D:$D,LOWER(ТаблицаВыработки[[#This Row],[Тип смены]])&"*",рапорт!$E:$E,LEFT(ТаблицаВыработки[[#This Row],[Мастер]],SEARCH(" ",ТаблицаВыработки[[#This Row],[Мастер]]&" ")-1)&"*")
... A33: 18.06.2026 | B33: =IF(ТаблицаВыработки[[#This Row],[Дата]]="","",DATE(VALUE(RIGHT(ТаблицаВыработки[[#This Row],[Дата]],4)),VALUE(MID(ТаблицаВыработки[[#This Row],[Дата]],4,2)),1)) | C33: День | D33: Линия 2 | E33: Дауылбай М. | F33: 4 | G33: 2700 | H33: 940 | I33: =SUMIFS(рапорт!$K:$K,рапорт!$A:$A,DATE(VALUE(RIGHT(ТаблицаВыработки[[#This Row],[Дата]],4)),VALUE(MID(ТаблицаВыработки[[#This Row],[Дата]],4,2)),VALUE(LEFT(ТаблицаВыработки[[#This Row],[Дата]],2))),рапорт!$D:$D,LOWER(ТаблицаВыработки[[#This Row],[Тип смены]])&"*",рапорт!$E:$E,LEFT(ТаблицаВыработки[[#This Row],[Мастер]],SEARCH(" ",ТаблицаВыработки[[#This Row],[Мастер]]&" ")-1)&"*") | J33: =SUMIFS(рапорт!$L:$L,рапорт!$A:$A,DATE(VALUE(RIGHT(ТаблицаВыработки[[#This Row],[Дата]],4)),VALUE(MID(ТаблицаВыработки[[#This Row],[Дата]],4,2)),VALUE(LEFT(ТаблицаВыработки[[#This Row],[Дата]],2))),рапорт!$D:$D,LOWER(ТаблицаВыработки[[#This Row],[Тип смены]])&"*",рапорт!$E:$E,LEFT(ТаблицаВыработки[[#This Row],[Мастер]],SEARCH(" ",ТаблицаВыработки[[#This Row],[Мастер]]&" ")-1)&"*")
A34: 19.06.2026 | B34: =IF(ТаблицаВыработки[[#This Row],[Дата]]="","",DATE(VALUE(RIGHT(ТаблицаВыработки[[#This Row],[Дата]],4)),VALUE(MID(ТаблицаВыработки[[#This Row],[Дата]],4,2)),1)) | C34: День | D34: Линия 2 | E34: Монаев С. | F34: 2 | G34: 2700 | I34: =SUMIFS(рапорт!$K:$K,рапорт!$A:$A,DATE(VALUE(RIGHT(ТаблицаВыработки[[#This Row],[Дата]],4)),VALUE(MID(ТаблицаВыработки[[#This Row],[Дата]],4,2)),VALUE(LEFT(ТаблицаВыработки[[#This Row],[Дата]],2))),рапорт!$D:$D,LOWER(ТаблицаВыработки[[#This Row],[Тип смены]])&"*",рапорт!$E:$E,LEFT(ТаблицаВыработки[[#This Row],[Мастер]],SEARCH(" ",ТаблицаВыработки[[#This Row],[Мастер]]&" ")-1)&"*") | J34: =SUMIFS(рапорт!$L:$L,рапорт!$A:$A,DATE(VALUE(RIGHT(ТаблицаВыработки[[#This Row],[Дата]],4)),VALUE(MID(ТаблицаВыработки[[#This Row],[Дата]],4,2)),VALUE(LEFT(ТаблицаВыработки[[#This Row],[Дата]],2))),рапорт!$D:$D,LOWER(ТаблицаВыработки[[#This Row],[Тип смены]])&"*",рапорт!$E:$E,LEFT(ТаблицаВыработки[[#This Row],[Мастер]],SEARCH(" ",ТаблицаВыработки[[#This Row],[Мастер]]&" ")-1)&"*")
A35: 20.06.2026 | B35: =IF(ТаблицаВыработки[[#This Row],[Дата]]="","",DATE(VALUE(RIGHT(ТаблицаВыработки[[#This Row],[Дата]],4)),VALUE(MID(ТаблицаВыработки[[#This Row],[Дата]],4,2)),1)) | C35: День | D35: Линия 2 | E35: Бекбосынов Р. | F35: 1 | G35: 2700 | H35: 2480 | I35: =SUMIFS(рапорт!$K:$K,рапорт!$A:$A,DATE(VALUE(RIGHT(ТаблицаВыработки[[#This Row],[Дата]],4)),VALUE(MID(ТаблицаВыработки[[#This Row],[Дата]],4,2)),VALUE(LEFT(ТаблицаВыработки[[#This Row],[Дата]],2))),рапорт!$D:$D,LOWER(ТаблицаВыработки[[#This Row],[Тип смены]])&"*",рапорт!$E:$E,LEFT(ТаблицаВыработки[[#This Row],[Мастер]],SEARCH(" ",ТаблицаВыработки[[#This Row],[Мастер]]&" ")-1)&"*") | J35: =SUMIFS(рапорт!$L:$L,рапорт!$A:$A,DATE(VALUE(RIGHT(ТаблицаВыработки[[#This Row],[Дата]],4)),VALUE(MID(ТаблицаВыработки[[#This Row],[Дата]],4,2)),VALUE(LEFT(ТаблицаВыработки[[#This Row],[Дата]],2))),рапорт!$D:$D,LOWER(ТаблицаВыработки[[#This Row],[Тип смены]])&"*",рапорт!$E:$E,LEFT(ТаблицаВыработки[[#This Row],[Мастер]],SEARCH(" ",ТаблицаВыработки[[#This Row],[Мастер]]&" ")-1)&"*")
A36: 20.06.2026 | B36: =IF(ТаблицаВыработки[[#This Row],[Дата]]="","",DATE(VALUE(RIGHT(ТаблицаВыработки[[#This Row],[Дата]],4)),VALUE(MID(ТаблицаВыработки[[#This Row],[Дата]],4,2)),1)) | C36: Ночь | D36: Линия 2 | E36: Монаев С. | F36: 2 | G36: 3300 | I36: =SUMIFS(рапорт!$K:$K,рапорт!$A:$A,DATE(VALUE(RIGHT(ТаблицаВыработки[[#This Row],[Дата]],4)),VALUE(MID(ТаблицаВыработки[[#This Row],[Дата]],4,2)),VALUE(LEFT(ТаблицаВыработки[[#This Row],[Дата]],2))),рапорт!$D:$D,LOWER(ТаблицаВыработки[[#This Row],[Тип смены]])&"*",рапорт!$E:$E,LEFT(ТаблицаВыработки[[#This Row],[Мастер]],SEARCH(" ",ТаблицаВыработки[[#This Row],[Мастер]]&" ")-1)&"*") | J36: =SUMIFS(рапорт!$L:$L,рапорт!$A:$A,DATE(VALUE(RIGHT(ТаблицаВыработки[[#This Row],[Дата]],4)),VALUE(MID(ТаблицаВыработки[[#This Row],[Дата]],4,2)),VALUE(LEFT(ТаблицаВыработки[[#This Row],[Дата]],2))),рапорт!$D:$D,LOWER(ТаблицаВыработки[[#This Row],[Тип смены]])&"*",рапорт!$E:$E,LEFT(ТаблицаВыработки[[#This Row],[Мастер]],SEARCH(" ",ТаблицаВыработки[[#This Row],[Мастер]]&" ")-1)&"*")
A37: 20.06.2026 | B37: =IF(ТаблицаВыработки[[#This Row],[Дата]]="","",DATE(VALUE(RIGHT(ТаблицаВыработки[[#This Row],[Дата]],4)),VALUE(MID(ТаблицаВыработки[[#This Row],[Дата]],4,2)),1)) | C37: Ночь | D37: Линия 2 | E37: Дауылбай М. | F37: 4 | G37: 3300 | H37: 3140 | I37: =SUMIFS(рапорт!$K:$K,рапорт!$A:$A,DATE(VALUE(RIGHT(ТаблицаВыработки[[#This Row],[Дата]],4)),VALUE(MID(ТаблицаВыработки[[#This Row],[Дата]],4,2)),VALUE(LEFT(ТаблицаВыработки[[#This Row],[Дата]],2))),рапорт!$D:$D,LOWER(ТаблицаВыработки[[#This Row],[Тип смены]])&"*",рапорт!$E:$E,LEFT(ТаблицаВыработки[[#This Row],[Мастер]],SEARCH(" ",ТаблицаВыработки[[#This Row],[Мастер]]&" ")-1)&"*") | J37: =SUMIFS(рапорт!$L:$L,рапорт!$A:$A,DATE(VALUE(RIGHT(ТаблицаВыработки[[#This Row],[Дата]],4)),VALUE(MID(ТаблицаВыработки[[#This Row],[Дата]],4,2)),VALUE(LEFT(ТаблицаВыработки[[#This Row],[Дата]],2))),рапорт!$D:$D,LOWER(ТаблицаВыработки[[#This Row],[Тип смены]])&"*",рапорт!$E:$E,LEFT(ТаблицаВыработки[[#This Row],[Мастер]],SEARCH(" ",ТаблицаВыработки[[#This Row],[Мастер]]&" ")-1)&"*")
A38: 21.06.2026 | B38: =IF(ТаблицаВыработки[[#This Row],[Дата]]="","",DATE(VALUE(RIGHT(ТаблицаВыработки[[#This Row],[Дата]],4)),VALUE(MID(ТаблицаВыработки[[#This Row],[Дата]],4,2)),1)) | C38: Ночь | D38: Линия 2 | E38: Бекбосынов Р. | F38: 1 | G38: 3300 | I38: =SUMIFS(рапорт!$K:$K,рапорт!$A:$A,DATE(VALUE(RIGHT(ТаблицаВыработки[[#This Row],[Дата]],4)),VALUE(MID(ТаблицаВыработки[[#This Row],[Дата]],4,2)),VALUE(LEFT(ТаблицаВыработки[[#This Row],[Дата]],2))),рапорт!$D:$D,LOWER(ТаблицаВыработки[[#This Row],[Тип смены]])&"*",рапорт!$E:$E,LEFT(ТаблицаВыработки[[#This Row],[Мастер]],SEARCH(" ",ТаблицаВыработки[[#This Row],[Мастер]]&" ")-1)&"*") | J38: =SUMIFS(рапорт!$L:$L,рапорт!$A:$A,DATE(VALUE(RIGHT(ТаблицаВыработки[[#This Row],[Дата]],4)),VALUE(MID(ТаблицаВыработки[[#This Row],[Дата]],4,2)),VALUE(LEFT(ТаблицаВыработки[[#This Row],[Дата]],2))),рапорт!$D:$D,LOWER(ТаблицаВыработки[[#This Row],[Тип смены]])&"*",рапорт!$E:$E,LEFT(ТаблицаВыработки[[#This Row],[Мастер]],SEARCH(" ",ТаблицаВыработки[[#This Row],[Мастер]]&" ")-1)&"*")
A39: 21.06.2026 | B39: =IF(ТаблицаВыработки[[#This Row],[Дата]]="","",DATE(VALUE(RIGHT(ТаблицаВыработки[[#This Row],[Дата]],4)),VALUE(MID(ТаблицаВыработки[[#This Row],[Дата]],4,2)),1)) | C39: День | D39: Линия 2 | E39: Султанулы С. | F39: 3 | G39: 2700 | I39: =SUMIFS(рапорт!$K:$K,рапорт!$A:$A,DATE(VALUE(RIGHT(ТаблицаВыработки[[#This Row],[Дата]],4)),VALUE(MID(ТаблицаВыработки[[#This Row],[Дата]],4,2)),VALUE(LEFT(ТаблицаВыработки[[#This Row],[Дата]],2))),рапорт!$D:$D,LOWER(ТаблицаВыработки[[#This Row],[Тип смены]])&"*",рапорт!$E:$E,LEFT(ТаблицаВыработки[[#This Row],[Мастер]],SEARCH(" ",ТаблицаВыработки[[#This Row],[Мастер]]&" ")-1)&"*") | J39: =SUMIFS(рапорт!$L:$L,рапорт!$A:$A,DATE(VALUE(RIGHT(ТаблицаВыработки[[#This Row],[Дата]],4)),VALUE(MID(ТаблицаВыработки[[#This Row],[Дата]],4,2)),VALUE(LEFT(ТаблицаВыработки[[#This Row],[Дата]],2))),рапорт!$D:$D,LOWER(ТаблицаВыработки[[#This Row],[Тип смены]])&"*",рапорт!$E:$E,LEFT(ТаблицаВыработки[[#This Row],[Мастер]],SEARCH(" ",ТаблицаВыработки[[#This Row],[Мастер]]&" ")-1)&"*")
A40: 22.06.2026 | B40: =IF(ТаблицаВыработки[[#This Row],[Дата]]="","",DATE(VALUE(RIGHT(ТаблицаВыработки[[#This Row],[Дата]],4)),VALUE(MID(ТаблицаВыработки[[#This Row],[Дата]],4,2)),1)) | C40: Ночь | D40: Линия 2 | E40: Султанулы С. | F40: 3 | G40: 3300 | I40: =SUMIFS(рапорт!$K:$K,рапорт!$A:$A,DATE(VALUE(RIGHT(ТаблицаВыработки[[#This Row],[Дата]],4)),VALUE(MID(ТаблицаВыработки[[#This Row],[Дата]],4,2)),VALUE(LEFT(ТаблицаВыработки[[#This Row],[Дата]],2))),рапорт!$D:$D,LOWER(ТаблицаВыработки[[#This Row],[Тип смены]])&"*",рапорт!$E:$E,LEFT(ТаблицаВыработки[[#This Row],[Мастер]],SEARCH(" ",ТаблицаВыработки[[#This Row],[Мастер]]&" ")-1)&"*") | J40: =SUMIFS(рапорт!$L:$L,рапорт!$A:$A,DATE(VALUE(RIGHT(ТаблицаВыработки[[#This Row],[Дата]],4)),VALUE(MID(ТаблицаВыработки[[#This Row],[Дата]],4,2)),VALUE(LEFT(ТаблицаВыработки[[#This Row],[Дата]],2))),рапорт!$D:$D,LOWER(ТаблицаВыработки[[#This Row],[Тип смены]])&"*",рапорт!$E:$E,LEFT(ТаблицаВыработки[[#This Row],[Мастер]],SEARCH(" ",ТаблицаВыработки[[#This Row],[Мастер]]&" ")-1)&"*")
A41: 22.06.2026 | B41: =IF(ТаблицаВыработки[[#This Row],[Дата]]="","",DATE(VALUE(RIGHT(ТаблицаВыработки[[#This Row],[Дата]],4)),VALUE(MID(ТаблицаВыработки[[#This Row],[Дата]],4,2)),1)) | C41: День | D41: Линия 2 | E41: Дауылбай М. | F41: 4 | G41: 0 | H41: 54 | I41: =SUMIFS(рапорт!$K:$K,рапорт!$A:$A,DATE(VALUE(RIGHT(ТаблицаВыработки[[#This Row],[Дата]],4)),VALUE(MID(ТаблицаВыработки[[#This Row],[Дата]],4,2)),VALUE(LEFT(ТаблицаВыработки[[#This Row],[Дата]],2))),рапорт!$D:$D,LOWER(ТаблицаВыработки[[#This Row],[Тип смены]])&"*",рапорт!$E:$E,LEFT(ТаблицаВыработки[[#This Row],[Мастер]],SEARCH(" ",ТаблицаВыработки[[#This Row],[Мастер]]&" ")-1)&"*") | J41: =SUMIFS(рапорт!$L:$L,рапорт!$A:$A,DATE(VALUE(RIGHT(ТаблицаВыработки[[#This Row],[Дата]],4)),VALUE(MID(ТаблицаВыработки[[#This Row],[Дата]],4,2)),VALUE(LEFT(ТаблицаВыработки[[#This Row],[Дата]],2))),рапорт!$D:$D,LOWER(ТаблицаВыработки[[#This Row],[Тип смены]])&"*",рапорт!$E:$E,LEFT(ТаблицаВыработки[[#This Row],[Мастер]],SEARCH(" ",ТаблицаВыработки[[#This Row],[Мастер]]&" ")-1)&"*")
A42: 23.06.2026 | B42: =IF(ТаблицаВыработки[[#This Row],[Дата]]="","",DATE(VALUE(RIGHT(ТаблицаВыработки[[#This Row],[Дата]],4)),VALUE(MID(ТаблицаВыработки[[#This Row],[Дата]],4,2)),1)) | C42: День | D42: Линия 2 | E42: Монаев С. | F42: 2 | G42: 2700 | I42: =SUMIFS(рапорт!$K:$K,рапорт!$A:$A,DATE(VALUE(RIGHT(ТаблицаВыработки[[#This Row],[Дата]],4)),VALUE(MID(ТаблицаВыработки[[#This Row],[Дата]],4,2)),VALUE(LEFT(ТаблицаВыработки[[#This Row],[Дата]],2))),рапорт!$D:$D,LOWER(ТаблицаВыработки[[#This Row],[Тип смены]])&"*",рапорт!$E:$E,LEFT(ТаблицаВыработки[[#This Row],[Мастер]],SEARCH(" ",ТаблицаВыработки[[#This Row],[Мастер]]&" ")-1)&"*") | J42: =SUMIFS(рапорт!$L:$L,рапорт!$A:$A,DATE(VALUE(RIGHT(ТаблицаВыработки[[#This Row],[Дата]],4)),VALUE(MID(ТаблицаВыработки[[#This Row],[Дата]],4,2)),VALUE(LEFT(ТаблицаВыработки[[#This Row],[Дата]],2))),рапорт!$D:$D,LOWER(ТаблицаВыработки[[#This Row],[Тип смены]])&"*",рапорт!$E:$E,LEFT(ТаблицаВыработки[[#This Row],[Мастер]],SEARCH(" ",ТаблицаВыработки[[#This Row],[Мастер]]&" ")-1)&"*")
A43: 24.06.2026 | B43: =IF(ТаблицаВыработки[[#This Row],[Дата]]="","",DATE(VALUE(RIGHT(ТаблицаВыработки[[#This Row],[Дата]],4)),VALUE(MID(ТаблицаВыработки[[#This Row],[Дата]],4,2)),1)) | C43: День | D43: Линия 2 | E43: Бекбосынов Р. | F43: 1 | G43: 2700 | I43: =SUMIFS(рапорт!$K:$K,рапорт!$A:$A,DATE(VALUE(RIGHT(ТаблицаВыработки[[#This Row],[Дата]],4)),VALUE(MID(ТаблицаВыработки[[#This Row],[Дата]],4,2)),VALUE(LEFT(ТаблицаВыработки[[#This Row],[Дата]],2))),рапорт!$D:$D,LOWER(ТаблицаВыработки[[#This Row],[Тип смены]])&"*",рапорт!$E:$E,LEFT(ТаблицаВыработки[[#This Row],[Мастер]],SEARCH(" ",ТаблицаВыработки[[#This Row],[Мастер]]&" ")-1)&"*") | J43: =SUMIFS(рапорт!$L:$L,рапорт!$A:$A,DATE(VALUE(RIGHT(ТаблицаВыработки[[#This Row],[Дата]],4)),VALUE(MID(ТаблицаВыработки[[#This Row],[Дата]],4,2)),VALUE(LEFT(ТаблицаВыработки[[#This Row],[Дата]],2))),рапорт!$D:$D,LOWER(ТаблицаВыработки[[#This Row],[Тип смены]])&"*",рапорт!$E:$E,LEFT(ТаблицаВыработки[[#This Row],[Мастер]],SEARCH(" ",ТаблицаВыработки[[#This Row],[Мастер]]&" ")-1)&"*")
A44: 24.06.2026 | B44: =IF(ТаблицаВыработки[[#This Row],[Дата]]="","",DATE(VALUE(RIGHT(ТаблицаВыработки[[#This Row],[Дата]],4)),VALUE(MID(ТаблицаВыработки[[#This Row],[Дата]],4,2)),1)) | C44: Ночь | D44: Линия 2 | E44: Монаев С. | F44: 2 | G44: 3300 | I44: =SUMIFS(рапорт!$K:$K,рапорт!$A:$A,DATE(VALUE(RIGHT(ТаблицаВыработки[[#This Row],[Дата]],4)),VALUE(MID(ТаблицаВыработки[[#This Row],[Дата]],4,2)),VALUE(LEFT(ТаблицаВыработки[[#This Row],[Дата]],2))),рапорт!$D:$D,LOWER(ТаблицаВыработки[[#This Row],[Тип смены]])&"*",рапорт!$E:$E,LEFT(ТаблицаВыработки[[#This Row],[Мастер]],SEARCH(" ",ТаблицаВыработки[[#This Row],[Мастер]]&" ")-1)&"*") | J44: =SUMIFS(рапорт!$L:$L,рапорт!$A:$A,DATE(VALUE(RIGHT(ТаблицаВыработки[[#This Row],[Дата]],4)),VALUE(MID(ТаблицаВыработки[[#This Row],[Дата]],4,2)),VALUE(LEFT(ТаблицаВыработки[[#This Row],[Дата]],2))),рапорт!$D:$D,LOWER(ТаблицаВыработки[[#This Row],[Тип смены]])&"*",рапорт!$E:$E,LEFT(ТаблицаВыработки[[#This Row],[Мастер]],SEARCH(" ",ТаблицаВыработки[[#This Row],[Мастер]]&" ")-1)&"*")
A45: 24.06.2026 | B45: =IF(ТаблицаВыработки[[#This Row],[Дата]]="","",DATE(VALUE(RIGHT(ТаблицаВыработки[[#This Row],[Дата]],4)),VALUE(MID(ТаблицаВыработки[[#This Row],[Дата]],4,2)),1)) | C45: Ночь | D45: Линия 2 | E45: Дауылбай М. | F45: 4 | G45: 3300 | I45: =SUMIFS(рапорт!$K:$K,рапорт!$A:$A,DATE(VALUE(RIGHT(ТаблицаВыработки[[#This Row],[Дата]],4)),VALUE(MID(ТаблицаВыработки[[#This Row],[Дата]],4,2)),VALUE(LEFT(ТаблицаВыработки[[#This Row],[Дата]],2))),рапорт!$D:$D,LOWER(ТаблицаВыработки[[#This Row],[Тип смены]])&"*",рапорт!$E:$E,LEFT(ТаблицаВыработки[[#This Row],[Мастер]],SEARCH(" ",ТаблицаВыработки[[#This Row],[Мастер]]&" ")-1)&"*") | J45: =SUMIFS(рапорт!$L:$L,рапорт!$A:$A,DATE(VALUE(RIGHT(ТаблицаВыработки[[#This Row],[Дата]],4)),VALUE(MID(ТаблицаВыработки[[#This Row],[Дата]],4,2)),VALUE(LEFT(ТаблицаВыработки[[#This Row],[Дата]],2))),рапорт!$D:$D,LOWER(ТаблицаВыработки[[#This Row],[Тип смены]])&"*",рапорт!$E:$E,LEFT(ТаблицаВыработки[[#This Row],[Мастер]],SEARCH(" ",ТаблицаВыработки[[#This Row],[Мастер]]&" ")-1)&"*")
A46: 25.06.2026 | B46: =IF(ТаблицаВыработки[[#This Row],[Дата]]="","",DATE(VALUE(RIGHT(ТаблицаВыработки[[#This Row],[Дата]],4)),VALUE(MID(ТаблицаВыработки[[#This Row],[Дата]],4,2)),1)) | C46: Ночь | D46: Линия 2 | E46: Бекбосынов Р. | F46: 1 | G46: 3300 | I46: =SUMIFS(рапорт!$K:$K,рапорт!$A:$A,DATE(VALUE(RIGHT(ТаблицаВыработки[[#This Row],[Дата]],4)),VALUE(MID(ТаблицаВыработки[[#This Row],[Дата]],4,2)),VALUE(LEFT(ТаблицаВыработки[[#This Row],[Дата]],2))),рапорт!$D:$D,LOWER(ТаблицаВыработки[[#This Row],[Тип смены]])&"*",рапорт!$E:$E,LEFT(ТаблицаВыработки[[#This Row],[Мастер]],SEARCH(" ",ТаблицаВыработки[[#This Row],[Мастер]]&" ")-1)&"*") | J46: =SUMIFS(рапорт!$L:$L,рапорт!$A:$A,DATE(VALUE(RIGHT(ТаблицаВыработки[[#This Row],[Дата]],4)),VALUE(MID(ТаблицаВыработки[[#This Row],[Дата]],4,2)),VALUE(LEFT(ТаблицаВыработки[[#This Row],[Дата]],2))),рапорт!$D:$D,LOWER(ТаблицаВыработки[[#This Row],[Тип смены]])&"*",рапорт!$E:$E,LEFT(ТаблицаВыработки[[#This Row],[Мастер]],SEARCH(" ",ТаблицаВыработки[[#This Row],[Мастер]]&" ")-1)&"*")
A47: 25.06.2026 | B47: =IF(ТаблицаВыработки[[#This Row],[Дата]]="","",DATE(VALUE(RIGHT(ТаблицаВыработки[[#This Row],[Дата]],4)),VALUE(MID(ТаблицаВыработки[[#This Row],[Дата]],4,2)),1)) | C47: День | D47: Линия 2 | E47: Султанулы С. | F47: 3 | G47: 2700 | I47: =SUMIFS(рапорт!$K:$K,рапорт!$A:$A,DATE(VALUE(RIGHT(ТаблицаВыработки[[#This Row],[Дата]],4)),VALUE(MID(ТаблицаВыработки[[#This Row],[Дата]],4,2)),VALUE(LEFT(ТаблицаВыработки[[#This Row],[Дата]],2))),рапорт!$D:$D,LOWER(ТаблицаВыработки[[#This Row],[Тип смены]])&"*",рапорт!$E:$E,LEFT(ТаблицаВыработки[[#This Row],[Мастер]],SEARCH(" ",ТаблицаВыработки[[#This Row],[Мастер]]&" ")-1)&"*") | J47: =SUMIFS(рапорт!$L:$L,рапорт!$A:$A,DATE(VALUE(RIGHT(ТаблицаВыработки[[#This Row],[Дата]],4)),VALUE(MID(ТаблицаВыработки[[#This Row],[Дата]],4,2)),VALUE(LEFT(ТаблицаВыработки[[#This Row],[Дата]],2))),рапорт!$D:$D,LOWER(ТаблицаВыработки[[#This Row],[Тип смены]])&"*",рапорт!$E:$E,LEFT(ТаблицаВыработки[[#This Row],[Мастер]],SEARCH(" ",ТаблицаВыработки[[#This Row],[Мастер]]&" ")-1)&"*")
A48: 26.06.2026 | B48: =IF(ТаблицаВыработки[[#This Row],[Дата]]="","",DATE(VALUE(RIGHT(ТаблицаВыработки[[#This Row],[Дата]],4)),VALUE(MID(ТаблицаВыработки[[#This Row],[Дата]],4,2)),1)) | C48: Ночь | D48: Линия 2 | E48: Султанулы С. | F48: 3 | G48: 3300 | I48: =SUMIFS(рапорт!$K:$K,рапорт!$A:$A,DATE(VALUE(RIGHT(ТаблицаВыработки[[#This Row],[Дата]],4)),VALUE(MID(ТаблицаВыработки[[#This Row],[Дата]],4,2)),VALUE(LEFT(ТаблицаВыработки[[#This Row],[Дата]],2))),рапорт!$D:$D,LOWER(ТаблицаВыработки[[#This Row],[Тип смены]])&"*",рапорт!$E:$E,LEFT(ТаблицаВыработки[[#This Row],[Мастер]],SEARCH(" ",ТаблицаВыработки[[#This Row],[Мастер]]&" ")-1)&"*") | J48: =SUMIFS(рапорт!$L:$L,рапорт!$A:$A,DATE(VALUE(RIGHT(ТаблицаВыработки[[#This Row],[Дата]],4)),VALUE(MID(ТаблицаВыработки[[#This Row],[Дата]],4,2)),VALUE(LEFT(ТаблицаВыработки[[#This Row],[Дата]],2))),рапорт!$D:$D,LOWER(ТаблицаВыработки[[#This Row],[Тип смены]])&"*",рапорт!$E:$E,LEFT(ТаблицаВыработки[[#This Row],[Мастер]],SEARCH(" ",ТаблицаВыработки[[#This Row],[Мастер]]&" ")-1)&"*")
A49: 26.06.2026 | B49: =IF(ТаблицаВыработки[[#This Row],[Дата]]="","",DATE(VALUE(RIGHT(ТаблицаВыработки[[#This Row],[Дата]],4)),VALUE(MID(ТаблицаВыработки[[#This Row],[Дата]],4,2)),1)) | C49: День | D49: Линия 2 | E49: Дауылбай М. | F49: 4 | G49: 2700 | I49: =SUMIFS(рапорт!$K:$K,рапорт!$A:$A,DATE(VALUE(RIGHT(ТаблицаВыработки[[#This Row],[Дата]],4)),VALUE(MID(ТаблицаВыработки[[#This Row],[Дата]],4,2)),VALUE(LEFT(ТаблицаВыработки[[#This Row],[Дата]],2))),рапорт!$D:$D,LOWER(ТаблицаВыработки[[#This Row],[Тип смены]])&"*",рапорт!$E:$E,LEFT(ТаблицаВыработки[[#This Row],[Мастер]],SEARCH(" ",ТаблицаВыработки[[#This Row],[Мастер]]&" ")-1)&"*") | J49: =SUMIFS(рапорт!$L:$L,рапорт!$A:$A,DATE(VALUE(RIGHT(ТаблицаВыработки[[#This Row],[Дата]],4)),VALUE(MID(ТаблицаВыработки[[#This Row],[Дата]],4,2)),VALUE(LEFT(ТаблицаВыработки[[#This Row],[Дата]],2))),рапорт!$D:$D,LOWER(ТаблицаВыработки[[#This Row],[Тип смены]])&"*",рапорт!$E:$E,LEFT(ТаблицаВыработки[[#This Row],[Мастер]],SEARCH(" ",ТаблицаВыработки[[#This Row],[Мастер]]&" ")-1)&"*")
A50: 27.06.2026 | B50: =IF(ТаблицаВыработки[[#This Row],[Дата]]="","",DATE(VALUE(RIGHT(ТаблицаВыработки[[#This Row],[Дата]],4)),VALUE(MID(ТаблицаВыработки[[#This Row],[Дата]],4,2)),1)) | C50: День | D50: Линия 2 | E50: Монаев С. | F50: 2 | G50: 2700 | I50: =SUMIFS(рапорт!$K:$K,рапорт!$A:$A,DATE(VALUE(RIGHT(ТаблицаВыработки[[#This Row],[Дата]],4)),VALUE(MID(ТаблицаВыработки[[#This Row],[Дата]],4,2)),VALUE(LEFT(ТаблицаВыработки[[#This Row],[Дата]],2))),рапорт!$D:$D,LOWER(ТаблицаВыработки[[#This Row],[Тип смены]])&"*",рапорт!$E:$E,LEFT(ТаблицаВыработки[[#This Row],[Мастер]],SEARCH(" ",ТаблицаВыработки[[#This Row],[Мастер]]&" ")-1)&"*") | J50: =SUMIFS(рапорт!$L:$L,рапорт!$A:$A,DATE(VALUE(RIGHT(ТаблицаВыработки[[#This Row],[Дата]],4)),VALUE(MID(ТаблицаВыработки[[#This Row],[Дата]],4,2)),VALUE(LEFT(ТаблицаВыработки[[#This Row],[Дата]],2))),рапорт!$D:$D,LOWER(ТаблицаВыработки[[#This Row],[Тип смены]])&"*",рапорт!$E:$E,LEFT(ТаблицаВыработки[[#This Row],[Мастер]],SEARCH(" ",ТаблицаВыработки[[#This Row],[Мастер]]&" ")-1)&"*")
A51: 28.06.2026 | B51: =IF(ТаблицаВыработки[[#This Row],[Дата]]="","",DATE(VALUE(RIGHT(ТаблицаВыработки[[#This Row],[Дата]],4)),VALUE(MID(ТаблицаВыработки[[#This Row],[Дата]],4,2)),1)) | C51: День | D51: Линия 2 | E51: Бекбосынов Р. | F51: 1 | G51: 2700 | I51: =SUMIFS(рапорт!$K:$K,рапорт!$A:$A,DATE(VALUE(RIGHT(ТаблицаВыработки[[#This Row],[Дата]],4)),VALUE(MID(ТаблицаВыработки[[#This Row],[Дата]],4,2)),VALUE(LEFT(ТаблицаВыработки[[#This Row],[Дата]],2))),рапорт!$D:$D,LOWER(ТаблицаВыработки[[#This Row],[Тип смены]])&"*",рапорт!$E:$E,LEFT(ТаблицаВыработки[[#This Row],[Мастер]],SEARCH(" ",ТаблицаВыработки[[#This Row],[Мастер]]&" ")-1)&"*") | J51: =SUMIFS(рапорт!$L:$L,рапорт!$A:$A,DATE(VALUE(RIGHT(ТаблицаВыработки[[#This Row],[Дата]],4)),VALUE(MID(ТаблицаВыработки[[#This Row],[Дата]],4,2)),VALUE(LEFT(ТаблицаВыработки[[#This Row],[Дата]],2))),рапорт!$D:$D,LOWER(ТаблицаВыработки[[#This Row],[Тип смены]])&"*",рапорт!$E:$E,LEFT(ТаблицаВыработки[[#This Row],[Мастер]],SEARCH(" ",ТаблицаВыработки[[#This Row],[Мастер]]&" ")-1)&"*")
A52: 28.06.2026 | B52: =IF(ТаблицаВыработки[[#This Row],[Дата]]="","",DATE(VALUE(RIGHT(ТаблицаВыработки[[#This Row],[Дата]],4)),VALUE(MID(ТаблицаВыработки[[#This Row],[Дата]],4,2)),1)) | C52: Ночь | D52: Линия 2 | E52: Монаев С. | F52: 2 | G52: 3300 | I52: =SUMIFS(рапорт!$K:$K,рапорт!$A:$A,DATE(VALUE(RIGHT(ТаблицаВыработки[[#This Row],[Дата]],4)),VALUE(MID(ТаблицаВыработки[[#This Row],[Дата]],4,2)),VALUE(LEFT(ТаблицаВыработки[[#This Row],[Дата]],2))),рапорт!$D:$D,LOWER(ТаблицаВыработки[[#This Row],[Тип смены]])&"*",рапорт!$E:$E,LEFT(ТаблицаВыработки[[#This Row],[Мастер]],SEARCH(" ",ТаблицаВыработки[[#This Row],[Мастер]]&" ")-1)&"*") | J52: =SUMIFS(рапорт!$L:$L,рапорт!$A:$A,DATE(VALUE(RIGHT(ТаблицаВыработки[[#This Row],[Дата]],4)),VALUE(MID(ТаблицаВыработки[[#This Row],[Дата]],4,2)),VALUE(LEFT(ТаблицаВыработки[[#This Row],[Дата]],2))),рапорт!$D:$D,LOWER(ТаблицаВыработки[[#This Row],[Тип смены]])&"*",рапорт!$E:$E,LEFT(ТаблицаВыработки[[#This Row],[Мастер]],SEARCH(" ",ТаблицаВыработки[[#This Row],[Мастер]]&" ")-1)&"*")
A53: 28.06.2026 | B53: =IF(ТаблицаВыработки[[#This Row],[Дата]]="","",DATE(VALUE(RIGHT(ТаблицаВыработки[[#This Row],[Дата]],4)),VALUE(MID(ТаблицаВыработки[[#This Row],[Дата]],4,2)),1)) | C53: Ночь | D53: Линия 2 | E53: Дауылбай М. | F53: 4 | G53: 3300 | I53: =SUMIFS(рапорт!$K:$K,рапорт!$A:$A,DATE(VALUE(RIGHT(ТаблицаВыработки[[#This Row],[Дата]],4)),VALUE(MID(ТаблицаВыработки[[#This Row],[Дата]],4,2)),VALUE(LEFT(ТаблицаВыработки[[#This Row],[Дата]],2))),рапорт!$D:$D,LOWER(ТаблицаВыработки[[#This Row],[Тип смены]])&"*",рапорт!$E:$E,LEFT(ТаблицаВыработки[[#This Row],[Мастер]],SEARCH(" ",ТаблицаВыработки[[#This Row],[Мастер]]&" ")-1)&"*") | J53: =SUMIFS(рапорт!$L:$L,рапорт!$A:$A,DATE(VALUE(RIGHT(ТаблицаВыработки[[#This Row],[Дата]],4)),VALUE(MID(ТаблицаВыработки[[#This Row],[Дата]],4,2)),VALUE(LEFT(ТаблицаВыработки[[#This Row],[Дата]],2))),рапорт!$D:$D,LOWER(ТаблицаВыработки[[#This Row],[Тип смены]])&"*",рапорт!$E:$E,LEFT(ТаблицаВыработки[[#This Row],[Мастер]],SEARCH(" ",ТаблицаВыработки[[#This Row],[Мастер]]&" ")-1)&"*")
... A56: 30.06.2026 | B56: =IF(ТаблицаВыработки[[#This Row],[Дата]]="","",DATE(VALUE(RIGHT(ТаблицаВыработки[[#This Row],[Дата]],4)),VALUE(MID(ТаблицаВыработки[[#This Row],[Дата]],4,2)),1)) | C56: Ночь | D56: Линия 2 | E56: Султанулы С. | F56: 3 | G56: 3300 | I56: =SUMIFS(рапорт!$K:$K,рапорт!$A:$A,DATE(VALUE(RIGHT(ТаблицаВыработки[[#This Row],[Дата]],4)),VALUE(MID(ТаблицаВыработки[[#This Row],[Дата]],4,2)),VALUE(LEFT(ТаблицаВыработки[[#This Row],[Дата]],2))),рапорт!$D:$D,LOWER(ТаблицаВыработки[[#This Row],[Тип смены]])&"*",рапорт!$E:$E,LEFT(ТаблицаВыработки[[#This Row],[Мастер]],SEARCH(" ",ТаблицаВыработки[[#This Row],[Мастер]]&" ")-1)&"*") | J56: =SUMIFS(рапорт!$L:$L,рапорт!$A:$A,DATE(VALUE(RIGHT(ТаблицаВыработки[[#This Row],[Дата]],4)),VALUE(MID(ТаблицаВыработки[[#This Row],[Дата]],4,2)),VALUE(LEFT(ТаблицаВыработки[[#This Row],[Дата]],2))),рапорт!$D:$D,LOWER(ТаблицаВыработки[[#This Row],[Тип смены]])&"*",рапорт!$E:$E,LEFT(ТаблицаВыработки[[#This Row],[Мастер]],SEARCH(" ",ТаблицаВыработки[[#This Row],[Мастер]]&" ")-1)&"*")
B57: =IF(ТаблицаВыработки[[#This Row],[Дата]]="","",DATE(VALUE(RIGHT(ТаблицаВыработки[[#This Row],[Дата]],4)),VALUE(MID(ТаблицаВыработки[[#This Row],[Дата]],4,2)),1)) | G57: =IF(ТаблицаВыработки[[#This Row],[Тип смены]]="День",2700,IF(ТаблицаВыработки[[#This Row],[Тип смены]]="Ночь",3300,"")) | I57: =SUMIFS(рапорт!$K:$K,рапорт!$A:$A,DATE(VALUE(RIGHT(ТаблицаВыработки[[#This Row],[Дата]],4)),VALUE(MID(ТаблицаВыработки[[#This Row],[Дата]],4,2)),VALUE(LEFT(ТаблицаВыработки[[#This Row],[Дата]],2))),рапорт!$D:$D,LOWER(ТаблицаВыработки[[#This Row],[Тип смены]])&"*",рапорт!$E:$E,LEFT(ТаблицаВыработки[[#This Row],[Мастер]],SEARCH(" ",ТаблицаВыработки[[#This Row],[Мастер]]&" ")-1)&"*") | J57: =SUMIFS(рапорт!$L:$L,рапорт!$A:$A,DATE(VALUE(RIGHT(ТаблицаВыработки[[#This Row],[Дата]],4)),VALUE(MID(ТаблицаВыработки[[#This Row],[Дата]],4,2)),VALUE(LEFT(ТаблицаВыработки[[#This Row],[Дата]],2))),рапорт!$D:$D,LOWER(ТаблицаВыработки[[#This Row],[Тип смены]])&"*",рапорт!$E:$E,LEFT(ТаблицаВыработки[[#This Row],[Мастер]],SEARCH(" ",ТаблицаВыработки[[#This Row],[Мастер]]&" ")-1)&"*")
B58: =IF(ТаблицаВыработки[[#This Row],[Дата]]="","",DATE(VALUE(RIGHT(ТаблицаВыработки[[#This Row],[Дата]],4)),VALUE(MID(ТаблицаВыработки[[#This Row],[Дата]],4,2)),1)) | G58: =IF(ТаблицаВыработки[[#This Row],[Тип смены]]="День",2700,IF(ТаблицаВыработки[[#This Row],[Тип смены]]="Ночь",3300,"")) | I58: =SUMIFS(рапорт!$K:$K,рапорт!$A:$A,DATE(VALUE(RIGHT(ТаблицаВыработки[[#This Row],[Дата]],4)),VALUE(MID(ТаблицаВыработки[[#This Row],[Дата]],4,2)),VALUE(LEFT(ТаблицаВыработки[[#This Row],[Дата]],2))),рапорт!$D:$D,LOWER(ТаблицаВыработки[[#This Row],[Тип смены]])&"*",рапорт!$E:$E,LEFT(ТаблицаВыработки[[#This Row],[Мастер]],SEARCH(" ",ТаблицаВыработки[[#This Row],[Мастер]]&" ")-1)&"*") | J58: =SUMIFS(рапорт!$L:$L,рапорт!$A:$A,DATE(VALUE(RIGHT(ТаблицаВыработки[[#This Row],[Дата]],4)),VALUE(MID(ТаблицаВыработки[[#This Row],[Дата]],4,2)),VALUE(LEFT(ТаблицаВыработки[[#This Row],[Дата]],2))),рапорт!$D:$D,LOWER(ТаблицаВыработки[[#This Row],[Тип смены]])&"*",рапорт!$E:$E,LEFT(ТаблицаВыработки[[#This Row],[Мастер]],SEARCH(" ",ТаблицаВыработки[[#This Row],[Мастер]]&" ")-1)&"*")
B59: =IF(ТаблицаВыработки[[#This Row],[Дата]]="","",DATE(VALUE(RIGHT(ТаблицаВыработки[[#This Row],[Дата]],4)),VALUE(MID(ТаблицаВыработки[[#This Row],[Дата]],4,2)),1)) | G59: =IF(ТаблицаВыработки[[#This Row],[Тип смены]]="День",2700,IF(ТаблицаВыработки[[#This Row],[Тип смены]]="Ночь",3300,"")) | I59: =SUMIFS(рапорт!$K:$K,рапорт!$A:$A,DATE(VALUE(RIGHT(ТаблицаВыработки[[#This Row],[Дата]],4)),VALUE(MID(ТаблицаВыработки[[#This Row],[Дата]],4,2)),VALUE(LEFT(ТаблицаВыработки[[#This Row],[Дата]],2))),рапорт!$D:$D,LOWER(ТаблицаВыработки[[#This Row],[Тип смены]])&"*",рапорт!$E:$E,LEFT(ТаблицаВыработки[[#This Row],[Мастер]],SEARCH(" ",ТаблицаВыработки[[#This Row],[Мастер]]&" ")-1)&"*") | J59: =SUMIFS(рапорт!$L:$L,рапорт!$A:$A,DATE(VALUE(RIGHT(ТаблицаВыработки[[#This Row],[Дата]],4)),VALUE(MID(ТаблицаВыработки[[#This Row],[Дата]],4,2)),VALUE(LEFT(ТаблицаВыработки[[#This Row],[Дата]],2))),рапорт!$D:$D,LOWER(ТаблицаВыработки[[#This Row],[Тип смены]])&"*",рапорт!$E:$E,LEFT(ТаблицаВыработки[[#This Row],[Мастер]],SEARCH(" ",ТаблицаВыработки[[#This Row],[Мастер]]&" ")-1)&"*")
B60: =IF(ТаблицаВыработки[[#This Row],[Дата]]="","",DATE(VALUE(RIGHT(ТаблицаВыработки[[#This Row],[Дата]],4)),VALUE(MID(ТаблицаВыработки[[#This Row],[Дата]],4,2)),1)) | G60: =IF(ТаблицаВыработки[[#This Row],[Тип смены]]="День",2700,IF(ТаблицаВыработки[[#This Row],[Тип смены]]="Ночь",3300,"")) | I60: =SUMIFS(рапорт!$K:$K,рапорт!$A:$A,DATE(VALUE(RIGHT(ТаблицаВыработки[[#This Row],[Дата]],4)),VALUE(MID(ТаблицаВыработки[[#This Row],[Дата]],4,2)),VALUE(LEFT(ТаблицаВыработки[[#This Row],[Дата]],2))),рапорт!$D:$D,LOWER(ТаблицаВыработки[[#This Row],[Тип смены]])&"*",рапорт!$E:$E,LEFT(ТаблицаВыработки[[#This Row],[Мастер]],SEARCH(" ",ТаблицаВыработки[[#This Row],[Мастер]]&" ")-1)&"*") | J60: =SUMIFS(рапорт!$L:$L,рапорт!$A:$A,DATE(VALUE(RIGHT(ТаблицаВыработки[[#This Row],[Дата]],4)),VALUE(MID(ТаблицаВыработки[[#This Row],[Дата]],4,2)),VALUE(LEFT(ТаблицаВыработки[[#This Row],[Дата]],2))),рапорт!$D:$D,LOWER(ТаблицаВыработки[[#This Row],[Тип смены]])&"*",рапорт!$E:$E,LEFT(ТаблицаВыработки[[#This Row],[Мастер]],SEARCH(" ",ТаблицаВыработки[[#This Row],[Мастер]]&" ")-1)&"*")
B61: =IF(ТаблицаВыработки[[#This Row],[Дата]]="","",DATE(VALUE(RIGHT(ТаблицаВыработки[[#This Row],[Дата]],4)),VALUE(MID(ТаблицаВыработки[[#This Row],[Дата]],4,2)),1)) | G61: =IF(ТаблицаВыработки[[#This Row],[Тип смены]]="День",2700,IF(ТаблицаВыработки[[#This Row],[Тип смены]]="Ночь",3300,"")) | I61: =SUMIFS(рапорт!$K:$K,рапорт!$A:$A,DATE(VALUE(RIGHT(ТаблицаВыработки[[#This Row],[Дата]],4)),VALUE(MID(ТаблицаВыработки[[#This Row],[Дата]],4,2)),VALUE(LEFT(ТаблицаВыработки[[#This Row],[Дата]],2))),рапорт!$D:$D,LOWER(ТаблицаВыработки[[#This Row],[Тип смены]])&"*",рапорт!$E:$E,LEFT(ТаблицаВыработки[[#This Row],[Мастер]],SEARCH(" ",ТаблицаВыработки[[#This Row],[Мастер]]&" ")-1)&"*") | J61: =SUMIFS(рапорт!$L:$L,рапорт!$A:$A,DATE(VALUE(RIGHT(ТаблицаВыработки[[#This Row],[Дата]],4)),VALUE(MID(ТаблицаВыработки[[#This Row],[Дата]],4,2)),VALUE(LEFT(ТаблицаВыработки[[#This Row],[Дата]],2))),рапорт!$D:$D,LOWER(ТаблицаВыработки[[#This Row],[Тип смены]])&"*",рапорт!$E:$E,LEFT(ТаблицаВыработки[[#This Row],[Мастер]],SEARCH(" ",ТаблицаВыработки[[#This Row],[Мастер]]&" ")-1)&"*")
...

Sheet рапорт
A1: дата | B1: № партии | C1: линия | D1: смена | E1: мастер | F1: продукт | G1: замес | H1: Формовка, лист | I1: Формовка, тонна | J1: На склад | K1: 1-сорт | L1: брак | M1: количество сбросов наката | N1: асбест | O1: Цемент | S1: цемент | T1: асб-слив | U1: цем-слив | V1: Лапрорл | X1: Целлюлоза | Z1: Стекловолокно | AB1: Д/ШИФЕР | AD1: асбозурит | AE1: норма А | AF1: факт А | AG1: откл | AH1: норма Ц | AI1: факт Ц | AJ1: откл | AK1: норма ЦЛ | AL1: факт ЦЛ | AM1: откл | AN1: норма СВ | AO1: факт СВ | AP1: откл | AQ1: норма ФБ | AR1: факт ФБ | AS1: откл | AT1: норма АСБ | AU1: факт АСБ | AV1: откл | AX1: масса, тн
O2: 1 силос | P2: 2 силос | Q2: 3 силос | R2: 4 силос | V2: Приход | W2: Расход | X2: Приход | Y2: Расход | Z2: Приход | AA2: Расход | AB2: Приход | AC2: Расход
A3: 46069 | B3: 0001 | C3: Линия 1 | D3: день | E3: Монаев | F3: РП | G3: 9 | H3: 268 | I3: =IFERROR(H3*VLOOKUP(F3,[1]инфо!$A$15:$C$28,3,FALSE)/1000,0) | N3: 908 | O3: 5400 | P3: 0 | Q3: 0 | R3: 0 | S3: =SUM(O3:R3) | T3: 0 | U3: 0 | Y3: 90 | AA3: 0 | AC3: 90 | AD3: 0 | AE3: =SUMIFS([1]инфо!$D$15:$D$28,[1]инфо!$A$15:$A$28,F3) | AF3: =IF(H3=0,0,N3/H3) | AG3: =AF3-AE3 | AH3: =SUMIFS([1]инфо!$E$15:$E$28,[1]инфо!$A$15:$A$28,F3) | AI3: =IF(H3=0,0,S3/H3) | AJ3: =AI3-AH3 | AK3: =SUMIFS([1]инфо!$F$15:$F$28,[1]инфо!$A$15:$A$28,F3) | AL3: =IF(H3=0,0,Y3/H3) | AM3: =AL3-AK3 | AN3: =SUMIFS([1]инфо!$G$15:$G$28,[1]инфо!$A$15:$A$28,F3) | AO3: =IF(H3=0,0,AA3/H3) | AP3: =AO3-AN3 | AQ3: =SUMIFS([1]инфо!$H$15:$H$28,[1]инфо!$A$15:$A$28,F3) | AR3: =IF(H3=0,0,AC3/H3) | AS3: =AR3-AQ3 | AT3: =SUMIFS([1]инфо!$I$15:$I$28,[1]инфо!$A$15:$A$28,F3) | AU3: =IF(H3=0,0,AD3/H3) | AV3: =AU3-AT3 | AX3: =SUMIFS([1]инфо!$C$15:$C$28,[1]инфо!$A$15:$A$28,F3)*H3
A4: 46069 | B4: 0002 | C4: Линия 1 | D4: ночь | E4: Дауылбай | F4: РП коричневый | G4: 27 | H4: 1265 | I4: =IFERROR(H4*VLOOKUP(F4,[1]инфо!$A$15:$C$28,3,FALSE)/1000,0) | K4: 13 | L4: 47 | N4: 2706 | O4: 16186 | S4: =SUM(O4:R4) | Y4: 270 | AC4: 270 | AE4: =SUMIFS([1]инфо!$D$15:$D$28,[1]инфо!$A$15:$A$28,F4) | AF4: =IF(H4=0,0,N4/H4) | AG4: =AF4-AE4 | AH4: =SUMIFS([1]инфо!$E$15:$E$28,[1]инфо!$A$15:$A$28,F4) | AI4: =IF(H4=0,0,S4/H4) | AJ4: =AI4-AH4 | AK4: =SUMIFS([1]инфо!$F$15:$F$28,[1]инфо!$A$15:$A$28,F4) | AL4: =IF(H4=0,0,Y4/H4) | AM4: =AL4-AK4 | AN4: =SUMIFS([1]инфо!$G$15:$G$28,[1]инфо!$A$15:$A$28,F4) | AO4: =IF(H4=0,0,AA4/H4) | AP4: =AO4-AN4 | AQ4: =SUMIFS([1]инфо!$H$15:$H$28,[1]инфо!$A$15:$A$28,F4) | AR4: =IF(H4=0,0,AC4/H4) | AS4: =AR4-AQ4 | AT4: =SUMIFS([1]инфо!$I$15:$I$28,[1]инфо!$A$15:$A$28,F4) | AU4: =IF(H4=0,0,AD4/H4) | AV4: =AU4-AT4 | AX4: =SUMIFS([1]инфо!$C$15:$C$28,[1]инфо!$A$15:$A$28,F4)*H4
A5: =A3+1 | B5: 0003 | C5: Линия 1 | D5: день | E5: Султанулы | F5: РП коричневый | G5: 20 | H5: 996 | I5: =IFERROR(H5*VLOOKUP(F5,[1]инфо!$A$15:$C$28,3,FALSE)/1000,0) | K5: 12 | N5: 2003 | O5: 12092 | S5: =SUM(O5:R5) | Y5: 200 | AC5: 190 | AE5: =SUMIFS([1]инфо!$D$15:$D$28,[1]инфо!$A$15:$A$28,F5) | AF5: =IF(H5=0,0,N5/H5) | AG5: =AF5-AE5 | AH5: =SUMIFS([1]инфо!$E$15:$E$28,[1]инфо!$A$15:$A$28,F5) | AI5: =IF(H5=0,0,S5/H5) | AJ5: =AI5-AH5 | AK5: =SUMIFS([1]инфо!$F$15:$F$28,[1]инфо!$A$15:$A$28,F5) | AL5: =IF(H5=0,0,Y5/H5) | AM5: =AL5-AK5 | AN5: =SUMIFS([1]инфо!$G$15:$G$28,[1]инфо!$A$15:$A$28,F5) | AO5: =IF(H5=0,0,AA5/H5) | AP5: =AO5-AN5 | AQ5: =SUMIFS([1]инфо!$H$15:$H$28,[1]инфо!$A$15:$A$28,F5) | AR5: =IF(H5=0,0,AC5/H5) | AS5: =AR5-AQ5 | AT5: =SUMIFS([1]инфо!$I$15:$I$28,[1]инфо!$A$15:$A$28,F5) | AU5: =IF(H5=0,0,AD5/H5) | AV5: =AU5-AT5 | AX5: =SUMIFS([1]инфо!$C$15:$C$28,[1]инфо!$A$15:$A$28,F5)*H5
A6: 46070 | B6: 0004 | C6: Линия 1 | D6: ночь | E6: Монаев | F6: РП коричневый | G6: 31 | H6: 1441 | I6: =IFERROR(H6*VLOOKUP(F6,[1]инфо!$A$15:$C$28,3,FALSE)/1000,0) | K6: 2 | L6: 4 | N6: 3117 | O6: 18988 | S6: =SUM(O6:R6) | Y6: 310 | AC6: 310 | AD6: 155 | AE6: =SUMIFS([1]инфо!$D$15:$D$28,[1]инфо!$A$15:$A$28,F6) | AF6: =IF(H6=0,0,N6/H6) | AG6: =AF6-AE6 | AH6: =SUMIFS([1]инфо!$E$15:$E$28,[1]инфо!$A$15:$A$28,F6) | AI6: =IF(H6=0,0,S6/H6) | AJ6: =AI6-AH6 | AK6: =SUMIFS([1]инфо!$F$15:$F$28,[1]инфо!$A$15:$A$28,F6) | AL6: =IF(H6=0,0,Y6/H6) | AM6: =AL6-AK6 | AN6: =SUMIFS([1]инфо!$G$15:$G$28,[1]инфо!$A$15:$A$28,F6) | AO6: =IF(H6=0,0,AA6/H6) | AP6: =AO6-AN6 | AQ6: =SUMIFS([1]инфо!$H$15:$H$28,[1]инфо!$A$15:$A$28,F6) | AR6: =IF(H6=0,0,AC6/H6) | AS6: =AR6-AQ6 | AT6: =SUMIFS([1]инфо!$I$15:$I$28,[1]инфо!$A$15:$A$28,F6) | AU6: =IF(H6=0,0,AD6/H6) | AV6: =AU6-AT6 | AX6: =SUMIFS([1]инфо!$C$15:$C$28,[1]инфо!$A$15:$A$28,F6)*H6
A7: 46071 | B7: 0005 | C7: Линия 1 | D7: день | E7: Султанулы | F7: РП коричневый | G7: 13 | H7: 612 | I7: =IFERROR(H7*VLOOKUP(F7,[1]инфо!$A$15:$C$28,3,FALSE)/1000,0) | K7: 4 | L7: 6 | N7: 1328 | O7: 1223 | P7: 6617 | S7: =SUM(O7:R7) | Y7: 130 | AC7: 110 | AE7: =SUMIFS([1]инфо!$D$15:$D$28,[1]инфо!$A$15:$A$28,F7) | AF7: =IF(H7=0,0,N7/H7) | AG7: =AF7-AE7 | AH7: =SUMIFS([1]инфо!$E$15:$E$28,[1]инфо!$A$15:$A$28,F7) | AI7: =IF(H7=0,0,S7/H7) | AJ7: =AI7-AH7 | AK7: =SUMIFS([1]инфо!$F$15:$F$28,[1]инфо!$A$15:$A$28,F7) | AL7: =IF(H7=0,0,Y7/H7) | AM7: =AL7-AK7 | AN7: =SUMIFS([1]инфо!$G$15:$G$28,[1]инфо!$A$15:$A$28,F7) | AO7: =IF(H7=0,0,AA7/H7) | AP7: =AO7-AN7 | AQ7: =SUMIFS([1]инфо!$H$15:$H$28,[1]инфо!$A$15:$A$28,F7) | AR7: =IF(H7=0,0,AC7/H7) | AS7: =AR7-AQ7 | AT7: =SUMIFS([1]инфо!$I$15:$I$28,[1]инфо!$A$15:$A$28,F7) | AU7: =IF(H7=0,0,AD7/H7) | AV7: =AU7-AT7 | AX7: =SUMIFS([1]инфо!$C$15:$C$28,[1]инфо!$A$15:$A$28,F7)*H7
A8: =A6+1 | B8: 0006 | C8: Линия 1 | D8: ночь | E8: Монаев | F8: РП коричневый | G8: 31 | H8: 1491 | I8: =IFERROR(H8*VLOOKUP(F8,[1]инфо!$A$15:$C$28,3,FALSE)/1000,0) | K8: 17 | L8: 8 | N8: 3117 | O8: 12200 | P8: 6719 | S8: =SUM(O8:R8) | Y8: 310 | AC8: 310 | AE8: =SUMIFS([1]инфо!$D$15:$D$28,[1]инфо!$A$15:$A$28,F8) | AF8: =IF(H8=0,0,N8/H8) | AG8: =AF8-AE8 | AH8: =SUMIFS([1]инфо!$E$15:$E$28,[1]инфо!$A$15:$A$28,F8) | AI8: =IF(H8=0,0,S8/H8) | AJ8: =AI8-AH8 | AK8: =SUMIFS([1]инфо!$F$15:$F$28,[1]инфо!$A$15:$A$28,F8) | AL8: =IF(H8=0,0,Y8/H8) | AM8: =AL8-AK8 | AN8: =SUMIFS([1]инфо!$G$15:$G$28,[1]инфо!$A$15:$A$28,F8) | AO8: =IF(H8=0,0,AA8/H8) | AP8: =AO8-AN8 | AQ8: =SUMIFS([1]инфо!$H$15:$H$28,[1]инфо!$A$15:$A$28,F8) | AR8: =IF(H8=0,0,AC8/H8) | AS8: =AR8-AQ8 | AT8: =SUMIFS([1]инфо!$I$15:$I$28,[1]инфо!$A$15:$A$28,F8) | AU8: =IF(H8=0,0,AD8/H8) | AV8: =AU8-AT8 | AX8: =SUMIFS([1]инфо!$C$15:$C$28,[1]инфо!$A$15:$A$28,F8)*H8
A9: =A7+1 | B9: 0007 | C9: Линия 1 | D9: день | E9: Дауылбай | F9: РП коричневый | G9: 32 | H9: 1575 | I9: =IFERROR(H9*VLOOKUP(F9,[1]инфо!$A$15:$C$28,3,FALSE)/1000,0) | K9: 9 | L9: 4 | N9: 3210 | O9: 19586 | P9: 0 | S9: =SUM(O9:R9) | Y9: 320 | AC9: 320 | AD9: 160 | AE9: =SUMIFS([1]инфо!$D$15:$D$28,[1]инфо!$A$15:$A$28,F9) | AF9: =IF(H9=0,0,N9/H9) | AG9: =AF9-AE9 | AH9: =SUMIFS([1]инфо!$E$15:$E$28,[1]инфо!$A$15:$A$28,F9) | AI9: =IF(H9=0,0,S9/H9) | AJ9: =AI9-AH9 | AK9: =SUMIFS([1]инфо!$F$15:$F$28,[1]инфо!$A$15:$A$28,F9) | AL9: =IF(H9=0,0,Y9/H9) | AM9: =AL9-AK9 | AN9: =SUMIFS([1]инфо!$G$15:$G$28,[1]инфо!$A$15:$A$28,F9) | AO9: =IF(H9=0,0,AA9/H9) | AP9: =AO9-AN9 | AQ9: =SUMIFS([1]инфо!$H$15:$H$28,[1]инфо!$A$15:$A$28,F9) | AR9: =IF(H9=0,0,AC9/H9) | AS9: =AR9-AQ9 | AT9: =SUMIFS([1]инфо!$I$15:$I$28,[1]инфо!$A$15:$A$28,F9) | AU9: =IF(H9=0,0,AD9/H9) | AV9: =AU9-AT9 | AX9: =SUMIFS([1]инфо!$C$15:$C$28,[1]инфо!$A$15:$A$28,F9)*H9
A10: 46072 | B10: 0008 | C10: Линия 1 | D10: ночь | E10: Султанулы | F10: РП коричневый | G10: 35 | H10: 1770 | I10: =IFERROR(H10*VLOOKUP(F10,[1]инфо!$A$15:$C$28,3,FALSE)/1000,0) | K10: 4 | L10: 1 | N10: 3538 | O10: 12247 | P10: 9186 | S10: =SUM(O10:R10) | Y10: 350 | AC10: 350 | AE10: =SUMIFS([1]инфо!$D$15:$D$28,[1]инфо!$A$15:$A$28,F10) | AF10: =IF(H10=0,0,N10/H10) | AG10: =AF10-AE10 | AH10: =SUMIFS([1]инфо!$E$15:$E$28,[1]инфо!$A$15:$A$28,F10) | AI10: =IF(H10=0,0,S10/H10) | AJ10: =AI10-AH10 | AK10: =SUMIFS([1]инфо!$F$15:$F$28,[1]инфо!$A$15:$A$28,F10) | AL10: =IF(H10=0,0,Y10/H10) | AM10: =AL10-AK10 | AN10: =SUMIFS([1]инфо!$G$15:$G$28,[1]инфо!$A$15:$A$28,F10) | AO10: =IF(H10=0,0,AA10/H10) | AP10: =AO10-AN10 | AQ10: =SUMIFS([1]инфо!$H$15:$H$28,[1]инфо!$A$15:$A$28,F10) | AR10: =IF(H10=0,0,AC10/H10) | AS10: =AR10-AQ10 | AT10: =SUMIFS([1]инфо!$I$15:$I$28,[1]инфо!$A$15:$A$28,F10) | AU10: =IF(H10=0,0,AD10/H10) | AV10: =AU10-AT10 | AX10: =SUMIFS([1]инфо!$C$15:$C$28,[1]инфо!$A$15:$A$28,F10)*H10
A11: 46073 | B11: 0009 | C11: Линия 1 | D11: день | E11: Дауылбай | F11: РП коричневый | G11: 28 | H11: 1365 | I11: =IFERROR(H11*VLOOKUP(F11,[1]инфо!$A$15:$C$28,3,FALSE)/1000,0) | K11: 25 | L11: 4 | N11: 2833 | O11: 8548 | P11: 8573 | S11: =SUM(O11:R11) | Y11: 280 | AC11: 280 | AD11: 140 | AE11: =SUMIFS([1]инфо!$D$15:$D$28,[1]инфо!$A$15:$A$28,F11) | AF11: =IF(H11=0,0,N11/H11) | AG11: =AF11-AE11 | AH11: =SUMIFS([1]инфо!$E$15:$E$28,[1]инфо!$A$15:$A$28,F11) | AI11: =IF(H11=0,0,S11/H11) | AJ11: =AI11-AH11 | AK11: =SUMIFS([1]инфо!$F$15:$F$28,[1]инфо!$A$15:$A$28,F11) | AL11: =IF(H11=0,0,Y11/H11) | AM11: =AL11-AK11 | AN11: =SUMIFS([1]инфо!$G$15:$G$28,[1]инфо!$A$15:$A$28,F11) | AO11: =IF(H11=0,0,AA11/H11) | AP11: =AO11-AN11 | AQ11: =SUMIFS([1]инфо!$H$15:$H$28,[1]инфо!$A$15:$A$28,F11) | AR11: =IF(H11=0,0,AC11/H11) | AS11: =AR11-AQ11 | AT11: =SUMIFS([1]инфо!$I$15:$I$28,[1]инфо!$A$15:$A$28,F11) | AU11: =IF(H11=0,0,AD11/H11) | AV11: =AU11-AT11 | AX11: =SUMIFS([1]инфо!$C$15:$C$28,[1]инфо!$A$15:$A$28,F11)*H11
A12: 46073 | B12: 0010 | C12: Линия 1 | D12: ночь | E12: Султанулы | F12: РП красный | G12: 43 | H12: 2096 | I12: =IFERROR(H12*VLOOKUP(F12,[1]инфо!$A$15:$C$28,3,FALSE)/1000,0) | K12: 23 | L12: 1 | N12: 4347 | O12: 13442 | P12: 12846 | S12: =SUM(O12:R12) | Y12: 430 | AC12: 430 | AD12: 215 | AE12: =SUMIFS([1]инфо!$D$15:$D$28,[1]инфо!$A$15:$A$28,F12) | AF12: =IF(H12=0,0,N12/H12) | AG12: =AF12-AE12 | AH12: =SUMIFS([1]инфо!$E$15:$E$28,[1]инфо!$A$15:$A$28,F12) | AI12: =IF(H12=0,0,S12/H12) | AJ12: =AI12-AH12 | AK12: =SUMIFS([1]инфо!$F$15:$F$28,[1]инфо!$A$15:$A$28,F12) | AL12: =IF(H12=0,0,Y12/H12) | AM12: =AL12-AK12 | AN12: =SUMIFS([1]инфо!$G$15:$G$28,[1]инфо!$A$15:$A$28,F12) | AO12: =IF(H12=0,0,AA12/H12) | AP12: =AO12-AN12 | AQ12: =SUMIFS([1]инфо!$H$15:$H$28,[1]инфо!$A$15:$A$28,F12) | AR12: =IF(H12=0,0,AC12/H12) | AS12: =AR12-AQ12 | AT12: =SUMIFS([1]инфо!$I$15:$I$28,[1]инфо!$A$15:$A$28,F12) | AU12: =IF(H12=0,0,AD12/H12) | AV12: =AU12-AT12 | AX12: =SUMIFS([1]инфо!$C$15:$C$28,[1]инфо!$A$15:$A$28,F12)*H12
A13: =A11+1 | B13: 0011 | C13: Линия 1 | D13: день | E13: Монаев | F13: РП красный | G13: 37 | H13: 1760 | I13: =IFERROR(H13*VLOOKUP(F13,[1]инфо!$A$15:$C$28,3,FALSE)/1000,0) | J13: 1700 | K13: 23 | L13: 2 | N13: 3737 | O13: 11620 | P13: 11009 | S13: =SUM(O13:R13) | Y13: 370 | AC13: 370 | AD13: 185 | AE13: =SUMIFS([1]инфо!$D$15:$D$28,[1]инфо!$A$15:$A$28,F13) | AF13: =IF(H13=0,0,N13/H13) | AG13: =AF13-AE13 | AH13: =SUMIFS([1]инфо!$E$15:$E$28,[1]инфо!$A$15:$A$28,F13) | AI13: =IF(H13=0,0,S13/H13) | AJ13: =AI13-AH13 | AK13: =SUMIFS([1]инфо!$F$15:$F$28,[1]инфо!$A$15:$A$28,F13) | AL13: =IF(H13=0,0,Y13/H13) | AM13: =AL13-AK13 | AN13: =SUMIFS([1]инфо!$G$15:$G$28,[1]инфо!$A$15:$A$28,F13) | AO13: =IF(H13=0,0,AA13/H13) | AP13: =AO13-AN13 | AQ13: =SUMIFS([1]инфо!$H$15:$H$28,[1]инфо!$A$15:$A$28,F13) | AR13: =IF(H13=0,0,AC13/H13) | AS13: =AR13-AQ13 | AT13: =SUMIFS([1]инфо!$I$15:$I$28,[1]инфо!$A$15:$A$28,F13) | AU13: =IF(H13=0,0,AD13/H13) | AV13: =AU13-AT13 | AX13: =SUMIFS([1]инфо!$C$15:$C$28,[1]инфо!$A$15:$A$28,F13)*H13
A14: =A12+1 | B14: 0012 | C14: Линия 1 | D14: ночь | E14: Дауылбай | F14: РП красный | G14: 41 | H14: 1935 | I14: =IFERROR(H14*VLOOKUP(F14,[1]инфо!$A$15:$C$28,3,FALSE)/1000,0) | J14: 1900 | K14: 10 | L14: 8 | N14: 4142 | O14: 12831 | P14: 12243 | S14: =SUM(O14:R14) | Y14: 380 | AC14: 410 | AD14: 205 | AE14: =SUMIFS([1]инфо!$D$15:$D$28,[1]инфо!$A$15:$A$28,F14) | AF14: =IF(H14=0,0,N14/H14) | AG14: =AF14-AE14 | AH14: =SUMIFS([1]инфо!$E$15:$E$28,[1]инфо!$A$15:$A$28,F14) | AI14: =IF(H14=0,0,S14/H14) | AJ14: =AI14-AH14 | AK14: =SUMIFS([1]инфо!$F$15:$F$28,[1]инфо!$A$15:$A$28,F14) | AL14: =IF(H14=0,0,Y14/H14) | AM14: =AL14-AK14 | AN14: =SUMIFS([1]инфо!$G$15:$G$28,[1]инфо!$A$15:$A$28,F14) | AO14: =IF(H14=0,0,AA14/H14) | AP14: =AO14-AN14 | AQ14: =SUMIFS([1]инфо!$H$15:$H$28,[1]инфо!$A$15:$A$28,F14) | AR14: =IF(H14=0,0,AC14/H14) | AS14: =AR14-AQ14 | AT14: =SUMIFS([1]инфо!$I$15:$I$28,[1]инфо!$A$15:$A$28,F14) | AU14: =IF(H14=0,0,AD14/H14) | AV14: =AU14-AT14 | AX14: =SUMIFS([1]инфо!$C$15:$C$28,[1]инфо!$A$15:$A$28,F14)*H14
A15: =A13+1 | B15: 0013 | C15: Линия 1 | D15: день | E15: Монаев | F15: РП красный | G15: 31 | H15: 1520 | I15: =IFERROR(H15*VLOOKUP(F15,[1]инфо!$A$15:$C$28,3,FALSE)/1000,0) | K15: 7 | L15: 2 | N15: 3127 | O15: 9169 | P15: 9798 | S15: =SUM(O15:R15) | Y15: 310 | AC15: 310 | AD15: 155 | AE15: =SUMIFS([1]инфо!$D$15:$D$28,[1]инфо!$A$15:$A$28,F15) | AF15: =IF(H15=0,0,N15/H15) | AG15: =AF15-AE15 | AH15: =SUMIFS([1]инфо!$E$15:$E$28,[1]инфо!$A$15:$A$28,F15) | AI15: =IF(H15=0,0,S15/H15) | AJ15: =AI15-AH15 | AK15: =SUMIFS([1]инфо!$F$15:$F$28,[1]инфо!$A$15:$A$28,F15) | AL15: =IF(H15=0,0,Y15/H15) | AM15: =AL15-AK15 | AN15: =SUMIFS([1]инфо!$G$15:$G$28,[1]инфо!$A$15:$A$28,F15) | AO15: =IF(H15=0,0,AA15/H15) | AP15: =AO15-AN15 | AQ15: =SUMIFS([1]инфо!$H$15:$H$28,[1]инфо!$A$15:$A$28,F15) | AR15: =IF(H15=0,0,AC15/H15) | AS15: =AR15-AQ15 | AT15: =SUMIFS([1]инфо!$I$15:$I$28,[1]инфо!$A$15:$A$28,F15) | AU15: =IF(H15=0,0,AD15/H15) | AV15: =AU15-AT15 | AX15: =SUMIFS([1]инфо!$C$15:$C$28,[1]инфо!$A$15:$A$28,F15)*H15
A16: 46075 | B16: 0014 | C16: Линия 1 | D16: ночь | E16: Дауылбай | F16: РП красный | G16: 42 | H16: 1985 | I16: =IFERROR(H16*VLOOKUP(F16,[1]инфо!$A$15:$C$28,3,FALSE)/1000,0) | K16: 11 | L16: 1 | N16: 4243 | O16: 13418 | P16: 12245 | S16: =SUM(O16:R16) | Y16: 420 | AC16: 420 | AD16: 210 | AE16: =SUMIFS([1]инфо!$D$15:$D$28,[1]инфо!$A$15:$A$28,F16) | AF16: =IF(H16=0,0,N16/H16) | AG16: =AF16-AE16 | AH16: =SUMIFS([1]инфо!$E$15:$E$28,[1]инфо!$A$15:$A$28,F16) | AI16: =IF(H16=0,0,S16/H16) | AJ16: =AI16-AH16 | AK16: =SUMIFS([1]инфо!$F$15:$F$28,[1]инфо!$A$15:$A$28,F16) | AL16: =IF(H16=0,0,Y16/H16) | AM16: =AL16-AK16 | AN16: =SUMIFS([1]инфо!$G$15:$G$28,[1]инфо!$A$15:$A$28,F16) | AO16: =IF(H16=0,0,AA16/H16) | AP16: =AO16-AN16 | AQ16: =SUMIFS([1]инфо!$H$15:$H$28,[1]инфо!$A$15:$A$28,F16) | AR16: =IF(H16=0,0,AC16/H16) | AS16: =AR16-AQ16 | AT16: =SUMIFS([1]инфо!$I$15:$I$28,[1]инфо!$A$15:$A$28,F16) | AU16: =IF(H16=0,0,AD16/H16) | AV16: =AU16-AT16 | AX16: =SUMIFS([1]инфо!$C$15:$C$28,[1]инфо!$A$15:$A$28,F16)*H16
A17: =A15+1 | B17: 0015 | C17: Линия 1 | D17: день | E17: Султанулы | F17: РП половинка красный | G17: 19 | H17: 1175 | I17: =IFERROR(H17*VLOOKUP(F17,[1]инфо!$A$15:$C$28,3,FALSE)/1000,0) | K17: 8 | L17: 4 | N17: 1916 | O17: 6715 | P17: 4877 | S17: =SUM(O17:R17) | Y17: 190 | AC17: 190 | AE17: =SUMIFS([1]инфо!$D$15:$D$28,[1]инфо!$A$15:$A$28,F17) | AF17: =IF(H17=0,0,N17/H17) | AG17: =AF17-AE17 | AH17: =SUMIFS([1]инфо!$E$15:$E$28,[1]инфо!$A$15:$A$28,F17) | AI17: =IF(H17=0,0,S17/H17) | AJ17: =AI17-AH17 | AK17: =SUMIFS([1]инфо!$F$15:$F$28,[1]инфо!$A$15:$A$28,F17) | AL17: =IF(H17=0,0,Y17/H17) | AM17: =AL17-AK17 | AN17: =SUMIFS([1]инфо!$G$15:$G$28,[1]инфо!$A$15:$A$28,F17) | AO17: =IF(H17=0,0,AA17/H17) | AP17: =AO17-AN17 | AQ17: =SUMIFS([1]инфо!$H$15:$H$28,[1]инфо!$A$15:$A$28,F17) | AR17: =IF(H17=0,0,AC17/H17) | AS17: =AR17-AQ17 | AT17: =SUMIFS([1]инфо!$I$15:$I$28,[1]инфо!$A$15:$A$28,F17) | AU17: =IF(H17=0,0,AD17/H17) | AV17: =AU17-AT17 | AX17: =SUMIFS([1]инфо!$C$15:$C$28,[1]инфо!$A$15:$A$28,F17)*H17
A18: 46076 | B18: 0016 | C18: Линия 1 | D18: ночь | E18: Монаев | F18: РП половинка красный | G18: 37 | H18: 3145 | I18: =IFERROR(H18*VLOOKUP(F18,[1]инфо!$A$15:$C$28,3,FALSE)/1000,0) | N18: 3724 | O18: 11459 | P18: 12099 | S18: =SUM(O18:R18) | Y18: 370 | AC18: 370 | AE18: =SUMIFS([1]инфо!$D$15:$D$28,[1]инфо!$A$15:$A$28,F18) | AF18: =IF(H18=0,0,N18/H18) | AG18: =AF18-AE18 | AH18: =SUMIFS([1]инфо!$E$15:$E$28,[1]инфо!$A$15:$A$28,F18) | AI18: =IF(H18=0,0,S18/H18) | AJ18: =AI18-AH18 | AK18: =SUMIFS([1]инфо!$F$15:$F$28,[1]инфо!$A$15:$A$28,F18) | AL18: =IF(H18=0,0,Y18/H18) | AM18: =AL18-AK18 | AN18: =SUMIFS([1]инфо!$G$15:$G$28,[1]инфо!$A$15:$A$28,F18) | AO18: =IF(H18=0,0,AA18/H18) | AP18: =AO18-AN18 | AQ18: =SUMIFS([1]инфо!$H$15:$H$28,[1]инфо!$A$15:$A$28,F18) | AR18: =IF(H18=0,0,AC18/H18) | AS18: =AR18-AQ18 | AT18: =SUMIFS([1]инфо!$I$15:$I$28,[1]инфо!$A$15:$A$28,F18) | AU18: =IF(H18=0,0,AD18/H18) | AV18: =AU18-AT18 | AX18: =SUMIFS([1]инфо!$C$15:$C$28,[1]инфо!$A$15:$A$28,F18)*H18
A19: =A17+1 | B19: 0017 | C19: Линия 1 | D19: день | E19: Султанулы | F19: РП половинка красный | G19: 27 | H19: 2210 | I19: =IFERROR(H19*VLOOKUP(F19,[1]инфо!$A$15:$C$28,3,FALSE)/1000,0) | K19: 5 | L19: 2 | N19: 2727 | O19: 8349 | P19: 8971 | S19: =SUM(O19:R19) | Y19: 135 | AC19: 270 | AE19: =SUMIFS([1]инфо!$D$15:$D$28,[1]инфо!$A$15:$A$28,F19) | AF19: =IF(H19=0,0,N19/H19) | AG19: =AF19-AE19 | AH19: =SUMIFS([1]инфо!$E$15:$E$28,[1]инфо!$A$15:$A$28,F19) | AI19: =IF(H19=0,0,S19/H19) | AJ19: =AI19-AH19 | AK19: =SUMIFS([1]инфо!$F$15:$F$28,[1]инфо!$A$15:$A$28,F19) | AL19: =IF(H19=0,0,Y19/H19) | AM19: =AL19-AK19 | AN19: =SUMIFS([1]инфо!$G$15:$G$28,[1]инфо!$A$15:$A$28,F19) | AO19: =IF(H19=0,0,AA19/H19) | AP19: =AO19-AN19 | AQ19: =SUMIFS([1]инфо!$H$15:$H$28,[1]инфо!$A$15:$A$28,F19) | AR19: =IF(H19=0,0,AC19/H19) | AS19: =AR19-AQ19 | AT19: =SUMIFS([1]инфо!$I$15:$I$28,[1]инфо!$A$15:$A$28,F19) | AU19: =IF(H19=0,0,AD19/H19) | AV19: =AU19-AT19 | AX19: =SUMIFS([1]инфо!$C$15:$C$28,[1]инфо!$A$15:$A$28,F19)*H19
A20: =A18+1 | B20: 0018 | C20: Линия 1 | D20: ночь | E20: Монаев | F20: РП половинка коричневый | G20: 32 | H20: 3403 | I20: =IFERROR(H20*VLOOKUP(F20,[1]инфо!$A$15:$C$28,3,FALSE)/1000,0) | K20: 21 | L20: 3 | N20: 3243 | O20: 10902 | P20: 9629 | S20: =SUM(O20:R20) | Y20: 160 | AC20: 320 | AD20: 160 | AE20: =SUMIFS([1]инфо!$D$15:$D$28,[1]инфо!$A$15:$A$28,F20) | AF20: =IF(H20=0,0,N20/H20) | AG20: =AF20-AE20 | AH20: =SUMIFS([1]инфо!$E$15:$E$28,[1]инфо!$A$15:$A$28,F20) | AI20: =IF(H20=0,0,S20/H20) | AJ20: =AI20-AH20 | AK20: =SUMIFS([1]инфо!$F$15:$F$28,[1]инфо!$A$15:$A$28,F20) | AL20: =IF(H20=0,0,Y20/H20) | AM20: =AL20-AK20 | AN20: =SUMIFS([1]инфо!$G$15:$G$28,[1]инфо!$A$15:$A$28,F20) | AO20: =IF(H20=0,0,AA20/H20) | AP20: =AO20-AN20 | AQ20: =SUMIFS([1]инфо!$H$15:$H$28,[1]инфо!$A$15:$A$28,F20) | AR20: =IF(H20=0,0,AC20/H20) | AS20: =AR20-AQ20 | AT20: =SUMIFS([1]инфо!$I$15:$I$28,[1]инфо!$A$15:$A$28,F20) | AU20: =IF(H20=0,0,AD20/H20) | AV20: =AU20-AT20 | AX20: =SUMIFS([1]инфо!$C$15:$C$28,[1]инфо!$A$15:$A$28,F20)*H20
