Workbook

Sheet Отчеты
D1: ИТОГО, т | G1: ЛФМ 1 | H1: =Z17+Z48+Z79+Z110+Z141+Z172+Z203+Z234+Z265+Z296+Z327+Z358+Z389+Z420+Z451+Z482+Z513+Z544+Z575+Z606+Z637+Z668+Z699+Z730+Z761+Z792+Z823+Z854+Z885+Z916+Z947+Z978+Z1009+Z1040+Z1071+Z1102+Z1133+Z1164+Z1195+Z1226+Z1257+Z1288+Z1319+Z1350+Z1381+Z1412+Z1443+Z1474+Z1505+Z1536+Z1567+Z1598+Z1629+Z1660+Z1691+Z1722+Z1753+Z1784+Z1815+Z1846 -> 0 | I1: ИТОГО за год, т | P1: Янв | Q1: Фев | R1: Мар | S1: Апр | T1: Май | U1: Июн | V1: Июл | W1: Авг | X1: Сент | Y1: Окт | Z1: Ноя | AA1: Дек
D2: =H1+H2 -> 0 | G2: ЛФМ 2 | H2: =Z24+Z55+Z86+Z117+Z148+Z179+Z210+Z241+Z272+Z303+Z334+Z365+Z396+Z427+Z458+Z489+Z520+Z551+Z582+Z613+Z644+Z675+Z706+Z737+Z768+Z799+Z830+Z861+Z892+Z923+Z954+Z985+Z1016+Z1047+Z1078+Z1109+Z1140+Z1171+Z1202+Z1233+Z1264+Z1295+Z1326+Z1357+Z1388+Z1419+Z1450+Z1481+Z1512+Z1543+Z1574+Z1605+Z1636+Z1667+Z1698+Z1729+Z1760+Z1791+Z1822+Z1853 -> 0 | I2: =P2+Q2+R2+S2+T2+U2+V2+W2+X2+Y2+Z2+AA2 -> 0 | U2: =D2 -> 0
AO3: Производственный отчет за смену
B5: Дата | C5: № смены | D5: № ЛФМ | E5: № партии | G5: № номенклатуры | H5: Ф.И.О. мастера | I5: Количество замесов | J5: Подача асбестит, сек. | K5: Раход на замес, кг | U5: выход листов с замеса, факт | V5: выход листов с замеса, норма | W5: Количество, готового продукта | X5: Сбросы, шт | Y5: Объем продукта, м3 | Z5: Масса готового продукта | AA5: Приход / Остаток цемента по силосам | AG5: Расход материалов в смену
AG6: Цем 1 42,5 Н | AN6: цемент 42,5 Н | AP6: Зола уноса | AR6: асбест 5-65 | AT6: асбест 6-45 | AV6: асбест 4-20 | AX6: Стекловол. 40мм | AZ6: ЛСТ | BB6: ЭкоКремний | BD6: Тип/ размер поддона / бруса | BE6: Количество
F8: Номенклатура | K8: Цем 1 42,5 Н, кг | L8: Зола - уноса, кг | M8: Асбестит кг сух. в 1 сек. | N8: Асбестит кг сух | O8: Хризотил 6-45, кг | P8: Хризотил 5-65, кг | Q8: Хризотил 4-20, кг | R8: Кремнезем 2% р-р, кг | S8: Стекловолокно 40мм | T8: Целлюлоза, кг | AA8: СИЛОС 1 (120т) | AB8: СИЛОС 2 (120т) | AC8: СИЛОС 3 (120т) | AD8: СИЛОС 4 (120т) | AE8: СИЛОС 5 (зола - уноса) | AF8: СИЛОС 6 (зола - уноса) | AG8: Расход факт силос 1/3 | AH8: Расход факт силос 2/4 | AI8: Зола уноса, кг | AJ8: Общ. Цемент, кг | AK8: Хризотил, кг | AN8: Факт с дозатора, кг | AO8: Норма, кг | AP8: Факт с дозатора, кг | AQ8: Норма, кг | AR8: Факт с дозатора, кг | AS8: Норма, кг | AT8: Факт по доз., кг | AU8: Норма, кг | AV8: Факт с доз., кг | AW8: Норма, кг | AX8: Факт по зам., кг | AY8: Норма, кг | AZ8: Факт, кг | BA8: Норма, кг | BB8: Факт, кг | BC8: Норма, кг
A9: 1Д | B9: 1 | C9: 2 | D9: 3 | E9: 4 | F9: 5 | G9: 6 | H9: 7 | I9: 8 | K9: 9 | L9: 10 | M9: 11 | O9: 12 | P9: 13 | Q9: 14 | R9: 15 | T9: 16 | U9: 17 | V9: 18 | W9: 19 | X9: 20 | Y9: 21 | Z9: 22 | AA9: 23 | AB9: 24 | AC9: 25 | AD9: 26 | AE9: 27 | AF9: 28 | AG9: 29 | AH9: 30 | AI9: 31 | AJ9: 32 | AM9: 41 | AN9: 33 | AO9: 34 | AR9: 42 | AS9: 43 | AT9: 44 | AU9: 45 | AV9: 46 | AW9: 47 | AX9: 35 | AY9: 36 | AZ9: 37 | BA9: 38 | BB9: 39 | BC9: 40 | BD9: 48 | BE9: 49
A10: 1Д | F10: Дневная смена ЛФМ 1 | AA10: 1 | AB10: 2 | AC10: 3 | AD10: 4 | AE10: 5 | AF10: 6 | AG10: Сил.1 | AH10: Сил.2 | AI10: Сил. 5 | AJ10: Общ. | AK10: 4-20 | AL10: 5-65 | AM10: 6-45
A11: 1Д | B11: 46023 | C11: 2 | D11: 1 | F11: =IFERROR(VLOOKUP($G11,нормы!$A$14:$BC$57,2,0),"") | G11: 301 | H11: =IF(C11=1,"Кульков С.А.", IF(C11=2,"Чудаков А.А.",IF(C11=3,"Королев В.Н.",IF(C11=4,"Николашин М.П.",IF(C11=5," Кульков С.А.",IF(C11=6,"А.А. Чудаков",IF(C11=7,"В.Н. Королев",IF(C11=8,"М.П. Николашин",0)))))))) -> Чудаков А.А. | I11: заг 1 | K11: =IFERROR(VLOOKUP($G11,[1]нормы!$A$21:$BC$151,15,0),"") -> 425 | L11: =IFERROR(VLOOKUP($G11,[1]нормы!$A$21:$BC$151,17,0),"") -> 75 | M11: =IFERROR(VLOOKUP($G11,[1]нормы!$A$21:$BC$151,27,0),"") -> 1.4 | N11: =IFERROR(Y11/Y17*(1.1*J11*I16),"") | O11: =IFERROR(VLOOKUP($G11,[1]нормы!$A$21:$BC$151,21,0),"") -> 0 | P11: =IFERROR(VLOOKUP($G11,[1]нормы!$A$21:$BC$151,19,0),"") -> 83 | Q11: =IFERROR(VLOOKUP($G11,[1]нормы!$A$21:$BC$151,23,0),"") -> 0 | R11: =IFERROR(VLOOKUP($G11,[1]нормы!$A$21:$BC$151,29,0),"") -> 0 | S11: =IFERROR(VLOOKUP($G11,[1]нормы!$A$21:$BC$151,31,0),"") -> 0 | T11: =IFERROR(VLOOKUP($G11,[1]нормы!$A$21:$BC$151,25,0),"") -> 0 | U11: =IFERROR(W11/(((100*Y11/Y17)*I16)/100),"") | V11: =IFERROR(VLOOKUP($G11,нормы!$A$14:$BC$57,38,0),"") | W11: 170 | Y11: =IFERROR(VLOOKUP($G11,нормы!$A$14:$BC$57,42,0)*W11,"") | Z11: =IFERROR(VLOOKUP($G11,нормы!$A$14:$BC$57,14,0)*W11/1000,0) -> 0 | AJ11: =AG11+AH11 -> 0 | AN11: =IFERROR(Y11*AJ11/Y17,) -> 0 | AO11: =IFERROR(VLOOKUP($G11,нормы!$A$14:$BC$57,53,0)*$W11,"") | AP11: =IFERROR(Y11*AI11/Y17,) -> 0 | AQ11: =IFERROR(VLOOKUP($G11,нормы!$A$14:$BC$57,54,0)*$W11,"") | AR11: =IFERROR(AS11/SUM(AS11:AS16)*AL11,0) -> 0 | AS11: =IFERROR(VLOOKUP($G11,нормы!$A$14:$BC$57,55,0)*W11,"") | AT11: =IFERROR(AU11/SUM(AU11:AU16)*AM11,0) -> 0 | AU11: =IFERROR(VLOOKUP($G11,нормы!$A$14:$BI$57,56,0)*W11,"") | AV11: =IFERROR(AW11/SUM(AW11:AW16)*AK11,0) -> 0 | AW11: =IFERROR(VLOOKUP($G11,нормы!$A$14:$BI$57,57,0)*W11,"") | AY11: =IFERROR(VLOOKUP($G11,нормы!$A$14:$BI$57,58,0)*W11,"") | BA11: =IFERROR(VLOOKUP($G11,нормы!$A$14:$BI$57,61,0)*$W11,"") | BC11: =IFERROR(VLOOKUP($G11,нормы!$A$14:$BI$57,60,0)*W11,"") | BD11: =IFERROR(VLOOKUP($G11,нормы!$A$14:$BG$57,44,0),"") | BE11: =IFERROR(W11/VLOOKUP($G11,нормы!$A$14:$BI$57,45,0),"")
A12: 1Д | B12: =B11 -> 46023 | C12: =C11 -> 2 | D12: =D11 -> 1 | F12: =IFERROR(VLOOKUP($G12,нормы!$A$14:$BC$57,2,0),"") | H12: =IF(C12=1,"Кульков С.А.", IF(C12=2,"Чудаков А.А.",IF(C12=3,"Королев В.Н.",IF(C12=4,"Николашин М.П.",IF(C12=5," Кульков С.А.",IF(C12=6,"А.А. Чудаков",IF(C12=7,"В.Н. Королев",IF(C12=8,"М.П. Николашин",0)))))))) -> Чудаков А.А. | I12: 10 | K12: =IFERROR(VLOOKUP($G12,[1]нормы!$A$21:$BC$151,15,0),"") -> 0 | L12: =IFERROR(VLOOKUP($G12,[1]нормы!$A$21:$BC$151,17,0),"") -> 0 | M12: =IFERROR(VLOOKUP($G12,[1]нормы!$A$21:$BC$151,27,0),"") -> 0 | N12: =IFERROR(Y12/Y17*(1.1*J11*I16),"") | O12: =IFERROR(VLOOKUP($G12,[1]нормы!$A$21:$BC$151,21,0),"") -> 0 | P12: =IFERROR(VLOOKUP($G12,[1]нормы!$A$21:$BC$151,19,0),"") -> 0 | Q12: =IFERROR(VLOOKUP($G12,[1]нормы!$A$21:$BC$151,23,0),"") -> 0 | R12: =IFERROR(VLOOKUP($G12,[1]нормы!$A$21:$BC$151,29,0),"") -> 0 | S12: =IFERROR(VLOOKUP($G12,[1]нормы!$A$21:$BC$151,31,0),"") -> 0 | T12: =IFERROR(VLOOKUP($G12,[1]нормы!$A$21:$BC$151,25,0),"") -> 0 | U12: =IFERROR(W12/(((100*Y12/Y17)*I16)/100),"") | V12: =IFERROR(VLOOKUP($G12,нормы!$A$14:$BC$57,38,0),"") | Y12: =IFERROR(VLOOKUP($G12,нормы!$A$14:$BC$57,42,0)*W12,"") | Z12: =IFERROR(VLOOKUP($G12,нормы!$A$14:$BC$57,14,0)*W12/1000,0) -> 0 | AN12: =IFERROR(Y12*AJ11/Y17,) -> 0 | AO12: =IFERROR(VLOOKUP($G12,нормы!$A$14:$BC$57,53,0)*$W12,"") | AP12: =IFERROR(Y12*AI11/Y17,) -> 0 | AQ12: =IFERROR(VLOOKUP($G12,нормы!$A$14:$BC$57,54,0)*$W12,"") | AR12: =IFERROR(AS12/SUM(AS11:AS16)*AL11,0) -> 0 | AS12: =IFERROR(VLOOKUP($G12,нормы!$A$14:$BC$57,55,0)*W12,"") | AT12: =IFERROR(AU12/SUM(AU11:AU16)*AM11,0) -> 0 | AU12: =IFERROR(VLOOKUP($G12,нормы!$A$14:$BI$57,56,0)*W12,"") | AV12: =IFERROR(AW12/SUM(AW11:AW16)*AK11,0) -> 0 | AW12: =IFERROR(VLOOKUP($G12,нормы!$A$14:$BI$57,57,0)*W12,"") | AY12: =IFERROR(VLOOKUP($G12,нормы!$A$14:$BI$57,58,0)*W12,"") | BA12: =IFERROR(VLOOKUP($G12,нормы!$A$14:$BI$57,61,0)*$W12,"") | BC12: =IFERROR(VLOOKUP($G12,нормы!$A$14:$BI$57,60,0)*W12,"") | BD12: =IFERROR(VLOOKUP($G12,нормы!$A$14:$BG$57,44,0),"") | BE12: =IFERROR(W12/VLOOKUP($G12,нормы!$A$14:$BI$57,45,0),"")
A13: 1Д | B13: =B12 -> 46023 | C13: =C12 -> 2 | D13: =D12 -> 1 | F13: =IFERROR(VLOOKUP($G13,нормы!$A$14:$BC$57,2,0),"") | H13: =IF(C13=1,"Кульков С.А.", IF(C13=2,"Чудаков А.А.",IF(C13=3,"Королев В.Н.",IF(C13=4,"Николашин М.П.",IF(C13=5," Кульков С.А.",IF(C13=6,"А.А. Чудаков",IF(C13=7,"В.Н. Королев",IF(C13=8,"М.П. Николашин",0)))))))) -> Чудаков А.А. | I13: заг 2 | K13: =IFERROR(VLOOKUP($G13,[1]нормы!$A$21:$BC$151,15,0),"") -> 0 | L13: =IFERROR(VLOOKUP($G13,[1]нормы!$A$21:$BC$151,17,0),"") -> 0 | M13: =IFERROR(VLOOKUP($G13,[1]нормы!$A$21:$BC$151,27,0),"") -> 0 | N13: =IFERROR(Y13/Y17*(1.1*J11*I16),"") | O13: =IFERROR(VLOOKUP($G13,[1]нормы!$A$21:$BC$151,21,0),"") -> 0 | P13: =IFERROR(VLOOKUP($G13,[1]нормы!$A$21:$BC$151,19,0),"") -> 0 | Q13: =IFERROR(VLOOKUP($G13,[1]нормы!$A$21:$BC$151,23,0),"") -> 0 | R13: =IFERROR(VLOOKUP($G13,[1]нормы!$A$21:$BC$151,29,0),"") -> 0 | S13: =IFERROR(VLOOKUP($G13,[1]нормы!$A$21:$BC$151,31,0),"") -> 0 | T13: =IFERROR(VLOOKUP($G13,[1]нормы!$A$21:$BC$151,25,0),"") -> 0 | U13: =IFERROR(W13/(((100*Y13/Y17)*I16)/100),"") | V13: =IFERROR(VLOOKUP($G13,нормы!$A$14:$BC$57,38,0),"") | Y13: =IFERROR(VLOOKUP($G13,нормы!$A$14:$BC$57,42,0)*W13,"") | Z13: =IFERROR(VLOOKUP($G13,нормы!$A$14:$BC$57,14,0)*W13/1000,0) -> 0 | AN13: =IFERROR(Y13*AJ11/Y17,) -> 0 | AO13: =IFERROR(VLOOKUP($G13,нормы!$A$14:$BC$57,53,0)*$W13,"") | AP13: =IFERROR(Y13*AI11/Y17,) -> 0 | AQ13: =IFERROR(VLOOKUP($G13,нормы!$A$14:$BC$57,54,0)*$W13,"") | AR13: =IFERROR(AS13/SUM(AS11:AS16)*AL11,0) -> 0 | AS13: =IFERROR(VLOOKUP($G13,нормы!$A$14:$BC$57,55,0)*W13,"") | AT13: =IFERROR(AU13/SUM(AU11:AU16)*AM11,0) -> 0 | AU13: =IFERROR(VLOOKUP($G13,нормы!$A$14:$BI$57,56,0)*W13,"") | AV13: =IFERROR(AW13/SUM(AW11:AW16)*AK11,0) -> 0 | AW13: =IFERROR(VLOOKUP($G13,нормы!$A$14:$BI$57,57,0)*W13,"") | AY13: =IFERROR(VLOOKUP($G13,нормы!$A$14:$BI$57,58,0)*W13,"") | BA13: =IFERROR(VLOOKUP($G13,нормы!$A$14:$BI$57,61,0)*$W13,"") | BC13: =IFERROR(VLOOKUP($G13,нормы!$A$14:$BI$57,60,0)*W13,"") | BD13: =IFERROR(VLOOKUP($G13,нормы!$A$14:$BG$57,44,0),"") | BE13: =IFERROR(W13/VLOOKUP($G13,нормы!$A$14:$BI$57,45,0),"")
A14: 1Д | B14: =B13 -> 46023 | C14: =C13 -> 2 | D14: =D13 -> 1 | F14: =IFERROR(VLOOKUP($G14,нормы!$A$14:$BC$57,2,0),"") | H14: =IF(C14=1,"Кульков С.А.", IF(C14=2,"Чудаков А.А.",IF(C14=3,"Королев В.Н.",IF(C14=4,"Николашин М.П.",IF(C14=5," Кульков С.А.",IF(C14=6,"А.А. Чудаков",IF(C14=7,"В.Н. Королев",IF(C14=8,"М.П. Николашин",0)))))))) -> Чудаков А.А. | I14: 20 | K14: =IFERROR(VLOOKUP($G14,[1]нормы!$A$21:$BC$151,15,0),"") -> 0 | L14: =IFERROR(VLOOKUP($G14,[1]нормы!$A$21:$BC$151,17,0),"") -> 0 | M14: =IFERROR(VLOOKUP($G14,[1]нормы!$A$21:$BC$151,27,0),"") -> 0 | N14: =IFERROR(Y14/Y17*(1.1*J11*I19),"") | O14: =IFERROR(VLOOKUP($G14,[1]нормы!$A$21:$BC$151,21,0),"") -> 0 | P14: =IFERROR(VLOOKUP($G14,[1]нормы!$A$21:$BC$151,19,0),"") -> 0 | Q14: =IFERROR(VLOOKUP($G14,[1]нормы!$A$21:$BC$151,23,0),"") -> 0 | R14: =IFERROR(VLOOKUP($G14,[1]нормы!$A$21:$BC$151,29,0),"") -> 0 | S14: =IFERROR(VLOOKUP($G14,[1]нормы!$A$21:$BC$151,31,0),"") -> 0 | T14: =IFERROR(VLOOKUP($G14,[1]нормы!$A$21:$BC$151,25,0),"") -> 0 | U14: =IFERROR(W14/(((100*Y14/Y17)*I16)/100),"") | V14: =IFERROR(VLOOKUP($G14,нормы!$A$14:$BC$57,38,0),"") | Y14: =IFERROR(VLOOKUP($G14,нормы!$A$14:$BC$57,42,0)*W14,"") | Z14: =IFERROR(VLOOKUP($G14,нормы!$A$14:$BC$57,14,0)*W14/1000,0) -> 0 | AN14: =IFERROR(Y14*AJ11/Y17,) -> 0 | AO14: =IFERROR(VLOOKUP($G14,нормы!$A$14:$BC$57,53,0)*$W14,"") | AP14: =IFERROR(Y14*AI11/Y17,) -> 0 | AQ14: =IFERROR(VLOOKUP($G14,нормы!$A$14:$BC$57,54,0)*$W14,"") | AR14: =IFERROR(AS14/SUM(AS11:AS16)*AL11,0) -> 0 | AS14: =IFERROR(VLOOKUP($G14,нормы!$A$14:$BC$57,55,0)*W14,"") | AT14: =IFERROR(AU14/SUM(AU11:AU16)*AM11,0) -> 0 | AU14: =IFERROR(VLOOKUP($G14,нормы!$A$14:$BI$57,56,0)*W14,"") | AV14: =IFERROR(AW14/SUM(AW11:AW16)*AK11,0) -> 0 | AW14: =IFERROR(VLOOKUP($G14,нормы!$A$14:$BI$57,57,0)*W14,"") | AY14: =IFERROR(VLOOKUP($G14,нормы!$A$14:$BI$57,58,0)*W14,"") | BA14: =IFERROR(VLOOKUP($G14,нормы!$A$14:$BI$57,61,0)*$W14,"") | BC14: =IFERROR(VLOOKUP($G14,нормы!$A$14:$BI$57,60,0)*W14,"") | BD14: =IFERROR(VLOOKUP($G14,нормы!$A$14:$BG$57,44,0),"") | BE14: =IFERROR(W14/VLOOKUP($G14,нормы!$A$14:$BI$57,45,0),"")
A15: 1Д | B15: =B14 -> 46023 | C15: =C14 -> 2 | D15: =D14 -> 1 | F15: =IFERROR(VLOOKUP($G15,нормы!$A$14:$BC$57,2,0),"") | H15: =IF(C15=1,"Кульков С.А.", IF(C15=2,"Чудаков А.А.",IF(C15=3,"Королев В.Н.",IF(C15=4,"Николашин М.П.",IF(C15=5," Кульков С.А.",IF(C15=6,"А.А. Чудаков",IF(C15=7,"В.Н. Королев",IF(C15=8,"М.П. Николашин",0)))))))) -> Чудаков А.А. | I15: общ | K15: =IFERROR(VLOOKUP($G15,[1]нормы!$A$21:$BC$151,15,0),"") -> 0 | L15: =IFERROR(VLOOKUP($G15,[1]нормы!$A$21:$BC$151,17,0),"") -> 0 | M15: =IFERROR(VLOOKUP($G15,[1]нормы!$A$21:$BC$151,27,0),"") -> 0 | N15: =IFERROR(Y15/Y17*(1.1*J11*I20),"") | O15: =IFERROR(VLOOKUP($G15,[1]нормы!$A$21:$BC$151,21,0),"") -> 0 | P15: =IFERROR(VLOOKUP($G15,[1]нормы!$A$21:$BC$151,19,0),"") -> 0 | Q15: =IFERROR(VLOOKUP($G15,[1]нормы!$A$21:$BC$151,23,0),"") -> 0 | R15: =IFERROR(VLOOKUP($G15,[1]нормы!$A$21:$BC$151,29,0),"") -> 0 | S15: =IFERROR(VLOOKUP($G15,[1]нормы!$A$21:$BC$151,31,0),"") -> 0 | T15: =IFERROR(VLOOKUP($G15,[1]нормы!$A$21:$BC$151,25,0),"") -> 0 | U15: =IFERROR(W15/(((100*Y15/Y17)*I16)/100),"") | V15: =IFERROR(VLOOKUP($G15,нормы!$A$14:$BC$57,38,0),"") | Y15: =IFERROR(VLOOKUP($G15,нормы!$A$14:$BC$57,42,0)*W15,"") | Z15: =IFERROR(VLOOKUP($G15,нормы!$A$14:$BC$57,14,0)*W15/1000,0) -> 0 | AN15: =IFERROR(Y15*AJ11/Y17,) -> 0 | AO15: =IFERROR(VLOOKUP($G15,нормы!$A$14:$BC$57,53,0)*$W15,"") | AP15: =IFERROR(Y15*AI11/Y17,) -> 0 | AQ15: =IFERROR(VLOOKUP($G15,нормы!$A$14:$BC$57,54,0)*$W15,"") | AR15: =IFERROR(AS15/SUM(AS11:AS16)*AL11,0) -> 0 | AS15: =IFERROR(VLOOKUP($G15,нормы!$A$14:$BC$57,55,0)*W15,"") | AT15: =IFERROR(AU15/SUM(AU11:AU16)*AM11,0) -> 0 | AU15: =IFERROR(VLOOKUP($G15,нормы!$A$14:$BI$57,56,0)*W15,"") | AV15: =IFERROR(AW15/SUM(AW11:AW16)*AK11,0) -> 0 | AW15: =IFERROR(VLOOKUP($G15,нормы!$A$14:$BI$57,57,0)*W15,"") | AY15: =IFERROR(VLOOKUP($G15,нормы!$A$14:$BI$57,58,0)*W15,"") | BA15: =IFERROR(VLOOKUP($G15,нормы!$A$14:$BI$57,61,0)*$W15,"") | BC15: =IFERROR(VLOOKUP($G15,нормы!$A$14:$BI$57,60,0)*W15,"") | BD15: =IFERROR(VLOOKUP($G15,нормы!$A$14:$BG$57,44,0),"") | BE15: =IFERROR(W15/VLOOKUP($G15,нормы!$A$14:$BI$57,45,0),"")
A16: 1Д | B16: =B15 -> 46023 | C16: =C15 -> 2 | D16: =D15 -> 1 | F16: =IFERROR(VLOOKUP($G16,нормы!$A$14:$BC$57,2,0),"") | H16: =IF(C16=1,"Кульков С.А.", IF(C16=2,"Чудаков А.А.",IF(C16=3,"Королев В.Н.",IF(C16=4,"Николашин М.П.",IF(C16=5," Кульков С.А.",IF(C16=6,"А.А. Чудаков",IF(C16=7,"В.Н. Королев",IF(C16=8,"М.П. Николашин",0)))))))) -> Чудаков А.А. | I16: =I12+I14 -> 30 | K16: =IFERROR(VLOOKUP($G16,[1]нормы!$A$21:$BC$151,15,0),"") -> 0 | L16: =IFERROR(VLOOKUP($G16,[1]нормы!$A$21:$BC$151,17,0),"") -> 0 | M16: =IFERROR(VLOOKUP($G16,[1]нормы!$A$21:$BC$151,27,0),"") -> 0 | N16: =IFERROR(Y16/Y17*(1.1*J11*I21),"") | O16: =IFERROR(VLOOKUP($G16,[1]нормы!$A$21:$BC$151,21,0),"") -> 0 | P16: =IFERROR(VLOOKUP($G16,[1]нормы!$A$21:$BC$151,19,0),"") -> 0 | Q16: =IFERROR(VLOOKUP($G16,[1]нормы!$A$21:$BC$151,23,0),"") -> 0 | R16: =IFERROR(VLOOKUP($G16,[1]нормы!$A$21:$BC$151,29,0),"") -> 0 | S16: =IFERROR(VLOOKUP($G16,[1]нормы!$A$21:$BC$151,31,0),"") -> 0 | T16: =IFERROR(VLOOKUP($G16,[1]нормы!$A$21:$BC$151,25,0),"") -> 0 | U16: =IFERROR(W16/(((100*Y16/Y17)*I16)/100),"") | V16: =IFERROR(VLOOKUP($G16,нормы!$A$14:$BC$57,38,0),"") | Y16: =IFERROR(VLOOKUP($G16,нормы!$A$14:$BC$57,42,0)*W16,"") | Z16: =IFERROR(VLOOKUP($G16,нормы!$A$14:$BC$57,14,0)*W16/1000,0) -> 0 | AN16: =IFERROR(Y16*AJ11/Y17,) -> 0 | AO16: =IFERROR(VLOOKUP($G16,нормы!$A$14:$BC$57,53,0)*$W16,"") | AP16: =IFERROR(Y16*AI11/Y17,) -> 0 | AQ16: =IFERROR(VLOOKUP($G16,нормы!$A$14:$BC$57,54,0)*$W16,"") | AR16: =IFERROR(AS16/SUM(AS11:AS16)*AL11,0) -> 0 | AS16: =IFERROR(VLOOKUP($G16,нормы!$A$14:$BC$57,55,0)*W16,"") | AT16: =IFERROR(AU16/SUM(AU11:AU16)*AM11,0) -> 0 | AU16: =IFERROR(VLOOKUP($G16,нормы!$A$14:$BI$57,56,0)*W16,"") | AV16: =IFERROR(AW16/SUM(AW11:AW16)*AK11,0) -> 0 | AW16: =IFERROR(VLOOKUP($G16,нормы!$A$14:$BI$57,57,0)*W16,"") | AY16: =IFERROR(VLOOKUP($G16,нормы!$A$14:$BI$57,58,0)*W16,"") | BA16: =IFERROR(VLOOKUP($G16,нормы!$A$14:$BI$57,61,0)*$W16,"") | BC16: =IFERROR(VLOOKUP($G16,нормы!$A$14:$BI$57,60,0)*W16,"") | BD16: =IFERROR(VLOOKUP($G16,нормы!$A$14:$BG$57,44,0),"") | BE16: =IFERROR(W16/VLOOKUP($G16,нормы!$A$14:$BI$57,45,0),"")
A17: 1Д | F17: Дневная смена ЛФМ 2 | K17: Итого: | M17: Итого: | N17: =SUM(N11:N16) -> 0 | O17: кг / | P17: =N17*8.937/1000 -> 0 | Q17: м3 | Y17: =SUM(Y11:Y16) -> 0 | Z17: =SUM(Z11:Z16) -> 0 | AG17: Сил.3 | AH17: Сил.4 | AI17: Сил. 6 | AJ17: Общ. | AK17: 4-20 | AL17: 5-65 | AM17: 6-45 | BE17: =IFERROR(W17/VLOOKUP($G17,нормы!$A$14:$BI$15,28,0),"")
A18: 1Д | B18: =B16 -> 46023 | D18: 2 | F18: =IFERROR(VLOOKUP($G18,нормы!$A$14:$BC$57,2,0),"") | H18: =IF(C18=1,"Кульков С.А.", IF(C18=2,"Чудаков А.А.",IF(C18=3,"Королев В.Н.",IF(C18=4,"Николашин М.П.",IF(C18=5," Кульков С.А.",IF(C18=6,"А.А. Чудаков",IF(C18=7,"В.Н. Королев",IF(C18=8,"М.П. Николашин",0)))))))) -> 0 | I18: заг 3 | K18: =IFERROR(VLOOKUP($G18,[1]нормы!$A$21:$BC$151,15,0),"") -> 0 | L18: =IFERROR(VLOOKUP($G18,[1]нормы!$A$21:$BC$151,17,0),"") -> 0 | M18: =IFERROR(VLOOKUP($G18,[1]нормы!$A$21:$BC$151,27,0),"") -> 0 | N18: =IFERROR(Y18/Y24*(1.1*J18*I23),"") | O18: =IFERROR(VLOOKUP($G18,[1]нормы!$A$21:$BC$151,21,0),"") -> 0 | P18: =IFERROR(VLOOKUP($G18,[1]нормы!$A$21:$BC$151,19,0),"") -> 0 | Q18: =IFERROR(VLOOKUP($G18,[1]нормы!$A$21:$BC$151,23,0),"") -> 0 | R18: =IFERROR(VLOOKUP($G18,[1]нормы!$A$21:$BC$151,29,0),"") -> 0 | S18: =IFERROR(VLOOKUP($G18,[1]нормы!$A$21:$BC$151,31,0),"") -> 0 | T18: =IFERROR(VLOOKUP($G18,[1]нормы!$A$21:$BC$151,25,0),"") -> 0 | U18: =IFERROR(W18/(((100*Y18/Y24)*I23)/100),"") | V18: =IFERROR(VLOOKUP($G18,нормы!$A$14:$BC$57,38,0),"") | Y18: =IFERROR(VLOOKUP($G18,нормы!$A$14:$BC$57,42,0)*W18,"") | Z18: =IFERROR(VLOOKUP($G18,нормы!$A$14:$BC$57,14,0)*W18/1000,0) -> 0 | AJ18: =AG18+AH18 -> 0 | AN18: =IFERROR(Y18*AJ18/Y24,) -> 0 | AO18: =IFERROR(VLOOKUP($G18,нормы!$A$14:$BC$57,53,0)*$W18,"") | AP18: =IFERROR(Y18*AI18/Y24,) -> 0 | AQ18: =IFERROR(VLOOKUP($G18,нормы!$A$14:$BC$57,54,0)*$W18,"") | AR18: =IFERROR(AS18/SUM(AS18:AS23)*AL18,0) -> 0 | AS18: =IFERROR(VLOOKUP($G18,нормы!$A$14:$BC$57,55,0)*W18,"") | AT18: =IFERROR(AU18/SUM(AU18:AU23)*AM18,0) -> 0 | AU18: =IFERROR(VLOOKUP($G18,нормы!$A$14:$BI$57,56,0)*W18,"") | AV18: =IFERROR(AW18/SUM(AW18:AW23)*AK18,0) -> 0 | AW18: =IFERROR(VLOOKUP($G18,нормы!$A$14:$BI$57,57,0)*W18,"") | AY18: =IFERROR(VLOOKUP($G18,нормы!$A$14:$BI$57,58,0)*W18,"") | BA18: =IFERROR(VLOOKUP($G18,нормы!$A$14:$BI$57,61,0)*$W18,"") | BC18: =IFERROR(VLOOKUP($G18,нормы!$A$14:$BI$57,60,0)*W18,"") | BD18: =IFERROR(VLOOKUP($G18,нормы!$A$14:$BG$57,44,0),"") | BE18: =IFERROR(W18/VLOOKUP($G18,нормы!$A$14:$BI$57,45,0),"")
A19: 1Д | B19: =B18 -> 46023 | C19: =C18 -> 0 | D19: =D18 -> 2 | F19: =IFERROR(VLOOKUP($G19,нормы!$A$14:$BC$57,2,0),"") | H19: =IF(C19=1,"Кульков С.А.", IF(C19=2,"Чудаков А.А.",IF(C19=3,"Королев В.Н.",IF(C19=4,"Николашин М.П.",IF(C19=5," Кульков С.А.",IF(C19=6,"А.А. Чудаков",IF(C19=7,"В.Н. Королев",IF(C19=8,"М.П. Николашин",0)))))))) -> 0 | K19: =IFERROR(VLOOKUP($G19,[1]нормы!$A$21:$BC$151,15,0),"") -> 0 | L19: =IFERROR(VLOOKUP($G19,[1]нормы!$A$21:$BC$151,17,0),"") -> 0 | M19: =IFERROR(VLOOKUP($G19,[1]нормы!$A$21:$BC$151,27,0),"") -> 0 | N19: =IFERROR(Y19/Y24*(1.1*J18*I23),"") | O19: =IFERROR(VLOOKUP($G19,[1]нормы!$A$21:$BC$151,21,0),"") -> 0 | P19: =IFERROR(VLOOKUP($G19,[1]нормы!$A$21:$BC$151,19,0),"") -> 0 | Q19: =IFERROR(VLOOKUP($G19,[1]нормы!$A$21:$BC$151,23,0),"") -> 0 | R19: =IFERROR(VLOOKUP($G19,[1]нормы!$A$21:$BC$151,29,0),"") -> 0 | S19: =IFERROR(VLOOKUP($G19,[1]нормы!$A$21:$BC$151,31,0),"") -> 0 | T19: =IFERROR(VLOOKUP($G19,[1]нормы!$A$21:$BC$151,25,0),"") -> 0 | U19: =IFERROR(W19/(((100*Y19/Y24)*I23)/100),"") | V19: =IFERROR(VLOOKUP($G19,нормы!$A$14:$BC$57,38,0),"") | Y19: =IFERROR(VLOOKUP($G19,нормы!$A$14:$BC$57,42,0)*W19,"") | Z19: =IFERROR(VLOOKUP($G19,нормы!$A$14:$BC$57,14,0)*W19/1000,0) -> 0 | AN19: =IFERROR(Y19*AJ18/Y24,) -> 0 | AO19: =IFERROR(VLOOKUP($G19,нормы!$A$14:$BC$57,53,0)*$W19,"") | AP19: =IFERROR(Y19*AI18/Y24,) -> 0 | AQ19: =IFERROR(VLOOKUP($G19,нормы!$A$14:$BC$57,54,0)*$W19,"") | AR19: =IFERROR(AS19/SUM(AS18:AS23)*AL18,0) -> 0 | AS19: =IFERROR(VLOOKUP($G19,нормы!$A$14:$BC$57,55,0)*W19,"") | AT19: =IFERROR(AU19/SUM(AU18:AU23)*AM18,0) -> 0 | AU19: =IFERROR(VLOOKUP($G19,нормы!$A$14:$BI$57,56,0)*W19,"") | AV19: =IFERROR(AW19/SUM(AW18:AW23)*AK18,0) -> 0 | AW19: =IFERROR(VLOOKUP($G19,нормы!$A$14:$BI$57,57,0)*W19,"") | AY19: =IFERROR(VLOOKUP($G19,нормы!$A$14:$BI$57,58,0)*W19,"") | BA19: =IFERROR(VLOOKUP($G19,нормы!$A$14:$BI$57,61,0)*$W19,"") | BC19: =IFERROR(VLOOKUP($G19,нормы!$A$14:$BI$57,60,0)*W19,"") | BD19: =IFERROR(VLOOKUP($G19,нормы!$A$14:$BG$57,44,0),"") | BE19: =IFERROR(W19/VLOOKUP($G19,нормы!$A$14:$BI$57,45,0),"")
A20: 1Д | B20: =B19 -> 46023 | C20: =C19 -> 0 | D20: =D19 -> 2 | F20: =IFERROR(VLOOKUP($G20,нормы!$A$14:$BC$57,2,0),"") | H20: =IF(C20=1,"Кульков С.А.", IF(C20=2,"Чудаков А.А.",IF(C20=3,"Королев В.Н.",IF(C20=4,"Николашин М.П.",IF(C20=5," Кульков С.А.",IF(C20=6,"А.А. Чудаков",IF(C20=7,"В.Н. Королев",IF(C20=8,"М.П. Николашин",0)))))))) -> 0 | I20: заг 4 | K20: =IFERROR(VLOOKUP($G20,[1]нормы!$A$21:$BC$151,15,0),"") -> 0 | L20: =IFERROR(VLOOKUP($G20,[1]нормы!$A$21:$BC$151,17,0),"") -> 0 | M20: =IFERROR(VLOOKUP($G20,[1]нормы!$A$21:$BC$151,27,0),"") -> 0 | N20: =IFERROR(Y20/Y24*(1.1*J18*I23),"") | O20: =IFERROR(VLOOKUP($G20,[1]нормы!$A$21:$BC$151,21,0),"") -> 0 | P20: =IFERROR(VLOOKUP($G20,[1]нормы!$A$21:$BC$151,19,0),"") -> 0 | Q20: =IFERROR(VLOOKUP($G20,[1]нормы!$A$21:$BC$151,23,0),"") -> 0 | R20: =IFERROR(VLOOKUP($G20,[1]нормы!$A$21:$BC$151,29,0),"") -> 0 | S20: =IFERROR(VLOOKUP($G20,[1]нормы!$A$21:$BC$151,31,0),"") -> 0 | T20: =IFERROR(VLOOKUP($G20,[1]нормы!$A$21:$BC$151,25,0),"") -> 0 | U20: =IFERROR(W20/(((100*Y20/Y24)*I23)/100),"") | V20: =IFERROR(VLOOKUP($G20,нормы!$A$14:$BC$57,38,0),"") | Y20: =IFERROR(VLOOKUP($G20,нормы!$A$14:$BC$57,42,0)*W20,"") | Z20: =IFERROR(VLOOKUP($G20,нормы!$A$14:$BC$57,14,0)*W20/1000,0) -> 0 | AN20: =IFERROR(Y20*AJ18/Y24,) -> 0 | AO20: =IFERROR(VLOOKUP($G20,нормы!$A$14:$BC$57,53,0)*$W20,"") | AP20: =IFERROR(Y20*AI18/Y24,) -> 0 | AQ20: =IFERROR(VLOOKUP($G20,нормы!$A$14:$BC$57,54,0)*$W20,"") | AR20: =IFERROR(AS20/SUM(AS18:AS23)*AL18,0) -> 0 | AS20: =IFERROR(VLOOKUP($G20,нормы!$A$14:$BC$57,55,0)*W20,"") | AT20: =IFERROR(AU20/SUM(AU18:AU23)*AM18,0) -> 0 | AU20: =IFERROR(VLOOKUP($G20,нормы!$A$14:$BI$57,56,0)*W20,"") | AV20: =IFERROR(AW20/SUM(AW18:AW23)*AK18,0) -> 0 | AW20: =IFERROR(VLOOKUP($G20,нормы!$A$14:$BI$57,57,0)*W20,"") | AY20: =IFERROR(VLOOKUP($G20,нормы!$A$14:$BI$57,58,0)*W20,"") | BA20: =IFERROR(VLOOKUP($G20,нормы!$A$14:$BI$57,61,0)*$W20,"") | BC20: =IFERROR(VLOOKUP($G20,нормы!$A$14:$BI$57,60,0)*W20,"") | BD20: =IFERROR(VLOOKUP($G20,нормы!$A$14:$BG$57,44,0),"") | BE20: =IFERROR(W20/VLOOKUP($G20,нормы!$A$14:$BI$57,45,0),"")
A21: 1Д | B21: =B20 -> 46023 | C21: =C20 -> 0 | D21: =D20 -> 2 | F21: =IFERROR(VLOOKUP($G21,нормы!$A$14:$BC$57,2,0),"") | H21: =IF(C21=1,"Кульков С.А.", IF(C21=2,"Чудаков А.А.",IF(C21=3,"Королев В.Н.",IF(C21=4,"Николашин М.П.",IF(C21=5," Кульков С.А.",IF(C21=6,"А.А. Чудаков",IF(C21=7,"В.Н. Королев",IF(C21=8,"М.П. Николашин",0)))))))) -> 0 | K21: =IFERROR(VLOOKUP($G21,[1]нормы!$A$21:$BC$151,15,0),"") -> 0 | L21: =IFERROR(VLOOKUP($G21,[1]нормы!$A$21:$BC$151,17,0),"") -> 0 | M21: =IFERROR(VLOOKUP($G21,[1]нормы!$A$21:$BC$151,27,0),"") -> 0 | N21: =IFERROR(Y21/Y24*(1.1*J18*I26),"") | O21: =IFERROR(VLOOKUP($G21,[1]нормы!$A$21:$BC$151,21,0),"") -> 0 | P21: =IFERROR(VLOOKUP($G21,[1]нормы!$A$21:$BC$151,19,0),"") -> 0 | Q21: =IFERROR(VLOOKUP($G21,[1]нормы!$A$21:$BC$151,23,0),"") -> 0 | R21: =IFERROR(VLOOKUP($G21,[1]нормы!$A$21:$BC$151,29,0),"") -> 0 | S21: =IFERROR(VLOOKUP($G21,[1]нормы!$A$21:$BC$151,31,0),"") -> 0 | T21: =IFERROR(VLOOKUP($G21,[1]нормы!$A$21:$BC$151,25,0),"") -> 0 | U21: =IFERROR(W21/(((100*Y21/Y24)*I23)/100),"") | V21: =IFERROR(VLOOKUP($G21,нормы!$A$14:$BC$57,38,0),"") | Y21: =IFERROR(VLOOKUP($G21,нормы!$A$14:$BC$57,42,0)*W21,"") | Z21: =IFERROR(VLOOKUP($G21,нормы!$A$14:$BC$57,14,0)*W21/1000,0) -> 0 | AN21: =IFERROR(Y21*AJ18/Y24,) -> 0 | AO21: =IFERROR(VLOOKUP($G21,нормы!$A$14:$BC$57,53,0)*$W21,"") | AP21: =IFERROR(Y21*AI18/Y24,) -> 0 | AQ21: =IFERROR(VLOOKUP($G21,нормы!$A$14:$BC$57,54,0)*$W21,"") | AR21: =IFERROR(AS21/SUM(AS18:AS23)*AL18,0) -> 0 | AS21: =IFERROR(VLOOKUP($G21,нормы!$A$14:$BC$57,55,0)*W21,"") | AT21: =IFERROR(AU21/SUM(AU18:AU23)*AM18,0) -> 0 | AU21: =IFERROR(VLOOKUP($G21,нормы!$A$14:$BI$57,56,0)*W21,"") | AV21: =IFERROR(AW21/SUM(AW18:AW23)*AK18,0) -> 0 | AW21: =IFERROR(VLOOKUP($G21,нормы!$A$14:$BI$57,57,0)*W21,"") | AY21: =IFERROR(VLOOKUP($G21,нормы!$A$14:$BI$57,58,0)*W21,"") | BA21: =IFERROR(VLOOKUP($G21,нормы!$A$14:$BI$57,61,0)*$W21,"") | BC21: =IFERROR(VLOOKUP($G21,нормы!$A$14:$BI$57,60,0)*W21,"") | BD21: =IFERROR(VLOOKUP($G21,нормы!$A$14:$BG$57,44,0),"") | BE21: =IFERROR(W21/VLOOKUP($G21,нормы!$A$14:$BI$57,45,0),"")
A22: 1Д | B22: =B21 -> 46023 | C22: =C21 -> 0 | D22: =D21 -> 2 | F22: =IFERROR(VLOOKUP($G22,нормы!$A$14:$BC$57,2,0),"") | H22: =IF(C22=1,"Кульков С.А.", IF(C22=2,"Чудаков А.А.",IF(C22=3,"Королев В.Н.",IF(C22=4,"Николашин М.П.",IF(C22=5," Кульков С.А.",IF(C22=6,"А.А. Чудаков",IF(C22=7,"В.Н. Королев",IF(C22=8,"М.П. Николашин",0)))))))) -> 0 | I22: общ | K22: =IFERROR(VLOOKUP($G22,[1]нормы!$A$21:$BC$151,15,0),"") -> 0 | L22: =IFERROR(VLOOKUP($G22,[1]нормы!$A$21:$BC$151,17,0),"") -> 0 | M22: =IFERROR(VLOOKUP($G22,[1]нормы!$A$21:$BC$151,27,0),"") -> 0 | N22: =IFERROR(Y22/Y24*(1.1*J18*I27),"") | O22: =IFERROR(VLOOKUP($G22,[1]нормы!$A$21:$BC$151,21,0),"") -> 0 | P22: =IFERROR(VLOOKUP($G22,[1]нормы!$A$21:$BC$151,19,0),"") -> 0 | Q22: =IFERROR(VLOOKUP($G22,[1]нормы!$A$21:$BC$151,23,0),"") -> 0 | R22: =IFERROR(VLOOKUP($G22,[1]нормы!$A$21:$BC$151,29,0),"") -> 0 | S22: =IFERROR(VLOOKUP($G22,[1]нормы!$A$21:$BC$151,31,0),"") -> 0 | T22: =IFERROR(VLOOKUP($G22,[1]нормы!$A$21:$BC$151,25,0),"") -> 0 | U22: =IFERROR(W22/(((100*Y22/Y24)*I23)/100),"") | V22: =IFERROR(VLOOKUP($G22,нормы!$A$14:$BC$57,38,0),"") | Y22: =IFERROR(VLOOKUP($G22,нормы!$A$14:$BC$57,42,0)*W22,"") | Z22: =IFERROR(VLOOKUP($G22,нормы!$A$14:$BC$57,14,0)*W22/1000,0) -> 0 | AN22: =IFERROR(Y22*AJ18/Y24,) -> 0 | AO22: =IFERROR(VLOOKUP($G22,нормы!$A$14:$BC$57,53,0)*$W22,"") | AP22: =IFERROR(Y22*AI18/Y24,) -> 0 | AQ22: =IFERROR(VLOOKUP($G22,нормы!$A$14:$BC$57,54,0)*$W22,"") | AR22: =IFERROR(AS22/SUM(AS18:AS23)*AL18,0) -> 0 | AS22: =IFERROR(VLOOKUP($G22,нормы!$A$14:$BC$57,55,0)*W22,"") | AT22: =IFERROR(AU22/SUM(AU18:AU23)*AM18,0) -> 0 | AU22: =IFERROR(VLOOKUP($G22,нормы!$A$14:$BI$57,56,0)*W22,"") | AV22: =IFERROR(AW22/SUM(AW18:AW23)*AK18,0) -> 0 | AW22: =IFERROR(VLOOKUP($G22,нормы!$A$14:$BI$57,57,0)*W22,"") | AY22: =IFERROR(VLOOKUP($G22,нормы!$A$14:$BI$57,58,0)*W22,"") | BA22: =IFERROR(VLOOKUP($G22,нормы!$A$14:$BI$57,61,0)*$W22,"") | BC22: =IFERROR(VLOOKUP($G22,нормы!$A$14:$BI$57,60,0)*W22,"") | BD22: =IFERROR(VLOOKUP($G22,нормы!$A$14:$BG$57,44,0),"") | BE22: =IFERROR(W22/VLOOKUP($G22,нормы!$A$14:$BI$57,45,0),"")
A23: 1Д | B23: =B22 -> 46023 | C23: =C22 -> 0 | D23: =D22 -> 2 | F23: =IFERROR(VLOOKUP($G23,нормы!$A$14:$BC$57,2,0),"") | H23: =IF(C23=1,"Кульков С.А.", IF(C23=2,"Чудаков А.А.",IF(C23=3,"Королев В.Н.",IF(C23=4,"Николашин М.П.",IF(C23=5," Кульков С.А.",IF(C23=6,"А.А. Чудаков",IF(C23=7,"В.Н. Королев",IF(C23=8,"М.П. Николашин",0)))))))) -> 0 | I23: =I19+I21 -> 0 | K23: =IFERROR(VLOOKUP($G23,[1]нормы!$A$21:$BC$151,15,0),"") -> 0 | L23: =IFERROR(VLOOKUP($G23,[1]нормы!$A$21:$BC$151,17,0),"") -> 0 | M23: =IFERROR(VLOOKUP($G23,[1]нормы!$A$21:$BC$151,27,0),"") -> 0 | N23: =IFERROR(Y23/Y24*(1.1*J18*I28),"") | O23: =IFERROR(VLOOKUP($G23,[1]нормы!$A$21:$BC$151,21,0),"") -> 0 | P23: =IFERROR(VLOOKUP($G23,[1]нормы!$A$21:$BC$151,19,0),"") -> 0 | Q23: =IFERROR(VLOOKUP($G23,[1]нормы!$A$21:$BC$151,23,0),"") -> 0 | R23: =IFERROR(VLOOKUP($G23,[1]нормы!$A$21:$BC$151,29,0),"") -> 0 | S23: =IFERROR(VLOOKUP($G23,[1]нормы!$A$21:$BC$151,31,0),"") -> 0 | T23: =IFERROR(VLOOKUP($G23,[1]нормы!$A$21:$BC$151,25,0),"") -> 0 | U23: =IFERROR(W23/(((100*Y23/Y24)*I23)/100),"") | V23: =IFERROR(VLOOKUP($G23,нормы!$A$14:$BC$57,38,0),"") | Y23: =IFERROR(VLOOKUP($G23,нормы!$A$14:$BC$57,42,0)*W23,"") | Z23: =IFERROR(VLOOKUP($G23,нормы!$A$14:$BC$57,14,0)*W23/1000,0) -> 0 | AN23: =IFERROR(Y23*AJ18/Y24,) -> 0 | AO23: =IFERROR(VLOOKUP($G23,нормы!$A$14:$BC$57,53,0)*$W23,"") | AP23: =IFERROR(Y23*AI18/Y24,) -> 0 | AQ23: =IFERROR(VLOOKUP($G23,нормы!$A$14:$BC$57,54,0)*$W23,"") | AR23: =IFERROR(AS23/SUM(AS18:AS23)*AL18,0) -> 0 | AS23: =IFERROR(VLOOKUP($G23,нормы!$A$14:$BC$57,55,0)*W23,"") | AT23: =IFERROR(AU23/SUM(AU18:AU23)*AM18,0) -> 0 | AU23: =IFERROR(VLOOKUP($G23,нормы!$A$14:$BI$57,56,0)*W23,"") | AV23: =IFERROR(AW23/SUM(AW18:AW23)*AK18,0) -> 0 | AW23: =IFERROR(VLOOKUP($G23,нормы!$A$14:$BI$57,57,0)*W23,"") | AY23: =IFERROR(VLOOKUP($G23,нормы!$A$14:$BI$57,58,0)*W23,"") | BA23: =IFERROR(VLOOKUP($G23,нормы!$A$14:$BI$57,61,0)*$W23,"") | BC23: =IFERROR(VLOOKUP($G23,нормы!$A$14:$BI$57,60,0)*W23,"") | BD23: =IFERROR(VLOOKUP($G23,нормы!$A$14:$BG$57,44,0),"") | BE23: =IFERROR(W23/VLOOKUP($G23,нормы!$A$14:$BI$57,45,0),"")
A24: 1Д | K24: Итого: | M24: Итого: | N24: =SUM(N18:N23) -> 0 | O24: кг / | P24: =N24*8.937/1000 -> 0 | Q24: м3 | Y24: =SUM(Y18:Y23) -> 0 | Z24: =SUM(Z18:Z23) -> 0 | AA24: =(AA10+AA11+AA12+AA13+AA14+AA15+AA16+AA18+AA19+AA20+AA21+AA22+AA23)-AG11 -> 1 | AB24: =(AB10+AB11+AB12+AB13+AB14+AB15+AB16+AB18+AB19+AB20+AB21+AB22+AB23)-AH11 -> 2 | AC24: =(AC10+AC11+AC12+AC13+AC14+AC15+AC16+AC18+AC19+AC20+AC21+AC22+AC23)-AG18 -> 3 | AD24: =(AD10+AD11+AD12+AD13+AD14+AD15+AD16+AD18+AD19+AD20+AD21+AD22+AD23)-AH18 -> 4 | AE24: =(AE10+AE11+AE12+AE13+AE14+AE15+AE16+AE18+AE19+AE20+AE21+AE22+AE23)-AI11 -> 5 | AF24: =(AF10+AF11+AF12+AF13+AF14+AF15+AF16+AF18+AF19+AF20+AF21+AF22+AF23)-AI18 -> 6 | AN24: =SUM(AN18:AN23) -> 0 | AO24: =SUM(AO18:AO23) -> 0 | AR24: =SUM(AR18:AR23) -> 0 | AS24: =SUM(AS18:AS23) -> 0 | AT24: =SUM(AT18:AT23) -> 0 | AU24: =SUM(AU18:AU23) -> 0 | AV24: =SUM(AV18:AV23) -> 0 | AW24: =SUM(AW18:AW23) -> 0 | AX24: =SUM(AX18:AX23) -> 0 | AY24: =SUM(AY18:AY23) -> 0 | AZ24: =SUM(AZ18:AZ23) -> 0 | BD24: =IFERROR(VLOOKUP($G24,нормы!$A$14:$BG$15,27,0),"") | BE24: =IFERROR(W24/VLOOKUP($G24,нормы!$A$14:$BI$15,28,0),"")
A25: 1Д | B25: Ежесменный учет простостоев ЛФМ №1 | AA25: Ежесменный учет простостоев ЛФМ №2
A26: 1Д | E26: Дата | H26: Причина простоя | Y26: Время простоя, мин | AD26: Дата | BD26: Время простоя, мин
A27: 1Д
A28: 1Д | E28: =B23 -> 46023 | X28: 1 | Y28: 1 | Z28: =Y28-X28 -> 0 | AD28: =E28 -> 46023 | BC28: 1 | BD28: 1 | BE28: =BD28-BC28 -> 0
A29: 1Д | E29: =E28 -> 46023 | X29: 1 | Y29: 1 | Z29: =Y29-X29 -> 0 | AA29: =AA28 -> 0 | AD29: =AD28 -> 46023 | BC29: 1 | BD29: 1 | BE29: =BD29-BC29 -> 0
A30: 1Д | E30: =E29 -> 46023 | X30: 1 | Y30: 1 | Z30: =Y30-X30 -> 0 | AA30: =AA29 -> 0 | AD30: =AD29 -> 46023 | BC30: 1 | BD30: 1 | BE30: =BD30-BC30 -> 0
A31: 1Д | E31: =E30 -> 46023 | X31: 1 | Y31: 1 | Z31: =Y31-X31 -> 0 | AA31: =AA30 -> 0 | AD31: =AD30 -> 46023 | BC31: 1 | BD31: 1 | BE31: =BD31-BC31 -> 0
A32: 1Д | E32: =E31 -> 46023 | X32: 1 | Y32: 1 | Z32: =Y32-X32 -> 0 | AA32: =AA31 -> 0 | AD32: =AD31 -> 46023 | BC32: 1 | BD32: 1 | BE32: =BD32-BC32 -> 0
A33: 1Д | E33: =E32 -> 46023 | X33: 1 | Y33: 1 | Z33: =Y33-X33 -> 0 | AA33: =AA32 -> 0 | AD33: =AD32 -> 46023 | BC33: 1 | BD33: 1 | BE33: =BD33-BC33 -> 0
A34: 1Д | E34: =E33 -> 46023 | X34: 1 | Y34: 1 | Z34: =Y34-X34 -> 0 | AA34: =AA33 -> 0 | AD34: =AD33 -> 46023 | BC34: 1 | BD34: 1 | BE34: =BD34-BC34 -> 0
A35: 1Д | E35: =E34 -> 46023 | X35: 1 | Y35: 1 | Z35: =Y35-X35 -> 0 | AA35: =AA34 -> 0 | AD35: =AD34 -> 46023 | BC35: 1 | BD35: 1 | BE35: =BD35-BC35 -> 0
A36: 1Д | E36: =E35 -> 46023 | X36: 1 | Y36: 1 | Z36: =Y36-X36 -> 0 | AA36: =AA35 -> 0 | AD36: =AD35 -> 46023 | BC36: 1 | BD36: 1 | BE36: =BD36-BC36 -> 0
A37: 1Д | E37: =E36 -> 46023 | X37: 1 | Y37: 1 | Z37: =Y37-X37 -> 0 | AA37: =AA36 -> 0 | AD37: =AD36 -> 46023 | BC37: 1 | BD37: 1 | BE37: =BD37-BC37 -> 0
A38: 1Д | E38: =E37 -> 46023 | X38: 1 | Y38: 1 | Z38: =Y38-X38 -> 0 | AA38: =AA37 -> 0 | AD38: =AD37 -> 46023 | BC38: 1 | BD38: 1 | BE38: =BD38-BC38 -> 0
A39: 1Д | E39: =E38 -> 46023 | X39: 1 | Y39: 1 | Z39: =Y39-X39 -> 0 | AA39: =AA38 -> 0 | AD39: =AD38 -> 46023 | BC39: 1 | BD39: 1 | BE39: =BD39-BC39 -> 0
A40: 1Д
A41: 1Н | F41: Ночная смена ЛФМ 1 | AA41: =AA24 -> 1 | AB41: =AB24 -> 2 | AC41: =AC24 -> 3 | AD41: =AD24 -> 4 | AE41: =AE24 -> 5 | AF41: =AF24 -> 6 | AG41: Сил.1 | AH41: Сил.2 | AI41: Сил. 5 | AJ41: Общ. | AK41: 4-20 | AL41: 5-65 | AM41: 6-45
A42: =A41 -> 1Н | B42: =B23 -> 46023 | D42: 1 | F42: =IFERROR(VLOOKUP($G42,нормы!$A$14:$BC$57,2,0),"") | H42: =IF(C42=1,"Кульков С.А.", IF(C42=2,"Чудаков А.А.",IF(C42=3,"Королев В.Н.",IF(C42=4,"Николашин М.П.",IF(C42=5," Кульков С.А.",IF(C42=6,"А.А. Чудаков",IF(C42=7,"В.Н. Королев",IF(C42=8,"М.П. Николашин",0)))))))) -> 0 | I42: заг 1 | K42: =IFERROR(VLOOKUP($G42,[1]нормы!$A$21:$BC$151,15,0),"") -> 0 | L42: =IFERROR(VLOOKUP($G42,[1]нормы!$A$21:$BC$151,17,0),"") -> 0 | M42: =IFERROR(VLOOKUP($G42,[1]нормы!$A$21:$BC$151,27,0),"") -> 0 | N42: =IFERROR(Y42/Y48*(1.1*J42*I47),"") | O42: =IFERROR(VLOOKUP($G42,[1]нормы!$A$21:$BC$151,21,0),"") -> 0 | P42: =IFERROR(VLOOKUP($G42,[1]нормы!$A$21:$BC$151,19,0),"") -> 0 | Q42: =IFERROR(VLOOKUP($G42,[1]нормы!$A$21:$BC$151,23,0),"") -> 0 | R42: =IFERROR(VLOOKUP($G42,[1]нормы!$A$21:$BC$151,29,0),"") -> 0 | S42: =IFERROR(VLOOKUP($G42,[1]нормы!$A$21:$BC$151,31,0),"") -> 0 | T42: =IFERROR(VLOOKUP($G42,[1]нормы!$A$21:$BC$151,25,0),"") -> 0 | U42: =IFERROR(W42/(((100*Y42/Y48)*I47)/100),"") | V42: =IFERROR(VLOOKUP($G42,нормы!$A$14:$BC$57,38,0),"") | Y42: =IFERROR(VLOOKUP($G42,нормы!$A$14:$BC$57,42,0)*W42,"") | Z42: =IFERROR(VLOOKUP($G42,нормы!$A$14:$BC$57,14,0)*W42/1000,0) -> 0 | AJ42: =AG42+AH42 -> 0 | AN42: =IFERROR(Y42*AJ42/Y48,) -> 0 | AO42: =IFERROR(VLOOKUP($G42,нормы!$A$14:$BC$57,53,0)*$W42,"") | AP42: =IFERROR(Y42*AI42/Y48,) -> 0 | AQ42: =IFERROR(VLOOKUP($G42,нормы!$A$14:$BC$57,54,0)*$W42,"") | AR42: =IFERROR(AS42/SUM(AS42:AS47)*AL42,0) -> 0 | AS42: =IFERROR(VLOOKUP($G42,нормы!$A$14:$BC$57,55,0)*W42,"") | AT42: =IFERROR(AU42/SUM(AU42:AU47)*AM42,0) -> 0 | AU42: =IFERROR(VLOOKUP($G42,нормы!$A$14:$BI$57,56,0)*W42,"") | AV42: =IFERROR(AW42/SUM(AW42:AW47)*AK42,0) -> 0 | AW42: =IFERROR(VLOOKUP($G42,нормы!$A$14:$BI$57,57,0)*W42,"") | AY42: =IFERROR(VLOOKUP($G42,нормы!$A$14:$BI$57,58,0)*W42,"") | BA42: =IFERROR(VLOOKUP($G42,нормы!$A$14:$BI$57,61,0)*$W42,"") | BC42: =IFERROR(VLOOKUP($G42,нормы!$A$14:$BI$57,60,0)*W42,"") | BD42: =IFERROR(VLOOKUP($G42,нормы!$A$14:$BG$57,44,0),"") | BE42: =IFERROR(W42/VLOOKUP($G42,нормы!$A$14:$BI$57,45,0),"")
...

Sheet нормы
H1: "Утверждаю" ____________ | Q1: Туматов Д.А. | AP1: Директор технический ООО "Фибратек" | BF1: "Утверждаю" ____________
AP2: С.А. Платонов
AP3: "_____" _________________ 2022 г.
AP5: Инженер технолог ООО "Фибратек"
C6: Нормы расхода основных и вспомогательных материалов | H6: с 25.10.2022г. | AP6: В.И Шувалов
AP7: "_____" _________________ 2022 г.
B9: Нормы расхода основных и вспомогательных материалов. | BJ9: Цех | BM9: ЛКЦ
A10: номенклтуры № | B10: наименование листа | C10: Расход материалов на лист | O10: Расход материалов на замес | AM10: Геометрические размеры листа | AT10: Расход вспомогательных материалов | BA10: Расход материалов на лист с учетом потерь | BJ10: Пигмент, кг | BM10: Пигмент, кг | BO10: Грунтовка, кг
C11: цемент Цем1 42,5Н | D11: Дробленый шифер | E11: Асбест А5-65 | F11: Асбест А6-40 | G11: Асбест А4-20 | H11: Стекловолокно 40мм | I11: Целлюлоза | J11: Асбозурит | K11: Лапрол | L11: Кол-во влаги в листе 12% | M11: МАССА листа с учето12 % химически связанной воды и 12% влаги (из них 1 % угл.кислоты) | O11: цемент Цем 1 42,5 Н | Q11: Дробленый шифер | S11: Асбест А5-65 | U11: Асбест А6-40 | W11: Асбест А4-20 | Y11: Целлюлоза | AA11: Прочий мин порошок | AC11: Асбозурит | AE11: Стекловолокно 40мм | AG11: Лапрол | AI11: вода | AJ11: Содержание хризотила общее, % | AK11: Всего в смеске кг с учетом воды 12% | AL11: Количество листов с замеса | AM11: Длина, мм | AN11: Ширина, мм | AO11: Толщина, мм | AP11: Объем листа, м3 | AQ11: Вес листа с учетом 12% (11 хим. связанной воды + 1% угликислоты) | AR11: ТИП ПОДДОНА/размер бруса | AS11: Количество листов 1 стопе | AT11: Количество усл. плиток в листе | AU11: Сукно техническое | AV11: сетка верхняя №28,м2 | AW11: сетка нижняя №2,м2 | AX11: Пеногаситель | AY11: Флокулянт | AZ11: соляная кислота,кг | BA11: цемент Цем 1 42,5 Н | BB11: Дробленый шифер | BC11: Асбест А5-65 | BD11: Асбест А6-40 | BE11: Асбест А4-20 | BF11: Стекловолокно 40мм | BG11: Целлюлоза | BH11: Асбозурит | BI11: Лапрол | BJ11: коричневый | BK11: красный | BL11: Лак, кг | BM11: коричневый | BN11: красный | BP11: Лак, кг
C12: кг | D12: кг | E12: кг | F12: кг | G12: кг | H12: кг | I12: кг | J12: кг | K12: кг | L12: л. | M12: кг | O12: кг | P12: % | Q12: кг | R12: % | S12: кг | T12: % | U12: кг | V12: % | W12: кг | X12: % | Y12: кг | AA12: кг | AC12: кг | AE12: кг | AG12: кг | AH12: % | AI12: % | AJ12: % | AK12: кг | AM12: мм | AN12: мм | AO12: мм | AP12: мм | AQ12: кг | AS12: шт | AT12: шт | AU12: кг/ лист | AV12: м2/лист | AW12: м2/лист | AX12: кг/лист | AY12: кг | AZ12: кг/л | BA12: кг | BB12: кг | BC12: кг | BD12: кг | BE12: кг | BF12: кг | BG12: кг | BH12: кг | BI12: кг | BJ12: кг | BK12: кг | BL12: кг | BM12: кг | BN12: кг | BO12: кг | BP12: кг
A13: 1 | B13: 2 | C13: 3 | D13: 4 | E13: 5 | F13: 6 | G13: 7 | H13: 8 | I13: 9 | J13: 10 | K13: 11 | L13: 12 | M13: 13 | N13: 14 | O13: 15 | P13: 16 | Q13: 17 | R13: 18 | S13: 19 | T13: 20 | U13: 21 | V13: 22 | W13: 23 | X13: 24 | Y13: 25 | Z13: 26 | AA13: 27 | AB13: 28 | AC13: 29 | AD13: 30 | AE13: 31 | AF13: 32 | AG13: 33 | AH13: 34 | AI13: 35 | AJ13: 36 | AK13: 37 | AL13: 38 | AM13: 39 | AN13: 40 | AO13: 41 | AP13: 42 | AQ13: 43 | AR13: 44 | AS13: 45 | AT13: 46 | AU13: 47 | AV13: 48 | AW13: 49 | AX13: 50 | AY13: 51 | AZ13: 52 | BA13: 53 | BB13: 54 | BC13: 55 | BD13: 56 | BE13: 57 | BF13: 58 | BG13: 59 | BH13: 60 | BI13: 61 | BJ13: 61 | BK13: 62 | BL13: 64 | BM13: 61 | BN13: 62 | BO13: 63 | BP13: 64
A15: 1 | B15: 8 волн рифл | C15: =O15/AL15 -> 14.768161 | D15: =Q15/AL15 -> 0.23075251 | E15: =S15/AL15 -> 2.3075251 | F15: =U15/AL15 -> 0 | G15: =W15/AL15 -> 0 | H15: =AE15/AL15 -> 0.046150503 | I15: =Y15/AL15 -> 0.23075251 | J15: =AC15/AL15 -> 0.11537626 | K15: =AG15/AL15 -> 0.00046150503 | L15: =SUM(C15:K15)+SUM(C15:K15)*24%-SUM(C15:K15) -> 4.247803 | M15: =AQ15+AQ15*12% -> 21.946982 | N15: 60.41952 | O15: 640 | P15: =O15/(O15+Q15+S15+U15+W15+Y15+AA15+AC15+AE15+AG15) -> 0.83439806 | Q15: 10 | R15: =Q15/(O15+Q15+S15+U15+W15+Y15+AA15+AC15+AE15+AG15) -> 0.01303747 | S15: 100 | T15: =S15/(O15+Q15+S15+U15+W15+Y15+AA15+AC15+AE15+AG15) -> 0.1303747 | V15: =U15/(O15+Q15+S15+U15+W15+Y15+AC15+AE15+AG15) -> 0 | X15: =W15/(O15+Q15+S15+U15+W15+Y15+AC15+AE15+AG15) -> 0 | Y15: 10 | Z15: =Y15/(O15+Q15+S15+U15+W15+Y15+AA15+AC15+AE15+AG15) -> 0.01303747 | AB15: =AA15/(O15+Q15+S15+U15+W15+Y15+AA15+AC15+AE15+AG15) -> 0 | AC15: 5 | AD15: =AC15/(O15+Q15+S15+U15+W15+Y15+AA15+AC15+AE15+AG15) -> 0.0065187348 | AE15: 2 | AF15: =AE15/(O15+Q15+S15+U15+W15+Y15+AA15+AC15+AE15+AG15) -> 0.0026074939 | AG15: 0.02 | AH15: =AG15/(O15+Q15+S15+U15+Y15+AA15+AC15+AE15+AG15) -> 2.6074939e-05 | AI15: 0.24 | AJ15: =T15+V15+X15 -> 0.1303747 | AK15: =(O15+Q15+S15+U15+W15+Y15+AC15+AE15+AG15)+(O15+Q15+S15+U15+W15+Y15+AC15+AE15+AG15)*AI15 -> 951.1048 | AL15: =AK15/M15 -> 43.336473 | AM15: 1750 | AN15: 1280 | AO15: 5.4 | AP15: =AM15*AN15*AO15/1000000000 -> 0.012096 | AQ15: =AP15*1.134/0.0007 -> 19.59552 | AR15: Поддон 1750х1130 | AS15: 125 | AT15: =AP15/0.0007 -> 17.28 | AU15: =0.115/1000*AT15 -> 0.0019872 | AV15: =0.055/1000*AT15 -> 0.0009504 | AW15: =0.005/1000*AT15 -> 8.64e-05 | AX15: =0.024*AT15/1000 -> 0.00041472 | AY15: =0.024*AT15/1000 -> 0.00041472 | AZ15: =0.0068/0.046*AP15 -> 0.0017881043 | BA15: =(O15+(O15*(1.31/100*P15)))/AL15 -> 14.929586 | BB15: =(Q15+(Q15*(1.31/100*R15)))/AL15 -> 0.23079192 | BC15: =(S15+(S15*(1.31/100*T15)))/AL15 -> 2.3114662 | BD15: =(U15+(U15*(1.31/100*V15)))/AL15 -> 0 | BE15: =(W15+(W15*(1.31/100*X15)))/AL15 -> 0 | BF15: =(AE15+(AE15*(1.31/100*AF15)))/AL15 -> 0.046152079 | BG15: =(Y15+(Y15*(1.31/100*Z15)))/AL15 -> 0.23079192 | BH15: =(AC15+(AC15*(1.31/100*AD15)))/AL15 -> 0.11538611 | BI15: =(AG15+(AG15*(1.31/100*AH15)))/AL15 -> 0.00046150519 | BJ15: =ЛКЦ!K4 -> 0.020384 | BK15: =ЛКЦ!L4 -> 0.020384 | BL15: =ЛКЦ!J4 -> 0.028 | BM15: =ЛКЦ!K12 -> 0.0784 | BN15: =ЛКЦ!L12 -> 0.0784 | BO15: =ЛКЦ!N12 -> 0.2912 | BP15: =ЛКЦ!J12 -> 0.4144
A16: 2 | B16: 7 волн рифл | C16: =O16/AL16 -> 12.864453 | D16: =Q16/AL16 -> 0.20100707 | E16: =S16/AL16 -> 2.0100707 | F16: =U16/AL16 -> 0 | G16: =W16/AL16 -> 0 | H16: =AE16/AL16 -> 0.040201415 | I16: =Y16/AL16 -> 0.20100707 | J16: =AC16/AL16 -> 0.10050354 | K16: =AG16/AL16 -> 0.00040201415 | L16: =SUM(C16:K16)+SUM(C16:K16)*24%-SUM(C16:K16) -> 3.7002347 | M16: =AQ16+AQ16*12% -> 19.117879 | N16: 60.41952 | O16: 640 | P16: =O16/(O16+Q16+S16+U16+W16+Y16+AA16+AC16+AE16+AG16) -> 0.83439806 | Q16: 10 | R16: =Q16/(O16+Q16+S16+U16+W16+Y16+AA16+AC16+AE16+AG16) -> 0.01303747 | S16: 100 | T16: =S16/(O16+Q16+S16+U16+W16+Y16+AA16+AC16+AE16+AG16) -> 0.1303747 | V16: =U16/(O16+Q16+S16+U16+W16+Y16+AC16+AE16+AG16) -> 0 | X16: =W16/(O16+Q16+S16+U16+W16+Y16+AC16+AE16+AG16) -> 0 | Y16: 10 | Z16: =Y16/(O16+Q16+S16+U16+W16+Y16+AA16+AC16+AE16+AG16) -> 0.01303747 | AB16: =AA16/(O16+Q16+S16+U16+W16+Y16+AA16+AC16+AE16+AG16) -> 0 | AC16: 5 | AD16: =AC16/(O16+Q16+S16+U16+W16+Y16+AA16+AC16+AE16+AG16) -> 0.0065187348 | AE16: 2 | AF16: =AE16/(O16+Q16+S16+U16+W16+Y16+AA16+AC16+AE16+AG16) -> 0.0026074939 | AG16: 0.02 | AH16: =AG16/(O16+Q16+S16+U16+Y16+AA16+AC16+AE16+AG16) -> 2.6074939e-05 | AI16: 0.24 | AJ16: =T16+V16+X16 -> 0.1303747 | AK16: =(O16+Q16+S16+U16+W16+Y16+AC16+AE16+AG16)+(O16+Q16+S16+U16+W16+Y16+AC16+AE16+AG16)*AI16 -> 951.1048 | AL16: =AK16/M16 -> 49.749493 | AM16: 1750 | AN16: 1115 | AO16: 5.4 | AP16: =AM16*AN16*AO16/1000000000 -> 0.01053675 | AQ16: =AP16*1.134/0.0007 -> 17.069535 | AR16: Поддон 1750х1130 | AS16: 135 | AT16: =AP16/0.0007 -> 15.0525 | AU16: =0.115/1000*AT16 -> 0.0017310375 | AV16: =0.055/1000*AT16 -> 0.0008278875 | AW16: =0.005/1000*AT16 -> 7.52625e-05 | AX16: =0.024*AT16/1000 -> 0.00036126 | AY16: =0.024*AT16/1000 -> 0.00036126 | AZ16: =0.0068/0.046*AP16 -> 0.0015576065 | BA16: =(O16+(O16*(1.31/100*P16)))/AL16 -> 13.005069 | BB16: =(Q16+(Q16*(1.31/100*R16)))/AL16 -> 0.2010414 | BC16: =(S16+(S16*(1.31/100*T16)))/AL16 -> 2.0135037 | BD16: =(U16+(U16*(1.31/100*V16)))/AL16 -> 0 | BE16: =(W16+(W16*(1.31/100*X16)))/AL16 -> 0 | BF16: =(AE16+(AE16*(1.31/100*AF16)))/AL16 -> 0.040202788 | BG16: =(Y16+(Y16*(1.31/100*Z16)))/AL16 -> 0.2010414 | BH16: =(AC16+(AC16*(1.31/100*AD16)))/AL16 -> 0.10051212 | BI16: =(AG16+(AG16*(1.31/100*AH16)))/AL16 -> 0.00040201428
A17: 3 | B17: 7 волн 3500*980 | C17: =O17/AL17 -> 25.728905 | D17: =Q17/AL17 -> 0.40201415 | E17: =S17/AL17 -> 4.0201415 | F17: =U17/AL17 -> 0 | G17: =W17/AL17 -> 0 | H17: =AE17/AL17 -> 0.080402829 | I17: =Y17/AL17 -> 0.40201415 | J17: =AC17/AL17 -> 0.20100707 | K17: =AG17/AL17 -> 0.00080402829 | L17: =SUM(C17:K17)+SUM(C17:K17)*24%-SUM(C17:K17) -> 7.4004694 | M17: =AQ17+AQ17*12% -> 38.235758 | N17: 60.41952 | O17: 640 | P17: =O17/(O17+Q17+S17+U17+W17+Y17+AA17+AC17+AE17+AG17) -> 0.83439806 | Q17: 10 | R17: =Q17/(O17+Q17+S17+U17+W17+Y17+AA17+AC17+AE17+AG17) -> 0.01303747 | S17: 100 | T17: =S17/(O17+Q17+S17+U17+W17+Y17+AA17+AC17+AE17+AG17) -> 0.1303747 | V17: =U17/(O17+Q17+S17+U17+W17+Y17+AC17+AE17+AG17) -> 0 | X17: =W17/(O17+Q17+S17+U17+W17+Y17+AC17+AE17+AG17) -> 0 | Y17: 10 | Z17: =Y17/(O17+Q17+S17+U17+W17+Y17+AA17+AC17+AE17+AG17) -> 0.01303747 | AB17: =AA17/(O17+Q17+S17+U17+W17+Y17+AA17+AC17+AE17+AG17) -> 0 | AC17: 5 | AD17: =AC17/(O17+Q17+S17+U17+W17+Y17+AA17+AC17+AE17+AG17) -> 0.0065187348 | AE17: 2 | AF17: =AE17/(O17+Q17+S17+U17+W17+Y17+AA17+AC17+AE17+AG17) -> 0.0026074939 | AG17: 0.02 | AH17: =AG17/(O17+Q17+S17+U17+Y17+AA17+AC17+AE17+AG17) -> 2.6074939e-05 | AI17: 0.24 | AJ17: =T17+V17+X17 -> 0.1303747 | AK17: =(O17+Q17+S17+U17+W17+Y17+AC17+AE17+AG17)+(O17+Q17+S17+U17+W17+Y17+AC17+AE17+AG17)*AI17 -> 951.1048 | AL17: =AK17/M17 -> 24.874747 | AM17: 3500 | AN17: 1115 | AO17: 5.4 | AP17: =AM17*AN17*AO17/1000000000 -> 0.0210735 | AQ17: =AP17*1.134/0.0007 -> 34.13907 | AR17: Поддон 1750х1130 | AS17: 135 | AT17: =AP17/0.0007 -> 30.105 | AU17: =0.115/1000*AT17 -> 0.003462075 | AV17: =0.055/1000*AT17 -> 0.001655775 | AW17: =0.005/1000*AT17 -> 0.000150525 | AX17: =0.024*AT17/1000 -> 0.00072252 | AY17: =0.024*AT17/1000 -> 0.00072252 | AZ17: =0.0068/0.046*AP17 -> 0.003115213 | BA17: =(O17+(O17*(1.31/100*P17)))/AL17 -> 26.010138 | BB17: =(Q17+(Q17*(1.31/100*R17)))/AL17 -> 0.40208281 | BC17: =(S17+(S17*(1.31/100*T17)))/AL17 -> 4.0270075 | BD17: =(U17+(U17*(1.31/100*V17)))/AL17 -> 0 | BE17: =(W17+(W17*(1.31/100*X17)))/AL17 -> 0 | BF17: =(AE17+(AE17*(1.31/100*AF17)))/AL17 -> 0.080405576 | BG17: =(Y17+(Y17*(1.31/100*Z17)))/AL17 -> 0.40208281 | BH17: =(AC17+(AC17*(1.31/100*AD17)))/AL17 -> 0.20102424 | BI17: =(AG17+(AG17*(1.31/100*AH17)))/AL17 -> 0.00080402857
A18: 4 | B18: плоский 10 мм | C18: =O18/AL18 -> 26.44066 | D18: =Q18/AL18 -> 0.41313531 | E18: =S18/AL18 -> 4.1313531 | F18: =U18/AL18 -> 0 | G18: =W18/AL18 -> 0 | H18: =AE18/AL18 -> 0 | I18: =Y18/AL18 -> 0.41313531 | J18: =AC18/AL18 -> 0.20656765 | K18: =AG18/AL18 -> 0.00082627062 | L18: =SUM(C18:K18)+SUM(C18:K18)*24%-SUM(C18:K18) -> 7.5853626 | M18: =AQ18+AQ18*12% -> 39.19104 | N18: 60.41952 | O18: 640 | P18: =O18/(O18+Q18+S18+U18+W18+Y18+AA18+AC18+AE18+AG18) -> 0.83657944 | Q18: 10 | R18: =Q18/(O18+Q18+S18+U18+W18+Y18+AA18+AC18+AE18+AG18) -> 0.013071554 | S18: 100 | T18: =S18/(O18+Q18+S18+U18+W18+Y18+AA18+AC18+AE18+AG18) -> 0.13071554 | V18: =U18/(O18+Q18+S18+U18+W18+Y18+AC18+AE18+AG18) -> 0 | X18: =W18/(O18+Q18+S18+U18+W18+Y18+AC18+AE18+AG18) -> 0 | Y18: 10 | Z18: =Y18/(O18+Q18+S18+U18+W18+Y18+AA18+AC18+AE18+AG18) -> 0.013071554 | AB18: =AA18/(O18+Q18+S18+U18+W18+Y18+AA18+AC18+AE18+AG18) -> 0 | AC18: 5 | AD18: =AC18/(O18+Q18+S18+U18+W18+Y18+AA18+AC18+AE18+AG18) -> 0.0065357768 | AE18: 0 | AF18: =AE18/(O18+Q18+S18+U18+W18+Y18+AA18+AC18+AE18+AG18) -> 0 | AG18: 0.02 | AH18: =AG18/(O18+Q18+S18+U18+Y18+AA18+AC18+AE18+AG18) -> 2.6143107e-05 | AI18: 0.24 | AJ18: =T18+V18+X18 -> 0.13071554 | AK18: =(O18+Q18+S18+U18+W18+Y18+AC18+AE18+AG18)+(O18+Q18+S18+U18+W18+Y18+AC18+AE18+AG18)*AI18 -> 948.6248 | AL18: =AK18/M18 -> 24.205145 | AM18: 1800 | AN18: 1200 | AO18: 10 | AP18: =AM18*AN18*AO18/1000000000 -> 0.0216 | AQ18: =AP18*1.134/0.0007 -> 34.992 | AR18: Поддон 1750х1130 | AS18: 50 | AT18: =AP18/0.0007 -> 30.857143 | AU18: =0.115/1000*AT18 -> 0.0035485714 | AV18: =0.055/1000*AT18 -> 0.0016971429 | AW18: =0.005/1000*AT18 -> 0.00015428571 | AX18: =0.024*AT18/1000 -> 0.00074057143 | AY18: =0.024*AT18/1000 -> 0.00074057143 | AZ18: =0.0068/0.046*AP18 -> 0.0031930435 | BA18: =(O18+(O18*(1.31/100*P18)))/AL18 -> 26.730428 | BB18: =(Q18+(Q18*(1.31/100*R18)))/AL18 -> 0.41320605 | BC18: =(S18+(S18*(1.31/100*T18)))/AL18 -> 4.1384275 | BD18: =(U18+(U18*(1.31/100*V18)))/AL18 -> 0 | BE18: =(W18+(W18*(1.31/100*X18)))/AL18 -> 0 | BF18: =(AE18+(AE18*(1.31/100*AF18)))/AL18 -> 0 | BG18: =(Y18+(Y18*(1.31/100*Z18)))/AL18 -> 0.41320605 | BH18: =(AC18+(AC18*(1.31/100*AD18)))/AL18 -> 0.20658534 | BI18: =(AG18+(AG18*(1.31/100*AH18)))/AL18 -> 0.0008262709
A19: 5 | B19: плоский 8 мм | C19: =O19/AL19 -> 21.152528 | D19: =Q19/AL19 -> 0.33050825 | E19: =S19/AL19 -> 3.3050825 | F19: =U19/AL19 -> 0 | G19: =W19/AL19 -> 0 | H19: =AE19/AL19 -> 0 | I19: =Y19/AL19 -> 0.33050825 | J19: =AC19/AL19 -> 0.16525412 | K19: =AG19/AL19 -> 0.00066101649 | L19: =SUM(C19:K19)+SUM(C19:K19)*24%-SUM(C19:K19) -> 6.0682901 | M19: =AQ19+AQ19*12% -> 31.352832 | N19: 60.41952 | O19: 640 | P19: =O19/(O19+Q19+S19+U19+W19+Y19+AA19+AC19+AE19+AG19) -> 0.83657944 | Q19: 10 | R19: =Q19/(O19+Q19+S19+U19+W19+Y19+AA19+AC19+AE19+AG19) -> 0.013071554 | S19: 100 | T19: =S19/(O19+Q19+S19+U19+W19+Y19+AA19+AC19+AE19+AG19) -> 0.13071554 | V19: =U19/(O19+Q19+S19+U19+W19+Y19+AC19+AE19+AG19) -> 0 | X19: =W19/(O19+Q19+S19+U19+W19+Y19+AC19+AE19+AG19) -> 0 | Y19: 10 | Z19: =Y19/(O19+Q19+S19+U19+W19+Y19+AA19+AC19+AE19+AG19) -> 0.013071554 | AB19: =AA19/(O19+Q19+S19+U19+W19+Y19+AA19+AC19+AE19+AG19) -> 0 | AC19: 5 | AD19: =AC19/(O19+Q19+S19+U19+W19+Y19+AA19+AC19+AE19+AG19) -> 0.0065357768 | AE19: 0 | AF19: =AE19/(O19+Q19+S19+U19+W19+Y19+AA19+AC19+AE19+AG19) -> 0 | AG19: 0.02 | AH19: =AG19/(O19+Q19+S19+U19+Y19+AA19+AC19+AE19+AG19) -> 2.6143107e-05 | AI19: 0.24 | AJ19: =T19+V19+X19 -> 0.13071554 | AK19: =(O19+Q19+S19+U19+W19+Y19+AC19+AE19+AG19)+(O19+Q19+S19+U19+W19+Y19+AC19+AE19+AG19)*AI19 -> 948.6248 | AL19: =AK19/M19 -> 30.256431 | AM19: 1800 | AN19: 1200 | AO19: 8 | AP19: =AM19*AN19*AO19/1000000000 -> 0.01728 | AQ19: =AP19*1.134/0.0007 -> 27.9936 | AR19: Поддон 1750х1130 | AS19: 50 | AT19: =AP19/0.0007 -> 24.685714 | AU19: =0.115/1000*AT19 -> 0.0028388571 | AV19: =0.055/1000*AT19 -> 0.0013577143 | AW19: =0.005/1000*AT19 -> 0.00012342857 | AX19: =0.024*AT19/1000 -> 0.00059245714 | AY19: =0.024*AT19/1000 -> 0.00059245714 | AZ19: =0.0068/0.046*AP19 -> 0.0025544348 | BA19: =(O19+(O19*(1.31/100*P19)))/AL19 -> 21.384342 | BB19: =(Q19+(Q19*(1.31/100*R19)))/AL19 -> 0.33056484 | BC19: =(S19+(S19*(1.31/100*T19)))/AL19 -> 3.310742 | BD19: =(U19+(U19*(1.31/100*V19)))/AL19 -> 0 | BE19: =(W19+(W19*(1.31/100*X19)))/AL19 -> 0 | BF19: =(AE19+(AE19*(1.31/100*AF19)))/AL19 -> 0 | BG19: =(Y19+(Y19*(1.31/100*Z19)))/AL19 -> 0.33056484 | BH19: =(AC19+(AC19*(1.31/100*AD19)))/AL19 -> 0.16526827 | BI19: =(AG19+(AG19*(1.31/100*AH19)))/AL19 -> 0.00066101672
A20: 6 | B20: плоский 6 мм | C20: =O20/AL20 -> 15.864396 | D20: =Q20/AL20 -> 0.24788119 | E20: =S20/AL20 -> 2.4788119 | F20: =U20/AL20 -> 0 | G20: =W20/AL20 -> 0 | H20: =AE20/AL20 -> 0 | I20: =Y20/AL20 -> 0.24788119 | J20: =AC20/AL20 -> 0.12394059 | K20: =AG20/AL20 -> 0.00049576237 | L20: =SUM(C20:K20)+SUM(C20:K20)*24%-SUM(C20:K20) -> 4.5512175 | M20: =AQ20+AQ20*12% -> 23.514624 | N20: 60.41952 | O20: 640 | P20: =O20/(O20+Q20+S20+U20+W20+Y20+AA20+AC20+AE20+AG20) -> 0.83657944 | Q20: 10 | R20: =Q20/(O20+Q20+S20+U20+W20+Y20+AA20+AC20+AE20+AG20) -> 0.013071554 | S20: 100 | T20: =S20/(O20+Q20+S20+U20+W20+Y20+AA20+AC20+AE20+AG20) -> 0.13071554 | V20: =U20/(O20+Q20+S20+U20+W20+Y20+AC20+AE20+AG20) -> 0 | X20: =W20/(O20+Q20+S20+U20+W20+Y20+AC20+AE20+AG20) -> 0 | Y20: 10 | Z20: =Y20/(O20+Q20+S20+U20+W20+Y20+AA20+AC20+AE20+AG20) -> 0.013071554 | AB20: =AA20/(O20+Q20+S20+U20+W20+Y20+AA20+AC20+AE20+AG20) -> 0 | AC20: 5 | AD20: =AC20/(O20+Q20+S20+U20+W20+Y20+AA20+AC20+AE20+AG20) -> 0.0065357768 | AE20: 0 | AF20: =AE20/(O20+Q20+S20+U20+W20+Y20+AA20+AC20+AE20+AG20) -> 0 | AG20: 0.02 | AH20: =AG20/(O20+Q20+S20+U20+Y20+AA20+AC20+AE20+AG20) -> 2.6143107e-05 | AI20: 0.24 | AJ20: =T20+V20+X20 -> 0.13071554 | AK20: =(O20+Q20+S20+U20+W20+Y20+AC20+AE20+AG20)+(O20+Q20+S20+U20+W20+Y20+AC20+AE20+AG20)*AI20 -> 948.6248 | AL20: =AK20/M20 -> 40.341908 | AM20: 1800 | AN20: 1200 | AO20: 6 | AP20: =AM20*AN20*AO20/1000000000 -> 0.01296 | AQ20: =AP20*1.134/0.0007 -> 20.9952 | AR20: Поддон 1750х1130 | AS20: 50 | AT20: =AP20/0.0007 -> 18.514286 | AU20: =0.115/1000*AT20 -> 0.0021291429 | AV20: =0.055/1000*AT20 -> 0.0010182857 | AW20: =0.005/1000*AT20 -> 9.2571429e-05 | AX20: =0.024*AT20/1000 -> 0.00044434286 | AY20: =0.024*AT20/1000 -> 0.00044434286 | AZ20: =0.0068/0.046*AP20 -> 0.0019158261 | BA20: =(O20+(O20*(1.31/100*P20)))/AL20 -> 16.038257 | BB20: =(Q20+(Q20*(1.31/100*R20)))/AL20 -> 0.24792363 | BC20: =(S20+(S20*(1.31/100*T20)))/AL20 -> 2.4830565 | BD20: =(U20+(U20*(1.31/100*V20)))/AL20 -> 0 | BE20: =(W20+(W20*(1.31/100*X20)))/AL20 -> 0 | BF20: =(AE20+(AE20*(1.31/100*AF20)))/AL20 -> 0 | BG20: =(Y20+(Y20*(1.31/100*Z20)))/AL20 -> 0.24792363 | BH20: =(AC20+(AC20*(1.31/100*AD20)))/AL20 -> 0.1239512 | BI20: =(AG20+(AG20*(1.31/100*AH20)))/AL20 -> 0.00049576254
A21: 7 | B21: Римская черепица 1750*930 | C21: =O21/AL21 -> 13.135801 | D21: =Q21/AL21 -> 0.20524688 | E21: =S21/AL21 -> 2.0524688 | F21: =U21/AL21 -> 0 | G21: =W21/AL21 -> 0 | H21: =AE21/AL21 -> 0.041049377 | I21: =Y21/AL21 -> 0.20524688 | J21: =AC21/AL21 -> 0.10262344 | K21: =AG21/AL21 -> 0.00041049377 | L21: =SUM(C21:K21)+SUM(C21:K21)*24%-SUM(C21:K21) -> 3.7782831 | M21: =AQ21+AQ21*12% -> 19.52113 | N21: 60.41952 | O21: 640 | P21: =O21/(O21+Q21+S21+U21+W21+Y21+AA21+AC21+AE21+AG21) -> 0.83439806 | Q21: 10 | R21: =Q21/(O21+Q21+S21+U21+W21+Y21+AA21+AC21+AE21+AG21) -> 0.01303747 | S21: 100 | T21: =S21/(O21+Q21+S21+U21+W21+Y21+AA21+AC21+AE21+AG21) -> 0.1303747 | V21: =U21/(O21+Q21+S21+U21+W21+Y21+AC21+AE21+AG21) -> 0 | X21: =W21/(O21+Q21+S21+U21+W21+Y21+AC21+AE21+AG21) -> 0 | Y21: 10 | Z21: =Y21/(O21+Q21+S21+U21+W21+Y21+AA21+AC21+AE21+AG21) -> 0.01303747 | AB21: =AA21/(O21+Q21+S21+U21+W21+Y21+AA21+AC21+AE21+AG21) -> 0 | AC21: 5 | AD21: =AC21/(O21+Q21+S21+U21+W21+Y21+AA21+AC21+AE21+AG21) -> 0.0065187348 | AE21: 2 | AF21: =AE21/(O21+Q21+S21+U21+W21+Y21+AA21+AC21+AE21+AG21) -> 0.0026074939 | AG21: 0.02 | AH21: =AG21/(O21+Q21+S21+U21+Y21+AA21+AC21+AE21+AG21) -> 2.6074939e-05 | AI21: 0.24 | AJ21: =T21+V21+X21 -> 0.1303747 | AK21: =(O21+Q21+S21+U21+W21+Y21+AC21+AE21+AG21)+(O21+Q21+S21+U21+W21+Y21+AC21+AE21+AG21)*AI21 -> 951.1048 | AL21: =AK21/M21 -> 48.721812 | AM21: 1750 | AN21: 1060 | AO21: 5.8 | AP21: =AM21*AN21*AO21/1000000000 -> 0.010759 | AQ21: =AP21*1.134/0.0007 -> 17.42958 | AR21: Поддон 1750х1130 | AS21: 100 | AT21: =AP21/0.0007 -> 15.37 | AU21: =0.115/1000*AT21 -> 0.00176755 | AV21: =0.055/1000*AT21 -> 0.00084535 | AW21: =0.005/1000*AT21 -> 7.685e-05 | AX21: =0.024*AT21/1000 -> 0.00036888 | AY21: =0.024*AT21/1000 -> 0.00036888 | AZ21: =0.0068/0.046*AP21 -> 0.0015904609 | BA21: =(O21+(O21*(1.31/100*P21)))/AL21 -> 13.279383 | BB21: =(Q21+(Q21*(1.31/100*R21)))/AL21 -> 0.20528194 | BC21: =(S21+(S21*(1.31/100*T21)))/AL21 -> 2.0559743 | BD21: =(U21+(U21*(1.31/100*V21)))/AL21 -> 0 | BE21: =(W21+(W21*(1.31/100*X21)))/AL21 -> 0 | BF21: =(AE21+(AE21*(1.31/100*AF21)))/AL21 -> 0.041050779 | BG21: =(Y21+(Y21*(1.31/100*Z21)))/AL21 -> 0.20528194 | BH21: =(AC21+(AC21*(1.31/100*AD21)))/AL21 -> 0.10263221 | BI21: =(AG21+(AG21*(1.31/100*AH21)))/AL21 -> 0.00041049391 | BJ21: =ЛКЦ!K5 -> 0.0213325 | BK21: =ЛКЦ!L5 -> 0.0213325 | BL21: =ЛКЦ!J5 -> 0.0287525 | BM21: =ЛКЦ!K13 -> 0.05565 | BN21: =ЛКЦ!L13 -> 0.05565 | BO21: =ЛКЦ!N13 -> 0.2226 | BP21: =ЛКЦ!J13 -> 0.31535
A22: 8 | B22: Римская черепица 875*930 | C22: =O22/AL22 -> 6.5679003 | D22: =Q22/AL22 -> 0.10262344 | E22: =S22/AL22 -> 1.0262344 | F22: =U22/AL22 -> 0 | G22: =W22/AL22 -> 0 | H22: =AE22/AL22 -> 0.020524688 | I22: =Y22/AL22 -> 0.10262344 | J22: =AC22/AL22 -> 0.051311721 | K22: =AG22/AL22 -> 0.00020524688 | L22: =SUM(C22:K22)+SUM(C22:K22)*24%-SUM(C22:K22) -> 1.8891416 | M22: =AQ22+AQ22*12% -> 9.7605648 | N22: 60.41952 | O22: 640 | P22: =O22/(O22+Q22+S22+U22+W22+Y22+AA22+AC22+AE22+AG22) -> 0.83439806 | Q22: 10 | R22: =Q22/(O22+Q22+S22+U22+W22+Y22+AA22+AC22+AE22+AG22) -> 0.01303747 | S22: 100 | T22: =S22/(O22+Q22+S22+U22+W22+Y22+AA22+AC22+AE22+AG22) -> 0.1303747 | V22: =U22/(O22+Q22+S22+U22+W22+Y22+AC22+AE22+AG22) -> 0 | X22: =W22/(O22+Q22+S22+U22+W22+Y22+AC22+AE22+AG22) -> 0 | Y22: 10 | Z22: =Y22/(O22+Q22+S22+U22+W22+Y22+AA22+AC22+AE22+AG22) -> 0.01303747 | AB22: =AA22/(O22+Q22+S22+U22+W22+Y22+AA22+AC22+AE22+AG22) -> 0 | AC22: 5 | AD22: =AC22/(O22+Q22+S22+U22+W22+Y22+AA22+AC22+AE22+AG22) -> 0.0065187348 | AE22: 2 | AF22: =AE22/(O22+Q22+S22+U22+W22+Y22+AA22+AC22+AE22+AG22) -> 0.0026074939 | AG22: 0.02 | AH22: =AG22/(O22+Q22+S22+U22+Y22+AA22+AC22+AE22+AG22) -> 2.6074939e-05 | AI22: 0.24 | AJ22: =T22+V22+X22 -> 0.1303747 | AK22: =(O22+Q22+S22+U22+W22+Y22+AC22+AE22+AG22)+(O22+Q22+S22+U22+W22+Y22+AC22+AE22+AG22)*AI22 -> 951.1048 | AL22: =AK22/M22 -> 97.443623 | AM22: 875 | AN22: 1060 | AO22: 5.8 | AP22: =AM22*AN22*AO22/1000000000 -> 0.0053795 | AQ22: =AP22*1.134/0.0007 -> 8.71479 | AR22: Поддон 1750х1130 | AS22: 100 | AT22: =AP22/0.0007 -> 7.685 | AU22: =0.115/1000*AT22 -> 0.000883775 | AV22: =0.055/1000*AT22 -> 0.000422675 | AW22: =0.005/1000*AT22 -> 3.8425e-05 | AX22: =0.024*AT22/1000 -> 0.00018444 | AY22: =0.024*AT22/1000 -> 0.00018444 | AZ22: =0.0068/0.046*AP22 -> 0.00079523043 | BA22: =(O22+(O22*(1.31/100*P22)))/AL22 -> 6.6396915 | BB22: =(Q22+(Q22*(1.31/100*R22)))/AL22 -> 0.10264097 | BC22: =(S22+(S22*(1.31/100*T22)))/AL22 -> 1.0279871 | BD22: =(U22+(U22*(1.31/100*V22)))/AL22 -> 0 | BE22: =(W22+(W22*(1.31/100*X22)))/AL22 -> 0 | BF22: =(AE22+(AE22*(1.31/100*AF22)))/AL22 -> 0.020525389 | BG22: =(Y22+(Y22*(1.31/100*Z22)))/AL22 -> 0.10264097 | BH22: =(AC22+(AC22*(1.31/100*AD22)))/AL22 -> 0.051316103 | BI22: =(AG22+(AG22*(1.31/100*AH22)))/AL22 -> 0.00020524695 | BJ22: =ЛКЦ!K6 -> 0.01066625 | BK22: =ЛКЦ!L6 -> 0.01066625 | BL22: =ЛКЦ!J6 -> 0.01437625 | BM22: =ЛКЦ!K14 -> 0.027825 | BN22: =ЛКЦ!L14 -> 0.027825 | BO22: =ЛКЦ!N14 -> 0.1113 | BP22: =ЛКЦ!J14 -> 0.157675
S464: 81
M465: 16
AO466: 23050
AO467: 25100

Sheet ЛКЦ
A1: Расход в цеху на 1м2 | J1: Расход на лист
A2: Наименование продукции | B2: Грунтовка | C2: Лак, кг | D2: Пигмент, кг | G2: Размер листа | J2: Лак, кг | K2: Пигмент, кг
D3: корич | E3: красный | F3: графит | G3: длина, м | H3: ширина, м | I3: площадь покрытия, кв м | K3: корич | L3: красный | M3: графит
A4: 8 волн рифл | C4: 0.0125 | D4: 0.0091 | E4: 0.0091 | F4: 0.0091 | G4: 1.75 | H4: 1.28 | I4: =G4*H4 -> 2.24 | J4: =I4*C4 -> 0.028 | K4: =I4*D4 -> 0.020384 | L4: =I4*E4 -> 0.020384 | M4: =I4*F4 -> 0.020384
A5: Римская черепица 1750*930 | C5: 0.0155 | D5: 0.0115 | E5: 0.0115 | F5: 0.0115 | G5: 1.75 | H5: 1.06 | I5: =G5*H5 -> 1.855 | J5: =I5*C5 -> 0.0287525 | K5: =I5*D5 -> 0.0213325 | L5: =I5*E5 -> 0.0213325 | M5: =I5*F5 -> 0.0213325
A6: Римская черепица 875*930 | C6: 0.0155 | D6: 0.0115 | E6: 0.0115 | F6: 0.0115 | G6: 0.875 | H6: 1.06 | I6: =G6*H6 -> 0.9275 | J6: =I6*C6 -> 0.01437625 | K6: =I6*D6 -> 0.01066625 | L6: =I6*E6 -> 0.01066625 | M6: =I6*F6 -> 0.01066625
A9: Расход в ЛКЦ на 1м2 | J9: Расход на лист
A10: Наименование продукции | B10: Грунтовка | C10: Лак, кг | D10: Пигмент, кг | G10: Размер листа | J10: Лак, кг | K10: Пигмент, кг | N10: Грунтовка, кг
D11: корич | E11: красный | F11: графит | G11: длина, м | H11: ширина, м | I11: площадь покрытия, кв м | K11: корич | L11: красный | M11: графит
A12: 8 волн рифл | B12: 0.13 | C12: 0.185 | D12: 0.035 | E12: 0.035 | F12: 0.035 | G12: 1.75 | H12: 1.28 | I12: =G12*H12 -> 2.24 | J12: =I12*C12 -> 0.4144 | K12: =I12*D12 -> 0.0784 | L12: =I12*E12 -> 0.0784 | M12: =I12*F12 -> 0.0784 | N12: =I12*B12 -> 0.2912
A13: Римская черепица 1750*930 | B13: 0.12 | C13: 0.17 | D13: 0.03 | E13: 0.03 | F13: 0.03 | G13: 1.75 | H13: 1.06 | I13: =G13*H13 -> 1.855 | J13: =I13*C13 -> 0.31535 | K13: =I13*D13 -> 0.05565 | L13: =I13*E13 -> 0.05565 | M13: =I13*F13 -> 0.05565 | N13: =I13*B13 -> 0.2226
A14: Римская черепица 875*930 | B14: 0.12 | C14: 0.17 | D14: 0.03 | E14: 0.03 | F14: 0.03 | G14: 0.875 | H14: 1.06 | I14: =G14*H14 -> 0.9275 | J14: =I14*C14 -> 0.157675 | K14: =I14*D14 -> 0.027825 | L14: =I14*E14 -> 0.027825 | M14: =I14*F14 -> 0.027825 | N14: =I14*B14 -> 0.1113
A17: Наименование продукции | B17: Общий расход на лист цех и ЛКЦ
B18: Грунтовка, кг | C18: Лак, кг | D18: Пигмент, кг
D19: корич | E19: красный | F19: графит
A20: 8 волн рифл | B20: =N12 -> 0.2912 | C20: =J12+J4 -> 0.4424 | D20: =K12+K4 -> 0.098784 | E20: =L12+L4 -> 0.098784 | F20: =M12+M4 -> 0.098784
A21: Римская черепица 1750*930 | B21: =N13 -> 0.2226 | C21: =J13+J5 -> 0.3441025 | D21: =K13+K5 -> 0.0769825 | E21: =L13+L5 -> 0.0769825 | F21: =M13+M5 -> 0.0769825
A22: Римская черепица 875*930 | B22: =N14 -> 0.1113 | C22: =J14+J6 -> 0.17205125 | D22: =K14+K6 -> 0.03849125 | E22: =L14+L6 -> 0.03849125 | F22: =M14+M6 -> 0.03849125

Sheet НОВЫЕ ПРОДУКТЫ
A1: Дата производства | B1: партия | C1: Наименование | D1: Количество | F1: Дата распиловки | G1: переработано в номенклатуру | H1: Количество | J1: Дата реализации | K1: переработано в номенклатуру | L1: Количество
D2: листов | E2: тонн | H2: листов | I2: тонн | L2: листов | M2: тонн

Sheet Лист2
